Workbook

Sheet 参数输入表
D1: 【抽水蓄能】财务评价计算模型边界条件输入参数表
B3: 类别 | C3: 序号 | D3: 参数 | E3: 操作类型 | F3: 数据结构化整理 | G3: 收入/成本归类 | H3: 参数释义/计算公式 | I3: 数值 | J3: 单位 | K3: 取值说明 | L3: 备注
B4: 工程计划 | C4: 1 | D4: 建设期 | E4: 自动计算，向上取整 | I4: =ROUNDUP(I10,0) -> 8 | J4: 年 | K4: 占用的表格年度跨度，如7.5年需考虑8个会计年度
D5: 建设期起始日期 | E5: 下拉菜单选择【日历】 | I5: 44958 | K5: 输入完动工年月及建设期结束日期，自动配置出参数表及计算表中建设期所占报表年度（如建设期为7年5个月，建设期实际占8个报表年）
D6: 建设期首年年末 | I6: 45291
D7: 建设期结束日期 | E7: 下拉菜单选择【日历】 | I7: 47695
D8: 建设期末年年初 | I8: 47484
D9: 建设期月份数 | E9: 自动计算 | I9: =ROUND(DATEDIF(I5,I7,"D")/365*12,0) -> 90 | J9: 月
D10: 建设期月份数转化为年 | I10: =I9/12 -> 7.5 | J10: 年
D11: 建设期首年月份 | E11: 自动计算 | I11: =ROUND(DATEDIF(I5,I6,"D")/365*12,0) -> 11 | J11: 月
D12: 建设期末年月份 | E12: 自动计算 | I12: =ROUND(DATEDIF(I8,I7,"D")/365*12,0) -> 7 | J12: 月
C13: 2 | D13: 施工进度安排 | I13: =SUM(I14:I23) -> 1
D14: 2023年3月（自定义时间点1） | E14: 自动计算 | I14: =投资概算明细!F24 -> 0.032776537 | J14: % | K14: 2023.2.1-2023.3.31（2个月）
D15: 45261 | E15: 自动计算 | I15: =投资概算明细!G24 -> 0.076478585 | J15: % | K15: 2023.4.1-2023.12.31（9个月）
D16: 45627 | E16: 自动计算 | I16: =投资概算明细!H24 -> 0.10622378 | J16: % | K16: 2024.1.1-2024.12.31（12个月）
D17: 45992 | E17: 自动计算 | I17: =投资概算明细!I24 -> 0.12056456 | J17: % | K17: 2025.1.1-2025.12.31（12个月）
D18: 46357 | E18: 自动计算 | I18: =投资概算明细!J24 -> 0.1318463 | J18: % | K18: 2026.1.1-2026.12.31（12个月）
D19: 46722 | E19: 自动计算 | I19: =投资概算明细!K24 -> 0.176246 | J19: % | K19: 2027.1.1-2027.12.31（12个月）
D20: 47088 | E20: 自动计算 | I20: =投资概算明细!L24 -> 0.16159672 | J20: % | K20: 2028.1.1-2028.12.31（12个月）
D21: 2029年8月（自定义时间点1） | E21: 自动计算 | I21: =投资概算明细!M24 -> 0.081637444 | J21: % | K21: 2029.1.1-2029.8.31（8个月）
D22: 47453 | E22: 自动计算 | I22: =投资概算明细!N24 -> 0.054424963 | J22: % | K22: 2029.9.1-2029.12.31（4个月）
D23: 47665 | E23: 自动计算 | I23: =投资概算明细!O24 -> 0.058205099 | J23: % | K23: 2030.1.1-2030.7.31（7个月）
D24: …… | E24: 根据需要（向上取整）配置
C25: 3 | D25: 投产起始日期 | E25: 手动输入/下拉菜单选择【日历】 | I25: =YEAR(I27)-YEAR(I5)+1 -> 8 | J25: 第n年/第n月
C26: 4 | D26: 运营期/商业运营期 | E26: 手动输入 | I26: 40 | J26: 年
D27: 运营期起始日期 | E27: 自动计算 | I27: =I7+1 -> 47696 | K27: 建设期结束后1天既进入运营期
D28: 运营期结束日期 | E28: 自动计算 | I28: =I7+I26*365+INT(I26/4) -> 62305 | K28: 以建设期结束日期加运营期计算所得，同时考虑每4年出现闰年比非闰年多1天，运营期无法被4整除的按倍数取整
C29: 5 | D29: 试运营期 | E29: 选择时间区间 | J29: 年/月 | K29: 用于最后的累计盈余资金判定
C30: 6 | D30: 项目所在地 | E30: 下拉菜单选择 | K30: 判定是否属于西部地区
D31: 所在省份 | E31: 下拉菜单选择
D32: 所在市、县 | E32: 下拉菜单选择
B33: 生产技术 | C33: 1 | D33: 实际装机容量 | E33: 手动输入 | I33: 1400 | J33: MW | K33: 1MW=1000kW
C34: 2 | D34: 年利用小时数 | E34: 手动输入 | I34: 1169.2857 | J34: h
C35: 3 | D35: 新增投产比例
D36: 47150 | E36: 下拉菜单选择【日历】/手动输入 | I36: 0 | J36: %
D37: 47362 | E37: 下拉菜单选择【日历】/手动输入 | I37: 0 | J37: %
D38: 47543 | E38: 下拉菜单选择【日历】/手动输入 | I38: 0 | J38: %
D39: 47696 | E39: 下拉菜单选择【日历】/手动输入 | I39: 1 | J39: %
C40: 4 | D40: 达产率
C41: 4.1 | D41: 设备设施平均达产率
...

Sheet 时间序列
B3: 项目 | C3: 建设期开始 | D3: 建设期 | N3: 运营期 | BC3: 运营期结束
B4: 项目完整时间序列 | C4: =参数输入表!I5 -> 44958 | D4: 45016 | E4: 45291 | F4: 45657 | G4: 46022 | H4: 46387 | I4: 46752 | J4: 47118 | K4: 47361 | L4: 47483 | M4: 47695 | N4: =参数输入表!I250 -> 47726 | O4: 47848 | P4: 48213 | Q4: 48579 | R4: 48944 | S4: 49309 | T4: 49674 | U4: 50040 | V4: 50405 | W4: 50770 | X4: 51135 | Y4: 51501 | Z4: 51866 | AA4: 52231 | AB4: 52596 | AC4: 52962 | AD4: 53327 | AE4: 53692 | AF4: 54057 | AG4: 54423 | AH4: 54788 | AI4: 55153 | AJ4: 55518 | AK4: 55884 | AL4: 56249 | AM4: 56614 | AN4: 56979 | AO4: 57345 | AP4: 57710 | AQ4: 58075 | AR4: 58440 | AS4: 58806 | AT4: 59171 | AU4: 59536 | AV4: 59901 | AW4: 60267 | AX4: 60632 | AY4: 60997 | AZ4: 61362 | BA4: 61728 | BB4: 62093 | BC4: =参数输入表!I28 -> 62305
B5: 相邻时间节点间隔（月） | C5: 0 | D5: =ROUND(DATEDIF(C4,D4,"d")/30,0) -> 2 | E5: =ROUND(DATEDIF(D4,E4,"d")/30,0) -> 9 | F5: =ROUND(DATEDIF(E4,F4,"d")/30,0) -> 12 | G5: =ROUND(DATEDIF(F4,G4,"d")/30,0) -> 12 | H5: =ROUND(DATEDIF(G4,H4,"d")/30,0) -> 12 | I5: =ROUND(DATEDIF(H4,I4,"d")/30,0) -> 12 | J5: =ROUND(DATEDIF(I4,J4,"d")/30,0) -> 12 | K5: =ROUND(DATEDIF(J4,K4,"d")/30,0) -> 8 | ... BC5: =ROUND(DATEDIF(BB4,BC4,"d")/30,0) -> 7
B6: 时间节点所处年度 | C6: =YEAR(C4) -> 2023 | D6: =YEAR(D4) -> 2023 | E6: =YEAR(E4) -> 2023 | F6: =YEAR(F4) -> 2024 | G6: =YEAR(G4) -> 2025 | H6: =YEAR(H4) -> 2026 | I6: =YEAR(I4) -> 2027 | J6: =YEAR(J4) -> 2028 | ... BC6: =YEAR(BC4) -> 2070
B7: 时间序列（年） | C7: 2023 | D7: 2024 | E7: 2025 | F7: 2026 | G7: 2027 | H7: 2028 | I7: 2029 | J7: 2030 | K7: 2031 | L7: 2032 | M7: 2033 | N7: 2034 | O7: 2035 | P7: 2036 | Q7: 2037 | R7: 2038 | S7: 2039 | T7: 2040 | U7: 2041 | V7: 2042 | W7: 2043 | X7: 2044 | Y7: 2045 | Z7: 2046 | AA7: 2047 | AB7: 2048 | AC7: 2049 | AD7: 2050 | AE7: 2051 | AF7: 2052 | AG7: 2053 | AH7: 2054 | AI7: 2055 | AJ7: 2056 | AK7: 2057 | AL7: 2058 | AM7: 2059 | AN7: 2060 | AO7: 2061 | AP7: 2062 | AQ7: 2063 | AR7: 2064 | AS7: 2065 | AT7: 2066 | AU7: 2067 | AV7: 2068 | AW7: 2069 | AX7: 2070
B8: 当年占用时间（月） | C8: =SUMIF($C$6:$BC$6,C7,$C$5:$BC$5) -> 11 | D8: =SUMIF($C$6:$BC$6,D7,$C$5:$BC$5) -> 12 | E8: =SUMIF($C$6:$BC$6,E7,$C$5:$BC$5) -> 12 | F8: =SUMIF($C$6:$BC$6,F7,$C$5:$BC$5) -> 12 | G8: =SUMIF($C$6:$BC$6,G7,$C$5:$BC$5) -> 12 | H8: =SUMIF($C$6:$BC$6,H7,$C$5:$BC$5) -> 12 | I8: =SUMIF($C$6:$BC$6,I7,$C$5:$BC$5) -> 12 | J8: =SUMIF($C$6:$BC$6,J7,$C$5:$BC$5) -> 12 | ... AX8: =SUMIF($C$6:$BC$6,AX7,$C$5:$BC$5) -> 7
B10: 项目 | C10: 投产开始 | AS10: 运营期结束
B11: 项目投产时间序列 | C11: =参数输入表!D36 -> 47150 | D11: 47483 | E11: 47848 | F11: 48213 | G11: 48579 | H11: 48944 | I11: 49309 | J11: 49674 | K11: 50040 | L11: 50405 | M11: 50770 | N11: 51135 | O11: 51501 | P11: 51866 | Q11: 52231 | R11: 52596 | S11: 52962 | T11: 53327 | U11: 53692 | V11: 54057 | W11: 54423 | X11: 54788 | Y11: 55153 | Z11: 55518 | AA11: 55884 | AB11: 56249 | AC11: 56614 | AD11: 56979 | AE11: 57345 | AF11: 57710 | AG11: 58075 | AH11: 58440 | AI11: 58806 | AJ11: 59171 | AK11: 59536 | AL11: 59901 | AM11: 60267 | AN11: 60632 | AO11: 60997 | AP11: 61362 | AQ11: 61728 | AR11: 62093 | AS11: =参数输入表!I28 -> 62305
B12: 相邻时间节点间隔（月） | C12: 0 | D12: =ROUND(DATEDIF(C11,D11,"d")/30,0) -> 11 | E12: =ROUND(DATEDIF(D11,E11,"d")/30,0) -> 12 | F12: =ROUND(DATEDIF(E11,F11,"d")/30,0) -> 12 | G12: =ROUND(DATEDIF(F11,G11,"d")/30,0) -> 12 | H12: =ROUND(DATEDIF(G11,H11,"d")/30,0) -> 12 | I12: =ROUND(DATEDIF(H11,I11,"d")/30,0) -> 12 | J12: =ROUND(DATEDIF(I11,J11,"d")/30,0) -> 12 | K12: =ROUND(DATEDIF(J11,K11,"d")/30,0) -> 12 | ... AS12: =ROUND(DATEDIF(AR11,AS11,"d")/30,0) -> 7
B13: 时间节点所处年度 | C13: =YEAR(C11) -> 2029 | D13: =YEAR(D11) -> 2029 | E13: =YEAR(E11) -> 2030 | F13: =YEAR(F11) -> 2031 | G13: =YEAR(G11) -> 2032 | H13: =YEAR(H11) -> 2033 | I13: =YEAR(I11) -> 2034 | J13: =YEAR(J11) -> 2035 | ... AS13: =YEAR(AS11) -> 2070
B14: 时间序列（年） | C14: 2029 | D14: 2030 | E14: 2031 | F14: 2032 | G14: 2033 | H14: 2034 | I14: 2035 | J14: 2036 | K14: 2037 | L14: 2038 | M14: 2039 | N14: 2040 | O14: 2041 | P14: 2042 | Q14: 2043 | R14: 2044 | S14: 2045 | T14: 2046 | U14: 2047 | V14: 2048 | W14: 2049 | X14: 2050 | Y14: 2051 | Z14: 2052 | AA14: 2053 | AB14: 2054 | AC14: 2055 | AD14: 2056 | AE14: 2057 | AF14: 2058 | AG14: 2059 | AH14: 2060 | AI14: 2061 | AJ14: 2062 | AK14: 2063 | AL14: 2064 | AM14: 2065 | AN14: 2066 | AO14: 2067 | AP14: 2068 | AQ14: 2069 | AR14: 2070
B15: 当年占用时间（月） | C15: =SUMIF($C$13:$BB$13,C14,$C$12:$BB$12) -> 11 | D15: =SUMIF($C$13:$BB$13,D14,$C$12:$BB$12) -> 12 | E15: =SUMIF($C$13:$BB$13,E14,$C$12:$BB$12) -> 12 | F15: =SUMIF($C$13:$BB$13,F14,$C$12:$BB$12) -> 12 | G15: =SUMIF($C$13:$BB$13,G14,$C$12:$BB$12) -> 12 | H15: =SUMIF($C$13:$BB$13,H14,$C$12:$BB$12) -> 12 | I15: =SUMIF($C$13:$BB$13,I14,$C$12:$BB$12) -> 12 | J15: =SUMIF($C$13:$BB$13,J14,$C$12:$BB$12) -> 12 | ... AR15: =SUMIF($C$13:$BB$13,AR14,$C$12:$BB$12) -> 7
B17: 首批固定资产折旧开始-结束时点 | C17: =参数输入表!$D$36 -> 47150 | D17: =参数输入表!$D$36+参数输入表!$I$622*365+INT(参数输入表!$I$622/4) -> 57742
B18: 固定资产折旧摊销时间序列 | C18: =YEAR(C19) -> 2029 | D18: =YEAR(D19) -> 2029 | E18: =YEAR(E19) -> 2030 | F18: =YEAR(F19) -> 2031 | G18: =YEAR(G19) -> 2032 | H18: =YEAR(H19) -> 2033 | I18: =YEAR(I19) -> 2034 | J18: =YEAR(J19) -> 2035 | ... AG18: =YEAR(AG19) -> 2058
C19: =C17 -> 47150 | D19: 47483 | E19: 47848 | F19: 48213 | G19: 48579 | H19: 48944 | I19: 49309 | J19: 49674 | K19: 50040 | L19: 50405 | M19: 50770 | N19: 51135 | O19: 51501 | P19: 51866 | Q19: 52231 | R19: 52596 | S19: 52962 | T19: 53327 | U19: 53692 | V19: 54057 | W19: 54423 | X19: 54788 | Y19: 55153 | Z19: 55518 | AA19: 55884 | AB19: 56249 | AC19: 56614 | AD19: 56979 | AE19: 57345 | AF19: 57710 | AG19: =D17 -> 57742
B20: =SUM(C20:AX20) -> 348 | C20: 0 | D20: =ROUND((DATEDIF(C19,D19,"d"))/30,0) -> 11 | E20: =ROUND((DATEDIF(D19,E19,"d"))/30,0) -> 12 | F20: =ROUND((DATEDIF(E19,F19,"d"))/30,0) -> 12 | G20: =ROUND((DATEDIF(F19,G19,"d"))/30,0) -> 12 | H20: =ROUND((DATEDIF(G19,H19,"d"))/30,0) -> 12 | I20: =ROUND((DATEDIF(H19,I19,"d"))/30,0) -> 12 | J20: =ROUND((DATEDIF(I19,J19,"d"))/30,0) -> 12 | K20: =ROUND((DATEDIF(J19,K19,"d"))/30,0) -> 12 | ... AG20: =ROUND((DATEDIF(AF19,AG19,"d"))/30,0) -> 1
B21: 时间序列（年） | C21: 2023 | D21: 2024 | E21: 2025 | F21: 2026 | G21: 2027 | H21: 2028 | I21: 2029 | J21: 2030 | K21: 2031 | L21: 2032 | M21: 2033 | N21: 2034 | O21: 2035 | P21: 2036 | Q21: 2037 | R21: 2038 | S21: 2039 | T21: 2040 | U21: 2041 | V21: 2042 | W21: 2043 | X21: 2044 | Y21: 2045 | Z21: 2046 | AA21: 2047 | AB21: 2048 | AC21: 2049 | AD21: 2050 | AE21: 2051 | AF21: 2052 | AG21: 2053 | AH21: 2054 | AI21: 2055 | AJ21: 2056 | AK21: 2057 | AL21: 2058 | AM21: 2059 | AN21: 2060 | AO21: 2061 | AP21: 2062 | AQ21: 2063 | AR21: 2064 | AS21: 2065 | AT21: 2066 | AU21: 2067 | AV21: 2068 | AW21: 2069 | AX21: 2070
B22: 当年折旧月份数（固定资产） | C22: =SUMIF($C$18:$AG$18,C21,$C$20:$AG$20) -> 0 | D22: =SUMIF($C$18:$AG$18,D21,$C$20:$AG$20) -> 0 | E22: =SUMIF($C$18:$AG$18,E21,$C$20:$AG$20) -> 0 | F22: =SUMIF($C$18:$AG$18,F21,$C$20:$AG$20) -> 0 | G22: =SUMIF($C$18:$AG$18,G21,$C$20:$AG$20) -> 0 | H22: =SUMIF($C$18:$AG$18,H21,$C$20:$AG$20) -> 0 | I22: =SUMIF($C$18:$AG$18,I21,$C$20:$AG$20) -> 11 | J22: =SUMIF($C$18:$AG$18,J21,$C$20:$AG$20) -> 12 | ... AX22: =SUMIF($C$18:$AG$18,AX21,$C$20:$AG$20) -> 0
B23: 首批投产设备设施无形资产折旧开始-结束时点 | C23: =参数输入表!D36 -> 47150 | D23: =参数输入表!$D$36+参数输入表!$I$638*365+INT(参数输入表!$I$638/4) -> 53724
B24: 无形资产折旧摊销时间序列 | C24: =YEAR(C25) -> 2029 | D24: =YEAR(D25) -> 2029 | E24: =YEAR(E25) -> 2030 | F24: =YEAR(F25) -> 2031 | G24: =YEAR(G25) -> 2032 | H24: =YEAR(H25) -> 2033 | I24: =YEAR(I25) -> 2034 | J24: =YEAR(J25) -> 2035 | ... V24: =YEAR(V25) -> 2047
C25: =C23 -> 47150 | D25: 47483 | E25: 47848 | F25: 48213 | G25: 48579 | H25: 48944 | I25: 49309 | J25: 49674 | K25: 50040 | L25: 50405 | M25: 50770 | N25: 51135 | O25: 51501 | P25: 51866 | Q25: 52231 | R25: 52596 | S25: 52962 | T25: 53327 | U25: 53692 | V25: =D23 -> 53724
B26: =SUM(C26:AX26) -> 216 | C26: 0 | D26: =ROUND((DATEDIF(C25,D25,"d"))/30,0) -> 11 | E26: =ROUND((DATEDIF(D25,E25,"d"))/30,0) -> 12 | F26: =ROUND((DATEDIF(E25,F25,"d"))/30,0) -> 12 | G26: =ROUND((DATEDIF(F25,G25,"d"))/30,0) -> 12 | H26: =ROUND((DATEDIF(G25,H25,"d"))/30,0) -> 12 | I26: =ROUND((DATEDIF(H25,I25,"d"))/30,0) -> 12 | J26: =ROUND((DATEDIF(I25,J25,"d"))/30,0) -> 12 | K26: =ROUND((DATEDIF(J25,K25,"d"))/30,0) -> 12 | ... V26: =ROUND((DATEDIF(U25,V25,"d"))/30,0) -> 1
B27: 时间序列（年） | C27: 2023 | D27: 2024 | E27: 2025 | F27: 2026 | G27: 2027 | H27: 2028 | I27: 2029 | J27: 2030 | K27: 2031 | L27: 2032 | M27: 2033 | N27: 2034 | O27: 2035 | P27: 2036 | Q27: 2037 | R27: 2038 | S27: 2039 | T27: 2040 | U27: 2041 | V27: 2042 | W27: 2043 | X27: 2044 | Y27: 2045 | Z27: 2046 | AA27: 2047 | AB27: 2048 | AC27: 2049 | AD27: 2050 | AE27: 2051 | AF27: 2052 | AG27: 2053 | AH27: 2054 | AI27: 2055 | AJ27: 2056 | AK27: 2057 | AL27: 2058 | AM27: 2059 | AN27: 2060 | AO27: 2061 | AP27: 2062 | AQ27: 2063 | AR27: 2064 | AS27: 2065 | AT27: 2066 | AU27: 2067 | AV27: 2068 | AW27: 2069 | AX27: 2070
B28: 当年折旧月份数（无形资产） | C28: =SUMIF($C$24:$V$24,C27,$C$26:$V$26) -> 0 | D28: =SUMIF($C$24:$V$24,D27,$C$26:$V$26) -> 0 | E28: =SUMIF($C$24:$V$24,E27,$C$26:$V$26) -> 0 | F28: =SUMIF($C$24:$V$24,F27,$C$26:$V$26) -> 0 | G28: =SUMIF($C$24:$V$24,G27,$C$26:$V$26) -> 0 | H28: =SUMIF($C$24:$V$24,H27,$C$26:$V$26) -> 0 | I28: =SUMIF($C$24:$V$24,I27,$C$26:$V$26) -> 11 | J28: =SUMIF($C$24:$V$24,J27,$C$26:$V$26) -> 12 | ... AX28: =SUMIF($C$24:$V$24,AX27,$C$26:$V$26) -> 0
B29: 首批投产（储能资产）折旧开始-结束时点 | C29: =参数输入表!$D$36 -> 47150 | D29: =参数输入表!$D$36+参数输入表!$I$627*365+INT(参数输入表!$I$627/4) -> 51533
B30: （储能资产）折旧摊销时间序列 | C30: =YEAR(C31) -> 2029 | D30: =YEAR(D31) -> 2029 | E30: =YEAR(E31) -> 2030 | F30: =YEAR(F31) -> 2031 | G30: =YEAR(G31) -> 2032 | H30: =YEAR(H31) -> 2033 | I30: =YEAR(I31) -> 2034 | J30: =YEAR(J31) -> 2035 | ... P30: =YEAR(P31) -> 2041
C31: =C29 -> 47150 | D31: 47483 | E31: 47848 | F31: 48213 | G31: 48579 | H31: 48944 | I31: 49309 | J31: 49674 | K31: 50040 | L31: 50405 | M31: 50770 | N31: 51135 | O31: 51501 | P31: =D29 -> 51533
B32: =SUM(C32:AX32) -> 144 | C32: 0 | D32: =ROUND((DATEDIF(C31,D31,"d"))/30,0) -> 11 | E32: =ROUND((DATEDIF(D31,E31,"d"))/30,0) -> 12 | F32: =ROUND((DATEDIF(E31,F31,"d"))/30,0) -> 12 | G32: =ROUND((DATEDIF(F31,G31,"d"))/30,0) -> 12 | H32: =ROUND((DATEDIF(G31,H31,"d"))/30,0) -> 12 | I32: =ROUND((DATEDIF(H31,I31,"d"))/30,0) -> 12 | J32: =ROUND((DATEDIF(I31,J31,"d"))/30,0) -> 12 | K32: =ROUND((DATEDIF(J31,K31,"d"))/30,0) -> 12 | ... P32: =ROUND((DATEDIF(O31,P31,"d"))/30,0) -> 1
B33: 时间序列（年） | C33: 2023 | D33: 2024 | E33: 2025 | F33: 2026 | G33: 2027 | H33: 2028 | I33: 2029 | J33: 2030 | K33: 2031 | L33: 2032 | M33: 2033 | N33: 2034 | O33: 2035 | P33: 2036 | Q33: 2037 | R33: 2038 | S33: 2039 | T33: 2040 | U33: 2041 | V33: 2042 | W33: 2043 | X33: 2044 | Y33: 2045 | Z33: 2046 | AA33: 2047 | AB33: 2048 | AC33: 2049 | AD33: 2050 | AE33: 2051 | AF33: 2052 | AG33: 2053 | AH33: 2054 | AI33: 2055 | AJ33: 2056 | AK33: 2057 | AL33: 2058 | AM33: 2059 | AN33: 2060 | AO33: 2061 | AP33: 2062 | AQ33: 2063 | AR33: 2064 | AS33: 2065 | AT33: 2066 | AU33: 2067 | AV33: 2068 | AW33: 2069 | AX33: 2070
B34: 当年折旧月份数（储能资产） | C34: =SUMIF($C$30:$P$30,C33,$C$32:$P$32) -> 0 | D34: =SUMIF($C$30:$P$30,D33,$C$32:$P$32) -> 0 | E34: =SUMIF($C$30:$P$30,E33,$C$32:$P$32) -> 0 | F34: =SUMIF($C$30:$P$30,F33,$C$32:$P$32) -> 0 | G34: =SUMIF($C$30:$P$30,G33,$C$32:$P$32) -> 0 | H34: =SUMIF($C$30:$P$30,H33,$C$32:$P$32) -> 0 | I34: =SUMIF($C$30:$P$30,I33,$C$32:$P$32) -> 11 | J34: =SUMIF($C$30:$P$30,J33,$C$32:$P$32) -> 12 | ... AX34: =SUMIF($C$30:$P$30,AX33,$C$32:$P$32) -> 0
B35: 首批投产（固定资产3）折旧开始-结束时点 | C35: =参数输入表!$D$36 -> 47150 | D35: =参数输入表!$D$36+参数输入表!$I$632*365+INT(参数输入表!$I$632/4) -> 54455
B36: （固定资产3）折旧摊销时间序列 | C36: =YEAR(C37) -> 2029 | D36: =YEAR(D37) -> 2029 | E36: =YEAR(E37) -> 2030 | F36: =YEAR(F37) -> 2031 | G36: =YEAR(G37) -> 2032 | H36: =YEAR(H37) -> 2033 | I36: =YEAR(I37) -> 2034 | J36: =YEAR(J37) -> 2035 | ... X36: =YEAR(X37) -> 2049
C37: =C35 -> 47150 | D37: 47483 | E37: 47848 | F37: 48213 | G37: 48579 | H37: 48944 | I37: 49309 | J37: 49674 | K37: 50040 | L37: 50405 | M37: 50770 | N37: 51135 | O37: 51501 | P37: 51866 | Q37: 52231 | R37: 52596 | S37: 52962 | T37: 53327 | U37: 53692 | V37: 54057 | W37: 54423 | X37: =D35 -> 54455
B38: =SUM(C38:AX38) -> 240 | C38: 0 | D38: =ROUND((DATEDIF(C37,D37,"d"))/30,0) -> 11 | E38: =ROUND((DATEDIF(D37,E37,"d"))/30,0) -> 12 | F38: =ROUND((DATEDIF(E37,F37,"d"))/30,0) -> 12 | G38: =ROUND((DATEDIF(F37,G37,"d"))/30,0) -> 12 | H38: =ROUND((DATEDIF(G37,H37,"d"))/30,0) -> 12 | I38: =ROUND((DATEDIF(H37,I37,"d"))/30,0) -> 12 | J38: =ROUND((DATEDIF(I37,J37,"d"))/30,0) -> 12 | K38: =ROUND((DATEDIF(J37,K37,"d"))/30,0) -> 12 | ... X38: =ROUND((DATEDIF(W37,X37,"d"))/30,0) -> 1
B39: 时间序列（年） | C39: 2023 | D39: 2024 | E39: 2025 | F39: 2026 | G39: 2027 | H39: 2028 | I39: 2029 | J39: 2030 | K39: 2031 | L39: 2032 | M39: 2033 | N39: 2034 | O39: 2035 | P39: 2036 | Q39: 2037 | R39: 2038 | S39: 2039 | T39: 2040 | U39: 2041 | V39: 2042 | W39: 2043 | X39: 2044 | Y39: 2045 | Z39: 2046 | AA39: 2047 | AB39: 2048 | AC39: 2049 | AD39: 2050 | AE39: 2051 | AF39: 2052 | AG39: 2053 | AH39: 2054 | AI39: 2055 | AJ39: 2056 | AK39: 2057 | AL39: 2058 | AM39: 2059 | AN39: 2060 | AO39: 2061 | AP39: 2062 | AQ39: 2063 | AR39: 2064 | AS39: 2065 | AT39: 2066 | AU39: 2067 | AV39: 2068 | AW39: 2069 | AX39: 2070
B40: 当年折旧月份数（固定资产3） | C40: =SUMIF($C$36:$X$36,C39,$C$38:$X$38) -> 0 | D40: =SUMIF($C$36:$X$36,D39,$C$38:$X$38) -> 0 | E40: =SUMIF($C$36:$X$36,E39,$C$38:$X$38) -> 0 | F40: =SUMIF($C$36:$X$36,F39,$C$38:$X$38) -> 0 | G40: =SUMIF($C$36:$X$36,G39,$C$38:$X$38) -> 0 | H40: =SUMIF($C$36:$X$36,H39,$C$38:$X$38) -> 0 | I40: =SUMIF($C$36:$X$36,I39,$C$38:$X$38) -> 11 | J40: =SUMIF($C$36:$X$36,J39,$C$38:$X$38) -> 12 | ... AX40: =SUMIF($C$36:$X$36,AX39,$C$38:$X$38) -> 0
B41: Check固定资产 | C41: =B20-参数输入表!$I$622*12=0 -> TRUE | D41: =SUM(C22:AX22)-B20=0 -> TRUE
B42: Check无形资产 | C42: =B26-参数输入表!$I$638*12=0 -> TRUE | D42: =SUM(C28:AX28)-B26=0 -> TRUE
B43: Check（储能资产） | C43: =B32-参数输入表!$I$627*12=0 -> TRUE | D43: =SUM(C34:AX34)-B32=0 -> TRUE
B44: Check（固定资产3） | C44: =B38-参数输入表!$I$632*12=0 -> TRUE | D44: =SUM(C40:AX40)-B38=0 -> TRUE
...

Sheet 投产&达产比例
C2: 关键时间节点参数 （设备设施平均达产率） | G2: 关键时间节点参数 （设备设施累计投产比例）
C3: =参数输入表!I5 -> 44958 | D3: 0 | G3: =参数输入表!I5 -> 44958 | H3: 0
C4: =参数输入表!D42 -> 47150 | D4: =参数输入表!I42 -> 0 | F4: 首批投产 | G4: =参数输入表!D36 -> 47150 | H4: =H3+参数输入表!I36 -> 0
C5: =参数输入表!D43 -> 47362 | D5: =参数输入表!I43 -> 0 | F5: 第二批投产 | G5: =参数输入表!D37 -> 47362 | H5: =H4+参数输入表!I37 -> 0
C6: =参数输入表!D44 -> 47543 | D6: =参数输入表!I44 -> 0 | F6: 第三批投产 | G6: =参数输入表!D38 -> 47543 | H6: =H5+参数输入表!I38 -> 0
C7: =参数输入表!D45 -> 47696 | D7: =参数输入表!I45 -> 1 | F7: 完全投产 | G7: =参数输入表!D39 -> 47696 | H7: =H6+参数输入表!I39 -> 1
C9: 投产设施月平均达产率 | G9: 投产比例（生产） | K9: 投产比例（确认资产） | O9: 项目月达产率
B10: =YEAR(C10) -> 2023 | C10: 44985 | D10: =D3 -> 0 | F10: =YEAR(G10) -> 2023 | G10: 44985 | H10: =H3 -> 0 | J10: =YEAR(K10) -> 2023 | K10: =G3 -> 44958 | L10: =IF(K10=参数输入表!$I$7,100%,H10) -> 0 | N10: =YEAR(O10) -> 2023 | O10: 44985 | P10: =D10*H10 -> 0 | T10: 各年期末资产确认比例 | Y10: 年度达产率统计
B11: =YEAR(C11) -> 2023 | C11: 45016 | D11: =$D$10 -> 0 | F11: =YEAR(G11) -> 2023 | G11: 45016 | H11: =$H$10 -> 0 | J11: =YEAR(K11) -> 2023 | K11: 45016 | L11: =IF(K11=参数输入表!$I$7,100%,H11) -> 0 | N11: =YEAR(O11) -> 2023 | O11: 45016 | P11: =D11*H11 -> 0 | R11: 建设期第1年 | S11: 合作期第1年 | T11: 2023 | U11: =L20 -> 0 | W11: 建设期第1年 | X11: 合作期第1年 | Y11: 2023 | Z11: =SUMIF($N$10:$N$579,Y11,$P$10:$P$579)/12 -> 0
B12: =YEAR(C12) -> 2023 | C12: 45046 | D12: =$D$10 -> 0 | F12: =YEAR(G12) -> 2023 | G12: 45046 | H12: =$H$10 -> 0 | J12: =YEAR(K12) -> 2023 | K12: 45046 | L12: =IF(K12=参数输入表!$I$7,100%,H12) -> 0 | N12: =YEAR(O12) -> 2023 | O12: 45046 | P12: =D12*H12 -> 0 | R12: 建设期第2年 | S12: 合作期第2年 | T12: 2024 | U12: =L32 -> 0 | W12: 建设期第2年 | X12: 合作期第2年 | Y12: 2024 | Z12: =SUMIF($N$10:$N$579,Y12,$P$10:$P$579)/12 -> 0
B13: =YEAR(C13) -> 2023 | C13: 45077 | D13: =$D$10 -> 0 | F13: =YEAR(G13) -> 2023 | G13: 45077 | H13: =$H$10 -> 0 | J13: =YEAR(K13) -> 2023 | K13: 45077 | L13: =IF(K13=参数输入表!$I$7,100%,H13) -> 0 | N13: =YEAR(O13) -> 2023 | O13: 45077 | P13: =D13*H13 -> 0 | R13: 建设期第3年 | S13: 合作期第3年 | T13: 2025 | U13: =L44 -> 0 | W13: 建设期第3年 | X13: 合作期第3年 | Y13: 2025 | Z13: =SUMIF($N$10:$N$579,Y13,$P$10:$P$579)/12 -> 0
B14: =YEAR(C14) -> 2023 | C14: 45107 | D14: =$D$10 -> 0 | F14: =YEAR(G14) -> 2023 | G14: 45107 | H14: =$H$10 -> 0 | J14: =YEAR(K14) -> 2023 | K14: 45107 | L14: =IF(K14=参数输入表!$I$7,100%,H14) -> 0 | N14: =YEAR(O14) -> 2023 | O14: 45107 | P14: =D14*H14 -> 0 | R14: 建设期第4年 | S14: 合作期第4年 | T14: 2026 | U14: =L56 -> 0 | W14: 建设期第4年 | X14: 合作期第4年 | Y14: 2026 | Z14: =SUMIF($N$10:$N$579,Y14,$P$10:$P$579)/12 -> 0
B15: =YEAR(C15) -> 2023 | C15: 45138 | D15: =$D$10 -> 0 | F15: =YEAR(G15) -> 2023 | G15: 45138 | H15: =$H$10 -> 0 | J15: =YEAR(K15) -> 2023 | K15: 45138 | L15: =IF(K15=参数输入表!$I$7,100%,H15) -> 0 | N15: =YEAR(O15) -> 2023 | O15: 45138 | P15: =D15*H15 -> 0 | R15: 建设期第5年 | S15: 合作期第5年 | T15: 2027 | U15: =L68 -> 0 | W15: 建设期第5年 | X15: 合作期第5年 | Y15: 2027 | Z15: =SUMIF($N$10:$N$579,Y15,$P$10:$P$579)/12 -> 0
B16: =YEAR(C16) -> 2023 | C16: 45169 | D16: =$D$10 -> 0 | F16: =YEAR(G16) -> 2023 | G16: 45169 | H16: =$H$10 -> 0 | J16: =YEAR(K16) -> 2023 | K16: 45169 | L16: =IF(K16=参数输入表!$I$7,100%,H16) -> 0 | N16: =YEAR(O16) -> 2023 | O16: 45169 | P16: =D16*H16 -> 0 | R16: 建设期第6年 | S16: 合作期第6年 | T16: 2028 | U16: =L80 -> 0 | W16: 建设期第6年 | X16: 合作期第6年 | Y16: 2028 | Z16: =SUMIF($N$10:$N$579,Y16,$P$10:$P$579)/12 -> 0
B17: =YEAR(C17) -> 2023 | C17: 45199 | D17: =$D$10 -> 0 | F17: =YEAR(G17) -> 2023 | G17: 45199 | H17: =$H$10 -> 0 | J17: =YEAR(K17) -> 2023 | K17: 45199 | L17: =IF(K17=参数输入表!$I$7,100%,H17) -> 0 | N17: =YEAR(O17) -> 2023 | O17: 45199 | P17: =D17*H17 -> 0 | R17: 建设期第7年 | S17: 合作期第7年 | T17: 2029 | U17: =L92 -> 0 | W17: 建设期第7年 | X17: 合作期第7年 | Y17: 2029 | Z17: =SUMIF($N$10:$N$579,Y17,$P$10:$P$579)/12 -> 0
B18: =YEAR(C18) -> 2023 | C18: 45230 | D18: =$D$10 -> 0 | F18: =YEAR(G18) -> 2023 | G18: 45230 | H18: =$H$10 -> 0 | J18: =YEAR(K18) -> 2023 | K18: 45230 | L18: =IF(K18=参数输入表!$I$7,100%,H18) -> 0 | N18: =YEAR(O18) -> 2023 | O18: 45230 | P18: =D18*H18 -> 0 | R18: 建设期第8年 | S18: 合作期第8年 | T18: 2030 | U18: =L104 -> 1 | W18: 建设期第8年 | X18: 合作期第8年 | Y18: 2030 | Z18: =SUMIF($N$10:$N$579,Y18,$P$10:$P$579)/12 -> 0.41666667
B19: =YEAR(C19) -> 2023 | C19: 45260 | D19: =$D$10 -> 0 | F19: =YEAR(G19) -> 2023 | G19: 45260 | H19: =$H$10 -> 0 | J19: =YEAR(K19) -> 2023 | K19: 45260 | L19: =IF(K19=参数输入表!$I$7,100%,H19) -> 0 | N19: =YEAR(O19) -> 2023 | O19: 45260 | P19: =D19*H19 -> 0 | S19: 合作期第9年 | T19: 2031 | U19: =L116 -> 1 | X19: 合作期第9年 | Y19: 2031 | Z19: =SUMIF($N$10:$N$579,Y19,$P$10:$P$579)/12 -> 1
B20: =YEAR(C20) -> 2023 | C20: 45291 | D20: =$D$10 -> 0 | F20: =YEAR(G20) -> 2023 | G20: 45291 | H20: =$H$10 -> 0 | J20: =YEAR(K20) -> 2023 | K20: 45291 | L20: =IF(K20=参数输入表!$I$7,100%,H20) -> 0 | N20: =YEAR(O20) -> 2023 | O20: 45291 | P20: =D20*H20 -> 0 | S20: 合作期第10年 | T20: 2032 | U20: =L128 -> 1 | X20: 合作期第10年 | Y20: 2032 | Z20: =SUMIF($N$10:$N$579,Y20,$P$10:$P$579)/12 -> 1
B21: =YEAR(C21) -> 2024 | C21: 45322 | D21: =$D$10 -> 0 | F21: =YEAR(G21) -> 2024 | G21: 45322 | H21: =$H$10 -> 0 | J21: =YEAR(K21) -> 2024 | K21: 45322 | L21: =IF(K21=参数输入表!$I$7,100%,H21) -> 0 | N21: =YEAR(O21) -> 2024 | O21: 45322 | P21: =D21*H21 -> 0 | S21: 合作期第11年 | T21: 2033 | U21: =L140 -> 1 | X21: 合作期第11年 | Y21: 2033 | Z21: =SUMIF($N$10:$N$579,Y21,$P$10:$P$579)/12 -> 1
B22: =YEAR(C22) -> 2024 | C22: 45351 | D22: =$D$10 -> 0 | F22: =YEAR(G22) -> 2024 | G22: 45351 | H22: =$H$10 -> 0 | J22: =YEAR(K22) -> 2024 | K22: 45351 | L22: =IF(K22=参数输入表!$I$7,100%,H22) -> 0 | N22: =YEAR(O22) -> 2024 | O22: 45351 | P22: =D22*H22 -> 0 | S22: 合作期第12年 | T22: 2034 | U22: =L152 -> 1 | X22: 合作期第12年 | Y22: 2034 | Z22: =SUMIF($N$10:$N$579,Y22,$P$10:$P$579)/12 -> 1
B23: =YEAR(C23) -> 2024 | C23: 45382 | D23: =$D$10 -> 0 | F23: =YEAR(G23) -> 2024 | G23: 45382 | H23: =$H$10 -> 0 | J23: =YEAR(K23) -> 2024 | K23: 45382 | L23: =IF(K23=参数输入表!$I$7,100%,H23) -> 0 | N23: =YEAR(O23) -> 2024 | O23: 45382 | P23: =D23*H23 -> 0 | S23: 合作期第13年 | T23: 2035 | U23: =L164 -> 1 | X23: 合作期第13年 | Y23: 2035 | Z23: =SUMIF($N$10:$N$579,Y23,$P$10:$P$579)/12 -> 1
B24: =YEAR(C24) -> 2024 | C24: 45412 | D24: =$D$10 -> 0 | F24: =YEAR(G24) -> 2024 | G24: 45412 | H24: =$H$10 -> 0 | J24: =YEAR(K24) -> 2024 | K24: 45412 | L24: =IF(K24=参数输入表!$I$7,100%,H24) -> 0 | N24: =YEAR(O24) -> 2024 | O24: 45412 | P24: =D24*H24 -> 0 | S24: 合作期第14年 | T24: 2036 | U24: =L176 -> 1 | X24: 合作期第14年 | Y24: 2036 | Z24: =SUMIF($N$10:$N$579,Y24,$P$10:$P$579)/12 -> 1
B25: =YEAR(C25) -> 2024 | C25: 45443 | D25: =$D$10 -> 0 | F25: =YEAR(G25) -> 2024 | G25: 45443 | H25: =$H$10 -> 0 | J25: =YEAR(K25) -> 2024 | K25: 45443 | L25: =IF(K25=参数输入表!$I$7,100%,H25) -> 0 | N25: =YEAR(O25) -> 2024 | O25: 45443 | P25: =D25*H25 -> 0 | S25: 合作期第15年 | T25: 2037 | U25: =L188 -> 1 | X25: 合作期第15年 | Y25: 2037 | Z25: =SUMIF($N$10:$N$579,Y25,$P$10:$P$579)/12 -> 1
B26: =YEAR(C26) -> 2024 | C26: 45473 | D26: =$D$10 -> 0 | F26: =YEAR(G26) -> 2024 | G26: 45473 | H26: =$H$10 -> 0 | J26: =YEAR(K26) -> 2024 | K26: 45473 | L26: =IF(K26=参数输入表!$I$7,100%,H26) -> 0 | N26: =YEAR(O26) -> 2024 | O26: 45473 | P26: =D26*H26 -> 0 | S26: 合作期第16年 | T26: 2038 | U26: =L200 -> 1 | X26: 合作期第16年 | Y26: 2038 | Z26: =SUMIF($N$10:$N$579,Y26,$P$10:$P$579)/12 -> 1
B27: =YEAR(C27) -> 2024 | C27: 45504 | D27: =$D$10 -> 0 | F27: =YEAR(G27) -> 2024 | G27: 45504 | H27: =$H$10 -> 0 | J27: =YEAR(K27) -> 2024 | K27: 45504 | L27: =IF(K27=参数输入表!$I$7,100%,H27) -> 0 | N27: =YEAR(O27) -> 2024 | O27: 45504 | P27: =D27*H27 -> 0 | S27: 合作期第17年 | T27: 2039 | U27: =L212 -> 1 | X27: 合作期第17年 | Y27: 2039 | Z27: =SUMIF($N$10:$N$579,Y27,$P$10:$P$579)/12 -> 1
B28: =YEAR(C28) -> 2024 | C28: 45535 | D28: =$D$10 -> 0 | F28: =YEAR(G28) -> 2024 | G28: 45535 | H28: =$H$10 -> 0 | J28: =YEAR(K28) -> 2024 | K28: 45535 | L28: =IF(K28=参数输入表!$I$7,100%,H28) -> 0 | N28: =YEAR(O28) -> 2024 | O28: 45535 | P28: =D28*H28 -> 0 | S28: 合作期第18年 | T28: 2040 | U28: =L224 -> 1 | X28: 合作期第18年 | Y28: 2040 | Z28: =SUMIF($N$10:$N$579,Y28,$P$10:$P$579)/12 -> 1
B29: =YEAR(C29) -> 2024 | C29: 45565 | D29: =$D$10 -> 0 | F29: =YEAR(G29) -> 2024 | G29: 45565 | H29: =$H$10 -> 0 | J29: =YEAR(K29) -> 2024 | K29: 45565 | L29: =IF(K29=参数输入表!$I$7,100%,H29) -> 0 | N29: =YEAR(O29) -> 2024 | O29: 45565 | P29: =D29*H29 -> 0 | S29: 合作期第19年 | T29: 2041 | U29: =L236 -> 1 | X29: 合作期第19年 | Y29: 2041 | Z29: =SUMIF($N$10:$N$579,Y29,$P$10:$P$579)/12 -> 1
B30: =YEAR(C30) -> 2024 | C30: 45596 | D30: =$D$10 -> 0 | F30: =YEAR(G30) -> 2024 | G30: 45596 | H30: =$H$10 -> 0 | J30: =YEAR(K30) -> 2024 | K30: 45596 | L30: =IF(K30=参数输入表!$I$7,100%,H30) -> 0 | N30: =YEAR(O30) -> 2024 | O30: 45596 | P30: =D30*H30 -> 0 | S30: 合作期第20年 | T30: 2042 | U30: =L248 -> 1 | X30: 合作期第20年 | Y30: 2042 | Z30: =SUMIF($N$10:$N$579,Y30,$P$10:$P$579)/12 -> 1
B31: =YEAR(C31) -> 2024 | C31: 45626 | D31: =$D$10 -> 0 | F31: =YEAR(G31) -> 2024 | G31: 45626 | H31: =$H$10 -> 0 | J31: =YEAR(K31) -> 2024 | K31: 45626 | L31: =IF(K31=参数输入表!$I$7,100%,H31) -> 0 | N31: =YEAR(O31) -> 2024 | O31: 45626 | P31: =D31*H31 -> 0 | S31: 合作期第21年 | T31: 2043 | U31: =L260 -> 1 | X31: 合作期第21年 | Y31: 2043 | Z31: =SUMIF($N$10:$N$579,Y31,$P$10:$P$579)/12 -> 1
B32: =YEAR(C32) -> 2024 | C32: 45657 | D32: =$D$10 -> 0 | F32: =YEAR(G32) -> 2024 | G32: 45657 | H32: =$H$10 -> 0 | J32: =YEAR(K32) -> 2024 | K32: 45657 | L32: =IF(K32=参数输入表!$I$7,100%,H32) -> 0 | N32: =YEAR(O32) -> 2024 | O32: 45657 | P32: =D32*H32 -> 0 | S32: 合作期第22年 | T32: 2044 | U32: =L272 -> 1 | X32: 合作期第22年 | Y32: 2044 | Z32: =SUMIF($N$10:$N$579,Y32,$P$10:$P$579)/12 -> 1
B33: =YEAR(C33) -> 2025 | C33: 45688 | D33: =$D$10 -> 0 | F33: =YEAR(G33) -> 2025 | G33: 45688 | H33: =$H$10 -> 0 | J33: =YEAR(K33) -> 2025 | K33: 45688 | L33: =IF(K33=参数输入表!$I$7,100%,H33) -> 0 | N33: =YEAR(O33) -> 2025 | O33: 45688 | P33: =D33*H33 -> 0 | S33: 合作期第23年 | T33: 2045 | U33: =L284 -> 1 | X33: 合作期第23年 | Y33: 2045 | Z33: =SUMIF($N$10:$N$579,Y33,$P$10:$P$579)/12 -> 1
B34: =YEAR(C34) -> 2025 | C34: 45716 | D34: =$D$10 -> 0 | F34: =YEAR(G34) -> 2025 | G34: 45716 | H34: =$H$10 -> 0 | J34: =YEAR(K34) -> 2025 | K34: 45716 | L34: =IF(K34=参数输入表!$I$7,100%,H34) -> 0 | N34: =YEAR(O34) -> 2025 | O34: 45716 | P34: =D34*H34 -> 0 | S34: 合作期第24年 | T34: 2046 | U34: =L296 -> 1 | X34: 合作期第24年 | Y34: 2046 | Z34: =SUMIF($N$10:$N$579,Y34,$P$10:$P$579)/12 -> 1
B35: =YEAR(C35) -> 2025 | C35: 45747 | D35: =$D$10 -> 0 | F35: =YEAR(G35) -> 2025 | G35: 45747 | H35: =$H$10 -> 0 | J35: =YEAR(K35) -> 2025 | K35: 45747 | L35: =IF(K35=参数输入表!$I$7,100%,H35) -> 0 | N35: =YEAR(O35) -> 2025 | O35: 45747 | P35: =D35*H35 -> 0 | S35: 合作期第25年 | T35: 2047 | U35: =L308 -> 1 | X35: 合作期第25年 | Y35: 2047 | Z35: =SUMIF($N$10:$N$579,Y35,$P$10:$P$579)/12 -> 1
B36: =YEAR(C36) -> 2025 | C36: 45777 | D36: =$D$10 -> 0 | F36: =YEAR(G36) -> 2025 | G36: 45777 | H36: =$H$10 -> 0 | J36: =YEAR(K36) -> 2025 | K36: 45777 | L36: =IF(K36=参数输入表!$I$7,100%,H36) -> 0 | N36: =YEAR(O36) -> 2025 | O36: 45777 | P36: =D36*H36 -> 0 | S36: 合作期第26年 | T36: 2048 | U36: =L320 -> 1 | X36: 合作期第26年 | Y36: 2048 | Z36: =SUMIF($N$10:$N$579,Y36,$P$10:$P$579)/12 -> 1
B37: =YEAR(C37) -> 2025 | C37: 45808 | D37: =$D$10 -> 0 | F37: =YEAR(G37) -> 2025 | G37: 45808 | H37: =$H$10 -> 0 | J37: =YEAR(K37) -> 2025 | K37: 45808 | L37: =IF(K37=参数输入表!$I$7,100%,H37) -> 0 | N37: =YEAR(O37) -> 2025 | O37: 45808 | P37: =D37*H37 -> 0 | S37: 合作期第27年 | T37: 2049 | U37: =L332 -> 1 | X37: 合作期第27年 | Y37: 2049 | Z37: =SUMIF($N$10:$N$579,Y37,$P$10:$P$579)/12 -> 1
B38: =YEAR(C38) -> 2025 | C38: 45838 | D38: =$D$10 -> 0 | F38: =YEAR(G38) -> 2025 | G38: 45838 | H38: =$H$10 -> 0 | J38: =YEAR(K38) -> 2025 | K38: 45838 | L38: =IF(K38=参数输入表!$I$7,100%,H38) -> 0 | N38: =YEAR(O38) -> 2025 | O38: 45838 | P38: =D38*H38 -> 0 | S38: 合作期第28年 | T38: 2050 | U38: =L344 -> 1 | X38: 合作期第28年 | Y38: 2050 | Z38: =SUMIF($N$10:$N$579,Y38,$P$10:$P$579)/12 -> 1
B39: =YEAR(C39) -> 2025 | C39: 45869 | D39: =$D$10 -> 0 | F39: =YEAR(G39) -> 2025 | G39: 45869 | H39: =$H$10 -> 0 | J39: =YEAR(K39) -> 2025 | K39: 45869 | L39: =IF(K39=参数输入表!$I$7,100%,H39) -> 0 | N39: =YEAR(O39) -> 2025 | O39: 45869 | P39: =D39*H39 -> 0 | S39: 合作期第29年 | T39: 2051 | U39: =L356 -> 1 | X39: 合作期第29年 | Y39: 2051 | Z39: =SUMIF($N$10:$N$579,Y39,$P$10:$P$579)/12 -> 1
B40: =YEAR(C40) -> 2025 | C40: 45900 | D40: =$D$10 -> 0 | F40: =YEAR(G40) -> 2025 | G40: 45900 | H40: =$H$10 -> 0 | J40: =YEAR(K40) -> 2025 | K40: 45900 | L40: =IF(K40=参数输入表!$I$7,100%,H40) -> 0 | N40: =YEAR(O40) -> 2025 | O40: 45900 | P40: =D40*H40 -> 0 | S40: 合作期第30年 | T40: 2052 | U40: =L368 -> 1 | X40: 合作期第30年 | Y40: 2052 | Z40: =SUMIF($N$10:$N$579,Y40,$P$10:$P$579)/12 -> 1
B41: =YEAR(C41) -> 2025 | C41: 45930 | D41: =$D$10 -> 0 | F41: =YEAR(G41) -> 2025 | G41: 45930 | H41: =$H$10 -> 0 | J41: =YEAR(K41) -> 2025 | K41: 45930 | L41: =IF(K41=参数输入表!$I$7,100%,H41) -> 0 | N41: =YEAR(O41) -> 2025 | O41: 45930 | P41: =D41*H41 -> 0 | S41: 合作期第31年 | T41: 2053 | U41: =L380 -> 1 | X41: 合作期第31年 | Y41: 2053 | Z41: =SUMIF($N$10:$N$579,Y41,$P$10:$P$579)/12 -> 1
B42: =YEAR(C42) -> 2025 | C42: 45961 | D42: =$D$10 -> 0 | F42: =YEAR(G42) -> 2025 | G42: 45961 | H42: =$H$10 -> 0 | J42: =YEAR(K42) -> 2025 | K42: 45961 | L42: =IF(K42=参数输入表!$I$7,100%,H42) -> 0 | N42: =YEAR(O42) -> 2025 | O42: 45961 | P42: =D42*H42 -> 0 | S42: 合作期第32年 | T42: 2054 | U42: =L392 -> 1 | X42: 合作期第32年 | Y42: 2054 | Z42: =SUMIF($N$10:$N$579,Y42,$P$10:$P$579)/12 -> 1
...

Sheet 投资概算明细
B2: 工程分年度投资输入表（可插入月度数据）
B3: 序号 | C3: 科目 | D3: 合计 | E3: 单位 | F3: 45016 | G3: 2023 | H3: 2024 | I3: 2025 | J3: 2026 | K3: 2027 | L3: 2028 | M3: 47361 | N3: 2029 | O3: 47695 | P3: 增值税税率
B4: 1 | C4: 枢纽工程 | D4: =SUM(F4:O4) -> 638349.96 | E4: 万元 | F4: =SUM(F5:F11) -> 22265.592 | G4: =SUM(G5:G11) -> 51953.048 | H4: =SUM(H5:H11) -> 69974.41 | I4: =SUM(I5:I11) -> 77779.18 | J4: =SUM(J5:J11) -> 85342.6 | K4: =SUM(K5:K11) -> 113182.66 | L4: =SUM(L5:L11) -> 101185.18 | M4: =SUM(M5:M11) -> 50715.138 | ... O4: =SUM(O5:O11) -> 32142.06
B5: 1.1 | C5: 施工辅助工程 | D5: =SUM(F5:O5) -> 62992.58 | E5: 万元 | F5: 4412.391 | G5: 10295.579 | H5: 19706.12 | I5: 15924.17 | J5: 5522.19 | K5: 1601.06 | L5: 1555.86 | M5: 1529.73 | N5: 1019.82 | O5: 1425.66 | P5: =参数输入表!G194 -> 0.09
B6: 1.2 | C6: 建筑工程 | D6: =SUM(F6:O6) -> 331236.41 | E6: 万元 | F6: 17853.201 | G6: 41657.469 | H6: 46778.98 | I6: 55122.11 | J6: 67791.02 | K6: 52983.1 | L6: 36031.24 | M6: 7002.258 | N6: 4668.172 | O6: 1348.86 | P6: =参数输入表!G195 -> 0.09
B7: 1.3 | C7: 环境保护和水土保持专项工程 | D7: =SUM(F7:O7) -> 17893.9 | E7: 万元 | H7: 3489.31 | I7: 3489.31 | J7: 2863.02 | K7: 2415.68 | L7: 2505.15 | M7: 751.542 | N7: 501.028 | O7: 1878.86 | P7: =参数输入表!G196 -> 0.09
B8: 1.4 | C8: 机电设备安装工程 | D8: =SUM(F8:O8) -> 68286.2 | E8: 万元 | I8: 3243.59 | J8: 3243.59 | K8: 19461.57 | L8: 13315.82 | M8: 12291.516 | N8: 8194.344 | O8: 8535.77 | P8: =参数输入表!G197 -> 0.09
B9: 1.5 | C9: 金属结构设备安装工程 | D9: =SUM(F9:O9) -> 157940.87 | E9: 万元 | J9: 5922.78 | K9: 36721.25 | L9: 47777.11 | M9: 29140.092 | N9: 19426.728 | O9: 18952.91 | P9: =参数输入表!G198 -> 0.09
B10: 1.6 | C10: 机电设备采购工程 | D10: =SUM(F10:O10) -> 0 | E10: 万元 | P10: =参数输入表!G199 -> 0.13
B11: 1.7 | C11: 金属结构设备采购工程 | D11: =SUM(F11:O11) -> 0 | E11: 万元 | P11: =参数输入表!G200 -> 0.13
B12: 2 | C12: 建设征地和移民安置补偿费用 | D12: =SUM(F12:O12) -> 5205.27 | E12: 万元 | F12: 697.725 | G12: 1628.025 | H12: 2325.75 | I12: 332.26 | J12: 193.82 | M12: 16.614 | N12: 11.076 | P12: =参数输入表!G201 -> 0
B13: 3 | C13: 独立费用 | D13: =SUM(F13:O13) -> 122855.89 | E13: 万元 | F13: =SUM(F14:F17) -> 4309.572 | G13: =SUM(G14:G17) -> 10055.668 | H13: =SUM(H14:H17) -> 14510.03 | I13: =SUM(I14:I17) -> 17514.68 | J13: =SUM(J14:J17) -> 16533.47 | K13: =SUM(K14:K17) -> 17305.88 | L13: =SUM(L14:L17) -> 17315.25 | M13: =SUM(M14:M17) -> 8799.102 | ... O13: =SUM(O14:O17) -> 10646.17
B14: 3.1 | C14: 建设管理费 | D14: =SUM(F14:O14) -> 54324.05 | E14: 万元 | F14: 1333.542 | G14: 3111.598 | H14: 6381.84 | I14: 8283.43 | J14: 7074.83 | K14: 9259.39 | L14: 9470.09 | M14: 4203.762 | N14: 2802.508 | O14: 2403.06 | P14: =参数输入表!G203 -> 0.06
B15: 3.2 | C15: 生产准备费 | D15: =SUM(F15:O15) -> 8001.3 | E15: 万元 | K15: 663.35 | L15: 663.35 | M15: 936.234 | N15: 624.156 | O15: 5114.21 | P15: =参数输入表!G204 -> 0
B16: 3.3 | C16: 科研勘查设计费 | D16: =SUM(F16:O16) -> 56990.05 | E16: 万元 | F16: 2976.03 | G16: 6944.07 | H16: 7470.1 | I16: 8269.11 | J16: 8548.51 | K16: 6498.01 | L16: 7056.81 | M16: 3659.106 | N16: 2439.404 | O16: 3128.9 | P16: =参数输入表!G205 -> 0.06
B17: 3.4 | C17: 其他税费 | D17: =SUM(F17:O17) -> 3540.49 | E17: 万元 | H17: 658.09 | I17: 962.14 | J17: 910.13 | K17: 885.13 | L17: 125 | P17: =参数输入表!G206 -> 0
B18: 4 | C18: 基本预备费 | D18: =SUM(F18:O18) -> 38197.3 | E18: 万元 | F18: 1091.844 | G18: 2547.636 | H18: 3374.56 | I18: 4507.7 | J18: 5248.71 | K18: 7941.96 | L18: 6618.49 | M18: 3050.244 | N18: 2033.496 | O18: 1782.66 | P18: =参数输入表!G207 -> 0.09
B19: 5 | C19: 送出线路投资 | D19: =SUM(F19:O19) -> 0 | E19: 万元 | P19: =参数输入表!G208 -> 0
B20: 6 | C20: 储能投资（配储情形） | D20: =SUM(F20:O20) -> 6000 | E20: 万元 | F20: 150 | G20: 350 | H20: 800 | I20: 900 | J20: 600 | K20: 1100 | L20: 1000 | M20: 360 | N20: 240 | O20: 500 | P20: =参数输入表!G209 -> 0.13
B21: 7 | C21: 静态投资 | D21: =SUM(F21:O21) -> 810608.42 | E21: 万元 | F21: =F4+F12+F13+F18+F19+F20 -> 28514.733 | G21: =G4+G12+G13+G18+G19+G20 -> 66534.377 | H21: =H4+H12+H13+H18+H19+H20 -> 90984.75 | I21: =I4+I12+I13+I18+I19+I20 -> 101033.82 | J21: =J4+J12+J13+J18+J19+J20 -> 107918.6 | K21: =K4+K12+K13+K18+K19+K20 -> 139530.5 | L21: =L4+L12+L13+L18+L19+L20 -> 126118.92 | M21: =M4+M12+M13+M18+M19+M20 -> 62941.098 | ... O21: =O4+O12+O13+O18+O19+O20 -> 45070.89
B22: 8 | C22: 价差预备费 | D22: =SUM(F22:O22) -> 59365.53 | E22: 万元 | H22: 1427.17 | I22: 3854.21 | J22: 6784.25 | K22: 13798.93 | L22: 14466.02 | M22: 8081.352 | N22: 5387.568 | O22: 5566.03 | P22: =参数输入表!G212 -> 0.09
B23: 9 | C23: 建设投资 | D23: =SUM(F23:O23) -> 869973.95 | E23: 万元 | F23: =F21+F22 -> 28514.733 | G23: =G21+G22 -> 66534.377 | H23: =H21+H22 -> 92411.92 | I23: =I21+I22 -> 104888.03 | J23: =J21+J22 -> 114702.85 | K23: =K21+K22 -> 153329.43 | L23: =L21+L22 -> 140584.94 | M23: =M21+M22 -> 71022.45 | ... O23: =O21+O22 -> 50636.92
C24: 投资进度 | D24: =SUM(F24:O24) -> 1 | E24: 万元 | F24: =F23/$D$23 -> 0.032776537 | G24: =G23/$D$23 -> 0.076478585 | H24: =H23/$D$23 -> 0.10622378 | I24: =I23/$D$23 -> 0.12056456 | J24: =J23/$D$23 -> 0.1318463 | K24: =K23/$D$23 -> 0.176246 | L24: =L23/$D$23 -> 0.16159672 | M24: =M23/$D$23 -> 0.081637444 | ... O24: =O23/$D$23 -> 0.058205099
B26: 工程增值税进项税
B27: 序号 | C27: 科目 | D27: 合计 | E27: 单位 | F27: 45016 | G27: 2023 | H27: 2024 | I27: 2025 | J27: 2026 | K27: 2027 | L27: 2028 | M27: 47361 | N27: 2029 | O27: 47695
B28: 1 | C28: 枢纽工程 | D28: =SUM(F28:O28) -> 52707.795 | E28: 万元 | F28: =SUM(F29:F35) -> 1838.4434 | G28: =SUM(G29:G35) -> 4289.7012 | H28: =SUM(H29:H35) -> 5777.7036 | I28: =SUM(I29:I35) -> 6422.1341 | J28: =SUM(J29:J35) -> 7046.6367 | K28: =SUM(K29:K35) -> 9345.3572 | L28: =SUM(L29:L35) -> 8354.7396 | M28: =SUM(M29:M35) -> 4187.4885 | ... O28: =SUM(O29:O35) -> 2653.9316
B29: 1.1 | C29: 施工辅助工程 | D29: =SUM(F29:O29) -> 5201.2222 | E29: 万元 | F29: =F5/(1+$P$5)*$P$5 -> 364.32586 | G29: =G5/(1+$P$5)*$P$5 -> 850.09368 | H29: =H5/(1+$P$5)*$P$5 -> 1627.1108 | I29: =I5/(1+$P$5)*$P$5 -> 1314.8397 | J29: =J5/(1+$P$5)*$P$5 -> 455.96064 | K29: =K5/(1+$P$5)*$P$5 -> 132.19761 | L29: =L5/(1+$P$5)*$P$5 -> 128.4655 | M29: =M5/(1+$P$5)*$P$5 -> 126.30798 | ... O29: =O5/(1+$P$5)*$P$5 -> 117.71505
B30: 1.2 | C30: 建筑工程 | D30: =SUM(F30:O30) -> 27349.795 | E30: 万元 | F30: =F6/(1+$P$6)*$P$6 -> 1474.1175 | G30: =G6/(1+$P$6)*$P$6 -> 3439.6075 | H30: =H6/(1+$P$6)*$P$6 -> 3862.4846 | I30: =I6/(1+$P$6)*$P$6 -> 4551.3669 | J30: =J6/(1+$P$6)*$P$6 -> 5597.4237 | K30: =K6/(1+$P$6)*$P$6 -> 4374.7514 | L30: =L6/(1+$P$6)*$P$6 -> 2975.0565 | M30: =M6/(1+$P$6)*$P$6 -> 578.16809 | ... O30: =O6/(1+$P$6)*$P$6 -> 111.37376
B31: 1.3 | C31: 环境保护和水土保持专项工程 | D31: =SUM(F31:O31) -> 1477.478 | E31: 万元 | F31: =F7/(1+$P$7)*$P$7 -> 0 | G31: =G7/(1+$P$7)*$P$7 -> 0 | H31: =H7/(1+$P$7)*$P$7 -> 288.10817 | I31: =I7/(1+$P$7)*$P$7 -> 288.10817 | J31: =J7/(1+$P$7)*$P$7 -> 236.39615 | K31: =K7/(1+$P$7)*$P$7 -> 199.45982 | L31: =L7/(1+$P$7)*$P$7 -> 206.84725 | M31: =M7/(1+$P$7)*$P$7 -> 62.053927 | ... O31: =O7/(1+$P$7)*$P$7 -> 155.13523
B32: 1.4 | C32: 机电设备安装工程 | D32: =SUM(F32:O32) -> 5638.3101 | E32: 万元 | F32: =F8/(1+$P$8)*$P$8 -> 0 | G32: =G8/(1+$P$8)*$P$8 -> 0 | H32: =H8/(1+$P$8)*$P$8 -> 0 | I32: =I8/(1+$P$8)*$P$8 -> 267.81936 | J32: =J8/(1+$P$8)*$P$8 -> 267.81936 | K32: =K8/(1+$P$8)*$P$8 -> 1606.9186 | L32: =L8/(1+$P$8)*$P$8 -> 1099.4714 | M32: =M8/(1+$P$8)*$P$8 -> 1014.8958 | ... O32: =O8/(1+$P$8)*$P$8 -> 704.78835
B33: 1.5 | C33: 金属结构设备安装工程 | D33: =SUM(F33:O33) -> 13040.989 | E33: 万元 | F33: =F9/(1+$P$9)*$P$9 -> 0 | G33: =G9/(1+$P$9)*$P$9 -> 0 | H33: =H9/(1+$P$9)*$P$9 -> 0 | I33: =I9/(1+$P$9)*$P$9 -> 0 | J33: =J9/(1+$P$9)*$P$9 -> 489.03688 | K33: =K9/(1+$P$9)*$P$9 -> 3032.0298 | L33: =L9/(1+$P$9)*$P$9 -> 3944.899 | M33: =M9/(1+$P$9)*$P$9 -> 2406.0626 | ... O33: =O9/(1+$P$9)*$P$9 -> 1564.9192
B34: 1.6 | C34: 机电设备采购工程 | D34: =SUM(F34:O34) -> 0 | E34: 万元 | F34: =F10/(1+$P$10)*$P$10 -> 0 | G34: =G10/(1+$P$10)*$P$10 -> 0 | H34: =H10/(1+$P$10)*$P$10 -> 0 | I34: =I10/(1+$P$10)*$P$10 -> 0 | J34: =J10/(1+$P$10)*$P$10 -> 0 | K34: =K10/(1+$P$10)*$P$10 -> 0 | L34: =L10/(1+$P$10)*$P$10 -> 0 | M34: =M10/(1+$P$10)*$P$10 -> 0 | ... O34: =O10/(1+$P$10)*$P$10 -> 0
B35: 1.7 | C35: 金属结构设备采购工程 | D35: =SUM(F35:O35) -> 0 | E35: 万元 | F35: =F11/(1+$P$11)*$P$11 -> 0 | G35: =G11/(1+$P$11)*$P$11 -> 0 | H35: =H11/(1+$P$11)*$P$11 -> 0 | I35: =I11/(1+$P$11)*$P$11 -> 0 | J35: =J11/(1+$P$11)*$P$11 -> 0 | K35: =K11/(1+$P$11)*$P$11 -> 0 | L35: =L11/(1+$P$11)*$P$11 -> 0 | M35: =M11/(1+$P$11)*$P$11 -> 0 | ... O35: =O11/(1+$P$11)*$P$11 -> 0
B36: 2 | C36: 建设征地和移民安置补偿费用 | D36: =SUM(F36:O36) -> 0 | E36: 万元 | F36: =F12/(1+$P$12)*$P$12 -> 0 | G36: =G12/(1+$P$12)*$P$12 -> 0 | H36: =H12/(1+$P$12)*$P$12 -> 0 | I36: =I12/(1+$P$12)*$P$12 -> 0 | J36: =J12/(1+$P$12)*$P$12 -> 0 | K36: =K12/(1+$P$12)*$P$12 -> 0 | L36: =L12/(1+$P$12)*$P$12 -> 0 | M36: =M12/(1+$P$12)*$P$12 -> 0 | ... O36: =O12/(1+$P$12)*$P$12 -> 0
B37: 3 | C37: 独立费用 | D37: =SUM(F37:O37) -> 6300.7981 | E37: 万元 | F37: =SUM(F38:F41) -> 243.93804 | G37: =SUM(G38:G41) -> 569.18875 | H37: =SUM(H38:H41) -> 784.07208 | I37: =SUM(I38:I41) -> 936.93623 | J37: =SUM(J38:J41) -> 884.34 | K37: =SUM(K38:K41) -> 891.9283 | L37: =SUM(L38:L41) -> 935.48491 | M37: =SUM(M38:M41) -> 445.068 | ... O37: =SUM(O38:O41) -> 313.12981
B38: 3.1 | C38: 建设管理费 | D38: =SUM(F38:O38) -> 3074.9462 | E38: 万元 | F38: =F14/(1+$P$14)*$P$14 -> 75.483509 | G38: =G14/(1+$P$14)*$P$14 -> 176.12819 | H38: =H14/(1+$P$14)*$P$14 -> 361.23623 | I38: =I14/(1+$P$14)*$P$14 -> 468.8734 | J38: =J14/(1+$P$14)*$P$14 -> 400.46208 | K38: =K14/(1+$P$14)*$P$14 -> 524.11642 | L38: =L14/(1+$P$14)*$P$14 -> 536.04283 | M38: =M14/(1+$P$14)*$P$14 -> 237.94879 | ... O38: =O14/(1+$P$14)*$P$14 -> 136.02226
B39: 3.2 | C39: 生产准备费 | D39: =SUM(F39:O39) -> 0 | E39: 万元 | F39: =F15/(1+$P$15)*$P$15 -> 0 | G39: =G15/(1+$P$15)*$P$15 -> 0 | H39: =H15/(1+$P$15)*$P$15 -> 0 | I39: =I15/(1+$P$15)*$P$15 -> 0 | J39: =J15/(1+$P$15)*$P$15 -> 0 | K39: =K15/(1+$P$15)*$P$15 -> 0 | L39: =L15/(1+$P$15)*$P$15 -> 0 | M39: =M15/(1+$P$15)*$P$15 -> 0 | ... O39: =O15/(1+$P$15)*$P$15 -> 0
B40: 3.3 | C40: 科研勘查设计费 | D40: =SUM(F40:O40) -> 3225.8519 | E40: 万元 | F40: =F16/(1+$P$16)*$P$16 -> 168.45453 | G40: =G16/(1+$P$16)*$P$16 -> 393.06057 | H40: =H16/(1+$P$16)*$P$16 -> 422.83585 | I40: =I16/(1+$P$16)*$P$16 -> 468.06283 | J40: =J16/(1+$P$16)*$P$16 -> 483.87792 | K40: =K16/(1+$P$16)*$P$16 -> 367.81189 | L40: =L16/(1+$P$16)*$P$16 -> 399.44208 | M40: =M16/(1+$P$16)*$P$16 -> 207.11921 | ... O40: =O16/(1+$P$16)*$P$16 -> 177.10755
B41: 3.4 | C41: 其他税费 | D41: =SUM(F41:O41) -> 0 | E41: 万元 | F41: =F17/(1+$P$17)*$P$17 -> 0 | G41: =G17/(1+$P$17)*$P$17 -> 0 | H41: =H17/(1+$P$17)*$P$17 -> 0 | I41: =I17/(1+$P$17)*$P$17 -> 0 | J41: =J17/(1+$P$17)*$P$17 -> 0 | K41: =K17/(1+$P$17)*$P$17 -> 0 | L41: =L17/(1+$P$17)*$P$17 -> 0 | M41: =M17/(1+$P$17)*$P$17 -> 0 | ... O41: =O17/(1+$P$17)*$P$17 -> 0
B42: 4 | C42: 基本预备费 | D42: =SUM(F42:O42) -> 3153.9055 | E42: 万元 | F42: =F18/(1+$P$18)*$P$18 -> 90.152257 | G42: =G18/(1+$P$18)*$P$18 -> 210.35527 | H42: =H18/(1+$P$18)*$P$18 -> 278.63339 | I42: =I18/(1+$P$18)*$P$18 -> 372.19541 | J42: =J18/(1+$P$18)*$P$18 -> 433.37972 | K42: =K18/(1+$P$18)*$P$18 -> 655.75817 | L42: =L18/(1+$P$18)*$P$18 -> 546.48083 | M42: =M18/(1+$P$18)*$P$18 -> 251.85501 | ... O42: =O18/(1+$P$18)*$P$18 -> 147.19211
...

Sheet 表1-资金筹措及还本付息表
B2: 资金筹措表 | F2: =时间序列!D5 -> 2 | G2: =时间序列!E5 -> 9 | H2: =时间序列!F5 -> 12 | I2: =时间序列!G5 -> 12 | J2: =时间序列!H5 -> 12 | K2: =时间序列!I5 -> 12 | L2: =时间序列!J5 -> 12 | M2: =时间序列!K5 -> 8 | ... BE2: =时间序列!BC5 -> 7
B3: 序号 | C3: 项目 | D3: 合计 | E3: 单位 | F3: 45016 | G3: 45291 | H3: 45657 | I3: 46022 | J3: 46387 | K3: 46752 | L3: 47118 | M3: 47361 | N3: 47483 | O3: 47695 | P3: =参数输入表!I250 -> 47726 | Q3: 47848 | R3: 48213 | S3: 48579 | T3: 48944 | U3: 49309 | V3: 49674 | W3: 50040 | X3: 50405 | Y3: 50770 | Z3: 51135 | AA3: 51501 | AB3: 51866 | AC3: 52231 | AD3: 52596 | AE3: 52962 | AF3: 53327 | AG3: 53692 | AH3: 54057 | AI3: 54423 | AJ3: 54788 | AK3: 55153 | AL3: 55518 | AM3: 55884 | AN3: 56249 | AO3: 56614 | AP3: 56979 | AQ3: 57345 | AR3: 57710 | AS3: 58075 | AT3: 58440 | AU3: 58806 | AV3: 59171 | AW3: 59536 | AX3: 59901 | AY3: 60267 | AZ3: 60632 | BA3: 60997 | BB3: 61362 | BC3: 61728 | BD3: 62093 | BE3: 62458
G4: 1 | H4: 2 | I4: 3 | J4: 4 | K4: 5 | L4: 6 | N4: 7 | Q4: 8 | R4: 9 | S4: 10 | T4: 11 | U4: 12 | V4: 13 | W4: 14 | X4: 15 | Y4: 16 | Z4: 17 | AA4: 18 | AB4: 19 | AC4: 20 | AD4: 21 | AE4: 22 | AF4: 23 | AG4: 24 | AH4: 25 | AI4: 26 | AJ4: 27 | AK4: 28 | AL4: 29 | AM4: 30 | AN4: 31 | AO4: 32 | AP4: 33 | AQ4: 34 | AR4: 35 | AS4: 36 | AT4: 37 | AU4: 38 | AV4: 39 | AW4: 40 | AX4: 41 | AY4: 42 | AZ4: 43 | BA4: 44 | BB4: 45 | BC4: 46 | BD4: 47 | BE4: 48
C5: 施工进度安排 | D5: =SUM(F5:BE5) -> 1 | F5: =参数输入表!I14 -> 0.032776537 | G5: =参数输入表!I15 -> 0.076478585 | H5: =参数输入表!I16 -> 0.10622378 | I5: =参数输入表!I17 -> 0.12056456 | J5: =参数输入表!I18 -> 0.1318463 | K5: =参数输入表!I19 -> 0.176246 | L5: =参数输入表!I20 -> 0.16159672 | M5: =参数输入表!I21 -> 0.081637444 | N5: =参数输入表!I22 -> 0.054424963 | O5: =参数输入表!I23 -> 0.058205099 | P5: 0 | Q5: 0 | R5: 0 | S5: 0 | T5: 0 | U5: 0 | V5: 0 | W5: 0 | X5: 0 | Y5: 0 | Z5: 0 | AA5: 0 | AB5: 0 | AC5: 0 | AD5: 0 | AE5: 0 | AF5: 0 | AG5: 0 | AH5: 0 | AI5: 0 | AJ5: 0 | AK5: 0 | AL5: 0 | AM5: 0 | AN5: 0 | AO5: 0 | AP5: 0 | AQ5: 0 | AR5: 0 | AS5: 0 | AT5: 0 | AU5: 0 | AV5: 0 | AW5: 0 | AX5: 0 | AY5: 0 | AZ5: 0 | BA5: 0 | BB5: 0 | BC5: 0 | BD5: 0 | BE5: 0
C6: 平均投产比例 | F6: ='投产&达产比例'!H10 -> 0 | G6: =AVERAGE('投产&达产比例'!H12:H20) -> 0 | H6: =AVERAGE('投产&达产比例'!H21:H32) -> 0 | I6: =AVERAGE('投产&达产比例'!H33:H44) -> 0 | J6: =AVERAGE('投产&达产比例'!H45:H56) -> 0 | K6: =AVERAGE('投产&达产比例'!H57:H68) -> 0 | L6: =AVERAGE('投产&达产比例'!H69:H80) -> 0 | M6: =AVERAGE('投产&达产比例'!H81:H88) -> 0 | N6: =AVERAGE('投产&达产比例'!H89:H92) -> 0 | O6: =AVERAGE('投产&达产比例'!H93:H99) -> 0 | P6: =AVERAGE('投产&达产比例'!H100:H101) -> 1 | Q6: =AVERAGE('投产&达产比例'!H102:H104) -> 1 | R6: =AVERAGE('投产&达产比例'!H105:H116) -> 1 | S6: =AVERAGE('投产&达产比例'!H117:H128) -> 1 | T6: =AVERAGE('投产&达产比例'!H129:H140) -> 1 | U6: =AVERAGE('投产&达产比例'!H141:H152) -> 1 | V6: =AVERAGE('投产&达产比例'!H153:H164) -> 1 | W6: =AVERAGE('投产&达产比例'!H165:H176) -> 1 | X6: =AVERAGE('投产&达产比例'!H177:H188) -> 1 | Y6: =AVERAGE('投产&达产比例'!H189:H200) -> 1 | Z6: =AVERAGE('投产&达产比例'!H201:H212) -> 1 | AA6: =AVERAGE('投产&达产比例'!H213:H224) -> 1 | AB6: =AVERAGE('投产&达产比例'!H225:H236) -> 1 | AC6: =AVERAGE('投产&达产比例'!H237:H248) -> 1 | AD6: =AVERAGE('投产&达产比例'!H249:H260) -> 1 | AE6: =AVERAGE('投产&达产比例'!H261:H272) -> 1 | AF6: =AVERAGE('投产&达产比例'!H273:H284) -> 1 | AG6: =AVERAGE('投产&达产比例'!H285:H296) -> 1 | AH6: =AVERAGE('投产&达产比例'!H297:H308) -> 1 | AI6: =AVERAGE('投产&达产比例'!H309:H320) -> 1 | AJ6: =AVERAGE('投产&达产比例'!H321:H332) -> 1 | AK6: =AVERAGE('投产&达产比例'!H333:H344) -> 1 | AL6: =AVERAGE('投产&达产比例'!H345:H356) -> 1 | AM6: =AVERAGE('投产&达产比例'!H357:H368) -> 1 | AN6: =AVERAGE('投产&达产比例'!H369:H380) -> 1 | AO6: =AVERAGE('投产&达产比例'!H381:H392) -> 1 | AP6: =AVERAGE('投产&达产比例'!H393:H404) -> 1 | AQ6: =AVERAGE('投产&达产比例'!H405:H416) -> 1 | AR6: =AVERAGE('投产&达产比例'!H417:H428) -> 1 | AS6: =AVERAGE('投产&达产比例'!H429:H440) -> 1 | AT6: =AVERAGE('投产&达产比例'!H441:H452) -> 1 | AU6: =AVERAGE('投产&达产比例'!H453:H464) -> 1 | AV6: =AVERAGE('投产&达产比例'!H465:H476) -> 1 | AW6: =AVERAGE('投产&达产比例'!H477:H488) -> 1 | AX6: =AVERAGE('投产&达产比例'!H489:H500) -> 1 | AY6: =AVERAGE('投产&达产比例'!H501:H512) -> 1 | AZ6: =AVERAGE('投产&达产比例'!H513:H524) -> 1 | BA6: =AVERAGE('投产&达产比例'!H525:H536) -> 1 | BB6: =AVERAGE('投产&达产比例'!H537:H548) -> 1 | BC6: =AVERAGE('投产&达产比例'!H549:H560) -> 1 | BD6: =AVERAGE('投产&达产比例'!H561:H572) -> 1 | BE6: =AVERAGE('投产&达产比例'!H573:H579) -> 1
B7: 1 | C7: 动态总投资（自主投资） | D7: =D8+D9+D35 -> 973381.77 | E7: 万元 | F7: =SUM(F8:F9)+F35 -> 28262.72 | G7: =SUM(G8:G9)+G35 -> 67248.597 | H7: =SUM(H8:H9)+H35 -> 95902.936 | I7: =SUM(I8:I9)+I35 -> 111527.37 | J7: =SUM(J8:J9)+J35 -> 124982.58 | K7: =SUM(K8:K9)+K35 -> 167811.54 | L7: =SUM(L8:L9)+L35 -> 160422.33 | M7: =SUM(M8:M9)+M35 -> 87218.189 | ... BE7: =SUM(BE8:BE9)+BE35 -> 0
B8: 1.1 | C8: 工程总投资（自主投资） | D8: =SUM(F8:BE8) -> 859973.95 | E8: 万元 | F8: =参数输入表!$I$214*F5 -> 28186.968 | G8: =参数输入表!$I$214*G5 -> 65769.591 | H8: =参数输入表!$I$214*H5 -> 91349.682 | I8: =参数输入表!$I$214*I5 -> 103682.38 | J8: =参数输入表!$I$214*J5 -> 113384.39 | K8: =参数输入表!$I$214*K5 -> 151566.97 | L8: =参数输入表!$I$214*L5 -> 138968.97 | M8: =参数输入表!$I$214*M5 -> 70206.076 | ... BE8: =参数输入表!$I$214*BE5 -> 0
B9: 1.2 | C9: 建设期利息（资本化） | D9: =SUM(F9:BE9) -> 106971.73 | E9: 万元 | F9: =SUM(F10:F21) -> 75.752476 | G9: =SUM(G10:G21) -> 1479.0055 | H9: =SUM(H10:H21) -> 4553.2536 | I9: =SUM(I10:I21) -> 7844.9881 | J9: =SUM(J10:J21) -> 11598.191 | K9: =SUM(K10:K21) -> 16244.573 | L9: =SUM(L10:L21) -> 21453.352 | M9: =SUM(M10:M21) -> 17012.114 | ... BE9: =SUM(BE10:BE21) -> 0
C10: 45016 | D10: =SUM(F10:BE10) -> 6759.8858 | E10: 万元 | F10: =IF(F3-参数输入表!$I$250<=0,IF($C$10-F3>=0,$F$42/2*(参数输入表!$I$251/12)*F2*(1-F6),($F$41-$F$44)*(参数输入表!$I$251/12)*F2*(1-F6)),0) -> 0 | G10: =IF(G3-参数输入表!$I$250<=0,IF($C$10-G3>=0,$F$42/2*(参数输入表!$I$251/12)*G2*(1-G6),($F$41-$F$44)*(参数输入表!$I$251/12)*G2*(1-G6)),0) -> 683.60454 | H10: =IF(H3-参数输入表!$I$250<=0,IF($C$10-H3>=0,$F$42/2*(参数输入表!$I$251/12)*H2*(1-H6),($F$41-$F$44)*(参数输入表!$I$251/12)*H2*(1-H6)),0) -> 911.47272 | I10: =IF(I3-参数输入表!$I$250<=0,IF($C$10-I3>=0,$F$42/2*(参数输入表!$I$251/12)*I2*(1-I6),($F$41-$F$44)*(参数输入表!$I$251/12)*I2*(1-I6)),0) -> 911.47272 | J10: =IF(J3-参数输入表!$I$250<=0,IF($C$10-J3>=0,$F$42/2*(参数输入表!$I$251/12)*J2*(1-J6),($F$41-$F$44)*(参数输入表!$I$251/12)*J2*(1-J6)),0) -> 911.47272 | K10: =IF(K3-参数输入表!$I$250<=0,IF($C$10-K3>=0,$F$42/2*(参数输入表!$I$251/12)*K2*(1-K6),($F$41-$F$44)*(参数输入表!$I$251/12)*K2*(1-K6)),0) -> 911.47272 | L10: =IF(L3-参数输入表!$I$250<=0,IF($C$10-L3>=0,$F$42/2*(参数输入表!$I$251/12)*L2*(1-L6),($F$41-$F$44)*(参数输入表!$I$251/12)*L2*(1-L6)),0) -> 911.47272 | M10: =IF(M3-参数输入表!$I$250<=0,IF($C$10-M3>=0,$F$42/2*(参数输入表!$I$251/12)*M2*(1-M6),($F$41-$F$44)*(参数输入表!$I$251/12)*M2*(1-M6)),0) -> 607.64848 | ... BE10: =IF(BE3-参数输入表!$I$250<=0,IF($C$10-BE3>=0,$F$42/2*(参数输入表!$I$251/12)*BE2*(1-BE6),($F$41-$F$44)*(参数输入表!$I$251/12)*BE2*(1-BE6)),0) -> 0
C11: 45291 | D11: =SUM(F11:BE11) -> 15073.119 | E11: 万元 | G11: =IF(G3-参数输入表!$I$250<=0,IF($C$11-G3>=0,$G$42/2*(参数输入表!$I$251/12)*G2*(1-G6),($G$41-$G$44)*(参数输入表!$I$251/12)*G2*(1-G6)),0) -> 795.40099 | H11: =IF(H3-参数输入表!$I$250<=0,IF($C$11-H3>=0,$G$42/2*(参数输入表!$I$251/12)*H2*(1-H6),($G$41-$G$44)*(参数输入表!$I$251/12)*H2*(1-H6)),0) -> 2168.7672 | I11: =IF(I3-参数输入表!$I$250<=0,IF($C$11-I3>=0,$G$42/2*(参数输入表!$I$251/12)*I2*(1-I6),($G$41-$G$44)*(参数输入表!$I$251/12)*I2*(1-I6)),0) -> 2168.7672 | J11: =IF(J3-参数输入表!$I$250<=0,IF($C$11-J3>=0,$G$42/2*(参数输入表!$I$251/12)*J2*(1-J6),($G$41-$G$44)*(参数输入表!$I$251/12)*J2*(1-J6)),0) -> 2168.7672 | K11: =IF(K3-参数输入表!$I$250<=0,IF($C$11-K3>=0,$G$42/2*(参数输入表!$I$251/12)*K2*(1-K6),($G$41-$G$44)*(参数输入表!$I$251/12)*K2*(1-K6)),0) -> 2168.7672 | L11: =IF(L3-参数输入表!$I$250<=0,IF($C$11-L3>=0,$G$42/2*(参数输入表!$I$251/12)*L2*(1-L6),($G$41-$G$44)*(参数输入表!$I$251/12)*L2*(1-L6)),0) -> 2168.7672 | M11: =IF(M3-参数输入表!$I$250<=0,IF($C$11-M3>=0,$G$42/2*(参数输入表!$I$251/12)*M2*(1-M6),($G$41-$G$44)*(参数输入表!$I$251/12)*M2*(1-M6)),0) -> 1445.8448 | N11: =IF(N3-参数输入表!$I$250<=0,IF($C$11-N3>=0,$G$42/2*(参数输入表!$I$251/12)*N2*(1-N6),($G$41-$G$44)*(参数输入表!$I$251/12)*N2*(1-N6)),0) -> 722.92241 | ... BE11: =IF(BE3-参数输入表!$I$250<=0,IF($C$11-BE3>=0,$G$42/2*(参数输入表!$I$251/12)*BE2*(1-BE6),($G$41-$G$44)*(参数输入表!$I$251/12)*BE2*(1-BE6)),0) -> 0
C12: 45657 | D12: =SUM(F12:BE12) -> 18741.536 | E12: 万元 | H12: =IF(H3-参数输入表!$I$250<=0,IF($C$12-H3>=0,$H$42/2*(参数输入表!$I$251/12)*H2*(1-H6),($H$41-$H$44)*(参数输入表!$I$251/12)*H2*(1-H6)),0) -> 1473.0136 | I12: =IF(I3-参数输入表!$I$250<=0,IF($C$12-I3>=0,$H$42/2*(参数输入表!$I$251/12)*I2*(1-I6),($H$41-$H$44)*(参数输入表!$I$251/12)*I2*(1-I6)),0) -> 3092.8697 | J12: =IF(J3-参数输入表!$I$250<=0,IF($C$12-J3>=0,$H$42/2*(参数输入表!$I$251/12)*J2*(1-J6),($H$41-$H$44)*(参数输入表!$I$251/12)*J2*(1-J6)),0) -> 3092.8697 | K12: =IF(K3-参数输入表!$I$250<=0,IF($C$12-K3>=0,$H$42/2*(参数输入表!$I$251/12)*K2*(1-K6),($H$41-$H$44)*(参数输入表!$I$251/12)*K2*(1-K6)),0) -> 3092.8697 | L12: =IF(L3-参数输入表!$I$250<=0,IF($C$12-L3>=0,$H$42/2*(参数输入表!$I$251/12)*L2*(1-L6),($H$41-$H$44)*(参数输入表!$I$251/12)*L2*(1-L6)),0) -> 3092.8697 | M12: =IF(M3-参数输入表!$I$250<=0,IF($C$12-M3>=0,$H$42/2*(参数输入表!$I$251/12)*M2*(1-M6),($H$41-$H$44)*(参数输入表!$I$251/12)*M2*(1-M6)),0) -> 2061.9131 | N12: =IF(N3-参数输入表!$I$250<=0,IF($C$12-N3>=0,$H$42/2*(参数输入表!$I$251/12)*N2*(1-N6),($H$41-$H$44)*(参数输入表!$I$251/12)*N2*(1-N6)),0) -> 1030.9566 | O12: =IF(O3-参数输入表!$I$250<=0,IF($C$12-O3>=0,$H$42/2*(参数输入表!$I$251/12)*O2*(1-O6),($H$41-$H$44)*(参数输入表!$I$251/12)*O2*(1-O6)),0) -> 1804.174 | ... BE12: =IF(BE3-参数输入表!$I$250<=0,IF($C$12-BE3>=0,$H$42/2*(参数输入表!$I$251/12)*BE2*(1-BE6),($H$41-$H$44)*(参数输入表!$I$251/12)*BE2*(1-BE6)),0) -> 0
C13: 46022 | D13: =SUM(F13:BE13) -> 18157.018 | E13: 万元 | I13: =IF(I3-参数输入表!$I$250<=0,IF($C$13-I3>=0,$I$42/2*(参数输入表!$I$251/12)*I2*(1-I6),($I$41-$I$44)*(参数输入表!$I$251/12)*I2*(1-I6)),0) -> 1671.8784 | J13: =IF(J3-参数输入表!$I$250<=0,IF($C$13-J3>=0,$I$42/2*(参数输入表!$I$251/12)*J2*(1-J6),($I$41-$I$44)*(参数输入表!$I$251/12)*J2*(1-J6)),0) -> 3596.7578 | K13: =IF(K3-参数输入表!$I$250<=0,IF($C$13-K3>=0,$I$42/2*(参数输入表!$I$251/12)*K2*(1-K6),($I$41-$I$44)*(参数输入表!$I$251/12)*K2*(1-K6)),0) -> 3596.7578 | L13: =IF(L3-参数输入表!$I$250<=0,IF($C$13-L3>=0,$I$42/2*(参数输入表!$I$251/12)*L2*(1-L6),($I$41-$I$44)*(参数输入表!$I$251/12)*L2*(1-L6)),0) -> 3596.7578 | M13: =IF(M3-参数输入表!$I$250<=0,IF($C$13-M3>=0,$I$42/2*(参数输入表!$I$251/12)*M2*(1-M6),($I$41-$I$44)*(参数输入表!$I$251/12)*M2*(1-M6)),0) -> 2397.8385 | N13: =IF(N3-参数输入表!$I$250<=0,IF($C$13-N3>=0,$I$42/2*(参数输入表!$I$251/12)*N2*(1-N6),($I$41-$I$44)*(参数输入表!$I$251/12)*N2*(1-N6)),0) -> 1198.9193 | O13: =IF(O3-参数输入表!$I$250<=0,IF($C$13-O3>=0,$I$42/2*(参数输入表!$I$251/12)*O2*(1-O6),($I$41-$I$44)*(参数输入表!$I$251/12)*O2*(1-O6)),0) -> 2098.1087 | P13: =IF(P3-参数输入表!$I$250<=0,IF($C$13-P3>=0,$I$42/2*(参数输入表!$I$251/12)*P2*(1-P6),($I$41-$I$44)*(参数输入表!$I$251/12)*P2*(1-P6)),0) -> 0 | ... BE13: =IF(BE3-参数输入表!$I$250<=0,IF($C$13-BE3>=0,$I$42/2*(参数输入表!$I$251/12)*BE2*(1-BE6),($I$41-$I$44)*(参数输入表!$I$251/12)*BE2*(1-BE6)),0) -> 0
C14: 46387 | D14: =SUM(F14:BE14) -> 16271.622 | E14: 万元 | J14: =IF(J3-参数输入表!$I$250<=0,IF($C$14-J3>=0,$J$42/2*(参数输入表!$I$251/12)*J2*(1-J6),($J$41-$J$44)*(参数输入表!$I$251/12)*J2*(1-J6)),0) -> 1828.3232 | K14: =IF(K3-参数输入表!$I$250<=0,IF($C$14-K3>=0,$J$42/2*(参数输入表!$I$251/12)*K2*(1-K6),($J$41-$J$44)*(参数输入表!$I$251/12)*K2*(1-K6)),0) -> 4030.6881 | L14: =IF(L3-参数输入表!$I$250<=0,IF($C$14-L3>=0,$J$42/2*(参数输入表!$I$251/12)*L2*(1-L6),($J$41-$J$44)*(参数输入表!$I$251/12)*L2*(1-L6)),0) -> 4030.6881 | M14: =IF(M3-参数输入表!$I$250<=0,IF($C$14-M3>=0,$J$42/2*(参数输入表!$I$251/12)*M2*(1-M6),($J$41-$J$44)*(参数输入表!$I$251/12)*M2*(1-M6)),0) -> 2687.1254 | N14: =IF(N3-参数输入表!$I$250<=0,IF($C$14-N3>=0,$J$42/2*(参数输入表!$I$251/12)*N2*(1-N6),($J$41-$J$44)*(参数输入表!$I$251/12)*N2*(1-N6)),0) -> 1343.5627 | O14: =IF(O3-参数输入表!$I$250<=0,IF($C$14-O3>=0,$J$42/2*(参数输入表!$I$251/12)*O2*(1-O6),($J$41-$J$44)*(参数输入表!$I$251/12)*O2*(1-O6)),0) -> 2351.2347 | P14: =IF(P3-参数输入表!$I$250<=0,IF($C$14-P3>=0,$J$42/2*(参数输入表!$I$251/12)*P2*(1-P6),($J$41-$J$44)*(参数输入表!$I$251/12)*P2*(1-P6)),0) -> 0 | Q14: =IF(Q3-参数输入表!$I$250<=0,IF($C$14-Q3>=0,$J$42/2*(参数输入表!$I$251/12)*Q2*(1-Q6),($J$41-$J$44)*(参数输入表!$I$251/12)*Q2*(1-Q6)),0) -> 0 | ... BE14: =IF(BE3-参数输入表!$I$250<=0,IF($C$14-BE3>=0,$J$42/2*(参数输入表!$I$251/12)*BE2*(1-BE6),($J$41-$J$44)*(参数输入表!$I$251/12)*BE2*(1-BE6)),0) -> 0
C15: 46752 | D15: =SUM(F15:BE15) -> 16424.817 | E15: 万元 | K15: =IF(K3-参数输入表!$I$250<=0,IF($C$15-K3>=0,$K$42/2*(参数输入表!$I$251/12)*K2*(1-K6),($K$41-$K$44)*(参数输入表!$I$251/12)*K2*(1-K6)),0) -> 2444.0174 | L15: =IF(L3-参数输入表!$I$250<=0,IF($C$15-L3>=0,$K$42/2*(参数输入表!$I$251/12)*L2*(1-L6),($K$41-$K$44)*(参数输入表!$I$251/12)*L2*(1-L6)),0) -> 5411.9223 | M15: =IF(M3-参数输入表!$I$250<=0,IF($C$15-M3>=0,$K$42/2*(参数输入表!$I$251/12)*M2*(1-M6),($K$41-$K$44)*(参数输入表!$I$251/12)*M2*(1-M6)),0) -> 3607.9482 | N15: =IF(N3-参数输入表!$I$250<=0,IF($C$15-N3>=0,$K$42/2*(参数输入表!$I$251/12)*N2*(1-N6),($K$41-$K$44)*(参数输入表!$I$251/12)*N2*(1-N6)),0) -> 1803.9741 | O15: =IF(O3-参数输入表!$I$250<=0,IF($C$15-O3>=0,$K$42/2*(参数输入表!$I$251/12)*O2*(1-O6),($K$41-$K$44)*(参数输入表!$I$251/12)*O2*(1-O6)),0) -> 3156.9547 | P15: =IF(P3-参数输入表!$I$250<=0,IF($C$15-P3>=0,$K$42/2*(参数输入表!$I$251/12)*P2*(1-P6),($K$41-$K$44)*(参数输入表!$I$251/12)*P2*(1-P6)),0) -> 0 | Q15: =IF(Q3-参数输入表!$I$250<=0,IF($C$15-Q3>=0,$K$42/2*(参数输入表!$I$251/12)*Q2*(1-Q6),($K$41-$K$44)*(参数输入表!$I$251/12)*Q2*(1-Q6)),0) -> 0 | R15: =IF(R3-参数输入表!$I$250<=0,IF($C$15-R3>=0,$K$42/2*(参数输入表!$I$251/12)*R2*(1-R6),($K$41-$K$44)*(参数输入表!$I$251/12)*R2*(1-R6)),0) -> 0 | ... BE15: =IF(BE3-参数输入表!$I$250<=0,IF($C$15-BE3>=0,$K$42/2*(参数输入表!$I$251/12)*BE2*(1-BE6),($K$41-$K$44)*(参数输入表!$I$251/12)*BE2*(1-BE6)),0) -> 0
C16: 47118 | D16: =SUM(F16:BE16) -> 10432.44 | E16: 万元 | L16: =IF(L3-参数输入表!$I$250<=0,IF($C$16-L3>=0,$L$42/2*(参数输入表!$I$251/12)*L2*(1-L6),($L$41-$L$44)*(参数输入表!$I$251/12)*L2*(1-L6)),0) -> 2240.8747 | M16: =IF(M3-参数输入表!$I$250<=0,IF($C$16-M3>=0,$L$42/2*(参数输入表!$I$251/12)*M2*(1-M6),($L$41-$L$44)*(参数输入表!$I$251/12)*M2*(1-M6)),0) -> 3449.08 | N16: =IF(N3-参数输入表!$I$250<=0,IF($C$16-N3>=0,$L$42/2*(参数输入表!$I$251/12)*N2*(1-N6),($L$41-$L$44)*(参数输入表!$I$251/12)*N2*(1-N6)),0) -> 1724.54 | O16: =IF(O3-参数输入表!$I$250<=0,IF($C$16-O3>=0,$L$42/2*(参数输入表!$I$251/12)*O2*(1-O6),($L$41-$L$44)*(参数输入表!$I$251/12)*O2*(1-O6)),0) -> 3017.945 | P16: =IF(P3-参数输入表!$I$250<=0,IF($C$16-P3>=0,$L$42/2*(参数输入表!$I$251/12)*P2*(1-P6),($L$41-$L$44)*(参数输入表!$I$251/12)*P2*(1-P6)),0) -> 0 | Q16: =IF(Q3-参数输入表!$I$250<=0,IF($C$16-Q3>=0,$L$42/2*(参数输入表!$I$251/12)*Q2*(1-Q6),($L$41-$L$44)*(参数输入表!$I$251/12)*Q2*(1-Q6)),0) -> 0 | R16: =IF(R3-参数输入表!$I$250<=0,IF($C$16-R3>=0,$L$42/2*(参数输入表!$I$251/12)*R2*(1-R6),($L$41-$L$44)*(参数输入表!$I$251/12)*R2*(1-R6)),0) -> 0 | S16: =IF(S3-参数输入表!$I$250<=0,IF($C$16-S3>=0,$L$42/2*(参数输入表!$I$251/12)*S2*(1-S6),($L$41-$L$44)*(参数输入表!$I$251/12)*S2*(1-S6)),0) -> 0 | ... BE16: =IF(BE3-参数输入表!$I$250<=0,IF($C$16-BE3>=0,$L$42/2*(参数输入表!$I$251/12)*BE2*(1-BE6),($L$41-$L$44)*(参数输入表!$I$251/12)*BE2*(1-BE6)),0) -> 0
C17: 47361 | D17: =SUM(F17:BE17) -> 3333.103 | E17: 万元 | M17: =IF(M3-参数输入表!$I$250<=0,IF($C$17-M3>=0,$M$42/2*(参数输入表!$I$251/12)*M2*(1-M6),($M$41-$M$44)*(参数输入表!$I$251/12)*M2*(1-M6)),0) -> 754.71531 | N17: =IF(N3-参数输入表!$I$250<=0,IF($C$17-N3>=0,$M$42/2*(参数输入表!$I$251/12)*N2*(1-N6),($M$41-$M$44)*(参数输入表!$I$251/12)*N2*(1-N6)),0) -> 937.59554 | O17: =IF(O3-参数输入表!$I$250<=0,IF($C$17-O3>=0,$M$42/2*(参数输入表!$I$251/12)*O2*(1-O6),($M$41-$M$44)*(参数输入表!$I$251/12)*O2*(1-O6)),0) -> 1640.7922 | P17: =IF(P3-参数输入表!$I$250<=0,IF($C$17-P3>=0,$M$42/2*(参数输入表!$I$251/12)*P2*(1-P6),($M$41-$M$44)*(参数输入表!$I$251/12)*P2*(1-P6)),0) -> 0 | Q17: =IF(Q3-参数输入表!$I$250<=0,IF($C$17-Q3>=0,$M$42/2*(参数输入表!$I$251/12)*Q2*(1-Q6),($M$41-$M$44)*(参数输入表!$I$251/12)*Q2*(1-Q6)),0) -> 0 | R17: =IF(R3-参数输入表!$I$250<=0,IF($C$17-R3>=0,$M$42/2*(参数输入表!$I$251/12)*R2*(1-R6),($M$41-$M$44)*(参数输入表!$I$251/12)*R2*(1-R6)),0) -> 0 | S17: =IF(S3-参数输入表!$I$250<=0,IF($C$17-S3>=0,$M$42/2*(参数输入表!$I$251/12)*S2*(1-S6),($M$41-$M$44)*(参数输入表!$I$251/12)*S2*(1-S6)),0) -> 0 | T17: =IF(T3-参数输入表!$I$250<=0,IF($C$17-T3>=0,$M$42/2*(参数输入表!$I$251/12)*T2*(1-T6),($M$41-$M$44)*(参数输入表!$I$251/12)*T2*(1-T6)),0) -> 0 | ... BE17: =IF(BE3-参数输入表!$I$250<=0,IF($C$17-BE3>=0,$M$42/2*(参数输入表!$I$251/12)*BE2*(1-BE6),($M$41-$M$44)*(参数输入表!$I$251/12)*BE2*(1-BE6)),0) -> 0
C18: 47483 | D18: =SUM(F18:BE18) -> 1307.3653 | E18: 万元 | N18: =IF(N3-参数输入表!$I$250<=0,IF($C$18-N3>=0,$N$42/2*(参数输入表!$I$251/12)*N2*(1-N6),($N$41-$N$44)*(参数输入表!$I$251/12)*N2*(1-N6)),0) -> 251.57177 | O18: =IF(O3-参数输入表!$I$250<=0,IF($C$18-O3>=0,$N$42/2*(参数输入表!$I$251/12)*O2*(1-O6),($N$41-$N$44)*(参数输入表!$I$251/12)*O2*(1-O6)),0) -> 1055.7936 | P18: =IF(P3-参数输入表!$I$250<=0,IF($C$18-P3>=0,$N$42/2*(参数输入表!$I$251/12)*P2*(1-P6),($N$41-$N$44)*(参数输入表!$I$251/12)*P2*(1-P6)),0) -> 0 | Q18: =IF(Q3-参数输入表!$I$250<=0,IF($C$18-Q3>=0,$N$42/2*(参数输入表!$I$251/12)*Q2*(1-Q6),($N$41-$N$44)*(参数输入表!$I$251/12)*Q2*(1-Q6)),0) -> 0 | R18: =IF(R3-参数输入表!$I$250<=0,IF($C$18-R3>=0,$N$42/2*(参数输入表!$I$251/12)*R2*(1-R6),($N$41-$N$44)*(参数输入表!$I$251/12)*R2*(1-R6)),0) -> 0 | S18: =IF(S3-参数输入表!$I$250<=0,IF($C$18-S3>=0,$N$42/2*(参数输入表!$I$251/12)*S2*(1-S6),($N$41-$N$44)*(参数输入表!$I$251/12)*S2*(1-S6)),0) -> 0 | T18: =IF(T3-参数输入表!$I$250<=0,IF($C$18-T3>=0,$N$42/2*(参数输入表!$I$251/12)*T2*(1-T6),($N$41-$N$44)*(参数输入表!$I$251/12)*T2*(1-T6)),0) -> 0 | U18: =IF(U3-参数输入表!$I$250<=0,IF($C$18-U3>=0,$N$42/2*(参数输入表!$I$251/12)*U2*(1-U6),($N$41-$N$44)*(参数输入表!$I$251/12)*U2*(1-U6)),0) -> 0 | ... BE18: =IF(BE3-参数输入表!$I$250<=0,IF($C$18-BE3>=0,$N$42/2*(参数输入表!$I$251/12)*BE2*(1-BE6),($N$41-$N$44)*(参数输入表!$I$251/12)*BE2*(1-BE6)),0) -> 0
C19: 47695 | D19: =SUM(F19:BE19) -> 470.82861 | E19: 万元 | O19: =IF(O3-参数输入表!$I$250<=0,IF($C$19-O3>=0,$O$42/2*(参数输入表!$I$251/12)*O2*(1-O6),($O$41-$O$44)*(参数输入表!$I$251/12)*O2*(1-O6)),0) -> 470.82861 | P19: =IF(P3-参数输入表!$I$250<=0,IF($C$19-P3>=0,$O$42/2*(参数输入表!$I$251/12)*P2*(1-P6),($O$41-$O$44)*(参数输入表!$I$251/12)*P2*(1-P6)),0) -> 0 | Q19: =IF(Q3-参数输入表!$I$250<=0,IF($C$19-Q3>=0,$O$42/2*(参数输入表!$I$251/12)*Q2*(1-Q6),($O$41-$O$44)*(参数输入表!$I$251/12)*Q2*(1-Q6)),0) -> 0 | R19: =IF(R3-参数输入表!$I$250<=0,IF($C$19-R3>=0,$O$42/2*(参数输入表!$I$251/12)*R2*(1-R6),($O$41-$O$44)*(参数输入表!$I$251/12)*R2*(1-R6)),0) -> 0 | S19: =IF(S3-参数输入表!$I$250<=0,IF($C$19-S3>=0,$O$42/2*(参数输入表!$I$251/12)*S2*(1-S6),($O$41-$O$44)*(参数输入表!$I$251/12)*S2*(1-S6)),0) -> 0 | T19: =IF(T3-参数输入表!$I$250<=0,IF($C$19-T3>=0,$O$42/2*(参数输入表!$I$251/12)*T2*(1-T6),($O$41-$O$44)*(参数输入表!$I$251/12)*T2*(1-T6)),0) -> 0 | U19: =IF(U3-参数输入表!$I$250<=0,IF($C$19-U3>=0,$O$42/2*(参数输入表!$I$251/12)*U2*(1-U6),($O$41-$O$44)*(参数输入表!$I$251/12)*U2*(1-U6)),0) -> 0 | V19: =IF(V3-参数输入表!$I$250<=0,IF($C$19-V3>=0,$O$42/2*(参数输入表!$I$251/12)*V2*(1-V6),($O$41-$O$44)*(参数输入表!$I$251/12)*V2*(1-V6)),0) -> 0 | ... BE19: =IF(BE3-参数输入表!$I$250<=0,IF($C$19-BE3>=0,$O$42/2*(参数输入表!$I$251/12)*BE2*(1-BE6),($O$41-$O$44)*(参数输入表!$I$251/12)*BE2*(1-BE6)),0) -> 0
