Workbook

Sheet 说明
B2: 参数输入表中：
C3: 标黄项为相对固定模块
C4: 标绿项为对成本类、收入类数据进行分类，成本参数按照：“生产成本/销售费用/管理费用/研发费用”划分；收入参数按照：“营业收入/其他收入/营业外收入”划分
C5: 标橙项为固定的分类原则
C6: 标紫项为在参数表中不需要手动输入、勾选的内容，根据其他输入参数自动计算得出，可不在参数输入界面呈现。
C7: 标红项为引用同样红色sheet中相关数据
C8: 标蓝项为可不展示内容，大部分为中间过程计算表/中间计算过程
C10: 【成本费用表】、【收入税金表】、【利润表】体现的是会计报表相关数据，涉及到的收入及成本数据均为不含增值税金额，不含税金额计算公式为： 【含税金额/（1+增值税税率）】；增值税计算公式为：【不含税金额*增值税税率】或【含税金额/（1+增值税税率）*增值税税率】
C12: 【成本费用表】中各项成本按照：一、营业总成本：（1）生产成本；（2）销售费用；（3）管理费用；（4）研发费用；（5）财务费用；二、营业外支出，进行划分，其中需重点关注长期待摊费用成本项，在成本费用表中以逐年摊销的形式出现。
C14: 【成本费用表】中标蓝的内容为不展示内容，为中间计算表，其中数据均还原成含税金额，用于后续的【现金流量表】引用
C16: 【收入表】中各项收入按照：一、营业收入；二、其他收入；三、营业外收入，营业收入及营业外收入需展示二级目录（具体的收入项）
C18: 【现金流量表】体现的是公司账上实际收到或支付的现金流，因此涉及到的收入及成本数据均为含增值税金额，数据需引用成本费用表中还原后的含税金额或参数输入表中的含税金额。同时，收入数据需关注付款比例及回款期限的应用。原理为当年的部分比例收入的滞后支付，第一年的某项收入现金流为预测现金流*首年支付比例，第二年的某项收入现金流为：当年预测现金流*当年支付比例+上一年预测现金流*（1-上一年支付比例）
C20: 【现金流量表-财务计划】增加IF判定条件，当某年的累计盈余资金<MAX(“流动资金（本项目为960万元）”,“当年的生产经营现金支出合计（成本费用表标蓝表第一行）)，给出明显提示（允许用户在参数输入界面填写各年度短期借款当期借款金额及还本金额，再重新生成新的结果）

Sheet 新建及改扩建项目投资概算明细 (光伏)
B2: 工程分年度投资输入表（可研中抓取数据） | I2: 错误计算进项税的方式
B3: 序号 | C3: 科目 | D3: 合计 | E3: 单位 | F3: 2023年 | G3: 2024年 | H3: 增值税税率 | I3: 2023年 | J3: 2024年 | K3: 合计 | L3: 差额
B4: 1 | C4: 设备购置费 | D4: =SUM(F4:G4) -> 100000 | E4: 万元 | F4: 30000 | G4: 70000 | H4: =参数输入表!G134 -> 0.13 | I4: =F4*H4 -> 3900 | J4: =G4*H4 -> 9100 | K4: =D4*H4 -> 13000 | L4: =K4-D18 -> 1495.5752
B5: 2 | C5: 建安工程费 | D5: =SUM(F5:G5) -> 20000 | E5: 万元 | F5: 6000 | G5: 14000 | H5: =参数输入表!G135 -> 0.09 | I5: =F5*H5 -> 540 | J5: =G5*H5 -> 1260 | K5: =D5*H5 -> 1800 | L5: =K5-D19 -> 148.62385
B6: 3 | C6: 其他费用 | D6: =SUM(F6:G6) -> 12000 | E6: 万元 | F6: 3600 | G6: 8400 | H6: =参数输入表!G136 -> 0.06 | I6: =F6*H6 -> 216 | J6: =G6*H6 -> 504 | K6: =D6*H6 -> 720 | L6: =K6-D20 -> 40.754717
B7: 4 | C7: 基本预备费 | D7: =SUM(F7:G7) -> 2500 | E7: 万元 | F7: 750 | G7: 1750 | H7: =参数输入表!G137 -> 0 | I7: =F7*H7 -> 0 | J7: =G7*H7 -> 0 | K7: =D7*H7 -> 0 | L7: =K7-D21 -> 0
B8: 5 | C8: 储能投资 | D8: =SUM(F8:G8) -> 500 | E8: 万元 | F8: 150 | G8: 350 | H8: =参数输入表!G138 -> 0.13 | I8: =F8*H8 -> 19.5 | J8: =G8*H8 -> 45.5 | K8: =D8*H8 -> 65 | L8: =K8-D22 -> 7.4778761
B9: 6 | C9: 送出线路投资 | D9: =SUM(F9:G9) -> 4000 | E9: 万元 | F9: 1200 | G9: 2800 | H9: =参数输入表!G139 -> 0.09 | I9: =F9*H9 -> 108 | J9: =G9*H9 -> 252 | K9: =D9*H9 -> 360 | L9: =K9-D23 -> 29.724771
B10: 7 | C10: 配套支持资金 | D10: =SUM(F10:G10) -> 0 | E10: 万元 | F10: 0 | G10: 0 | H10: =参数输入表!G140 -> 0 | I10: =F10*H10 -> 0 | J10: =G10*H10 -> 0 | K10: =D10*H10 -> 0 | L10: =K10-D24 -> 0
B11: 8 | C11: 静态投资 | D11: =SUM(F11:G11) -> 139000 | E11: 万元 | F11: =SUM(F4:F10) -> 41700 | G11: =SUM(G4:G10) -> 97300 | I11: =F11*H11 -> 0 | J11: =G11*H11 -> 0 | K11: =D11*H11 -> 0 | L11: =K11-D25 -> 0
B12: 9 | C12: 价差预备费 | D12: =SUM(F12:G12) -> 0 | E12: 万元 | F12: 0 | G12: 0 | H12: =参数输入表!G143 -> 0 | I12: =F12*H12 -> 0 | J12: =G12*H12 -> 0
B13: 10 | C13: 建设投资 | D13: =SUM(F13:G13) -> 139000 | E13: 万元 | F13: =F11+F12 -> 41700 | G13: =G11+G12 -> 97300
C14: 投资进度 | D14: =SUM(F14:G14) -> 1 | E14: 万元 | F14: =F13/$D$13 -> 0.3 | G14: =G13/$D$13 -> 0.7 | I14: =SUM(I4:I11) -> 4783.5 | J14: =SUM(J4:J11) -> 11161.5 | K14: =SUM(K4:K11) -> 15945 | L14: =SUM(L4:L11) -> 1722.1564
B16: 工程增值税进项税
B17: 序号 | C17: 科目 | D17: 合计 | E17: 单位 | F17: =F3 -> 2023年 | G17: =G3 -> 2024年
B18: 1 | C18: 设备购置费 | D18: =SUM(F18:G18) -> 11504.425 | E18: 万元 | F18: =F4/(1+$H$4)*$H$4 -> 3451.3274 | G18: =G4/(1+$H$4)*$H$4 -> 8053.0973
B19: 2 | C19: 建安工程费 | D19: =SUM(F19:G19) -> 1651.3761 | E19: 万元 | F19: =F5/(1+$H$5)*$H$5 -> 495.41284 | G19: =G5/(1+$H$5)*$H$5 -> 1155.9633
B20: 3 | C20: 其他费用 | D20: =SUM(F20:G20) -> 679.24528 | E20: 万元 | F20: =F6/(1+$H$6)*$H$6 -> 203.77358 | G20: =G6/(1+$H$6)*$H$6 -> 475.4717
B21: 4 | C21: 基本预备费 | D21: =SUM(F21:G21) -> 0 | E21: 万元 | F21: =F7/(1+$H$7)*$H$7 -> 0 | G21: =G7/(1+$H$7)*$H$7 -> 0
B22: 5 | C22: 储能投资 | D22: =SUM(F22:G22) -> 57.522124 | E22: 万元 | F22: =F8/(1+$H$8)*$H$8 -> 17.256637 | G22: =G8/(1+$H$8)*$H$8 -> 40.265487
B23: 6 | C23: 送出线路投资 | D23: =SUM(F23:G23) -> 330.27523 | E23: 万元 | F23: =F9/(1+$H$9)*$H$9 -> 99.082569 | G23: =G9/(1+$H$9)*$H$9 -> 231.19266
B24: 7 | C24: 配套支持资金 | D24: =SUM(F24:G24) -> 0 | E24: 万元 | F24: =F10/(1+$H$10)*$H$10 -> 0 | G24: =G10/(1+$H$10)*$H$10 -> 0
B25: 8 | C25: 价差预备费 | D25: =SUM(F25:G25) -> 0 | E25: 万元 | F25: =F12/(1+$H$12)*$H$12 -> 0 | G25: =G12/(1+$H$12)*$H$12 -> 0
B26: 工程可抵扣进项税合计 | D26: =SUM(F26:G26) -> 14222.844 | E26: 万元 | F26: =SUM(F18:F25) -> 4266.8531 | G26: =SUM(G18:G25) -> 9955.9905
B27: 工程可抵扣进项税累计 | E27: 万元 | F27: =F26 -> 4266.8531 | G27: =F27+G26 -> 14222.844
C29: 可抵扣进项税为后台计算，不需要作为成果展示

Sheet 参数输入表
D1: 【光伏】财务评价计算模型边界条件输入参数表
B3: 类别 | C3: 序号 | D3: 参数 | E3: 操作类型 | F3: 数据结构化整理 | G3: 收入/成本归类 | H3: 参数释义/计算公式 | I3: 数值 | J3: 单位 | K3: 取值说明 | L3: 备注
C4: 1 | D4: 项目投产日 | E4: 下拉菜单选择【日历】 | I4: 43921
D5: 项目运营期 | E5: 手动输入 | I5: 25 | J5: 年
D6: 项目结束日 | E6: 自动计算 | I6: =I4+365*I5 -> 53046
D7: 审计期间 | E7: 手动输入 | I7: 4 | J7: 年 | K7: 历史数据占用的年度范围
D8: 评估基准日 | E8: 手动输入 | I8: 45107
D9: 预测期 | E9: 自动计算 | I9: =IF(MONTH(I8)=12,YEAR(I6)-YEAR(I8),YEAR(I6)-YEAR(I8)+1) -> 23 | K9: 预测期占用的年度范围
C10: 2 | D10: 估值结果
D11: 股权价值 | E11: 手动输入 | I11: 8000 | J11: 万元
D12: 企业价值 | E12: 手动输入 | I12: 47000 | J12: 万元
C13: 3 | D13: 新建及改扩建项目
B14: 基础信息 | C14: 3.1 | D14: 建设期 | E14: 自动计算，向上取整 | I14: 2 | J14: 年 | K14: 测算表占用的年度范围
D15: 建设期起始日期 | E15: 下拉菜单选择【日历】 | I15: 45107 | J15: 年/月 | K15: 输入完动工年月及建设期结束日期，自动配置出参数表及计算表中建设期所占报表年度（如建设期为7年5个月，建设期实际占8个报表年）
D16: 建设期结束日期 | E16: 下拉菜单选择【日历】 | I16: 45627 | J16: 年/月
C17: 3.2 | D17: 施工进度安排 | I17: =SUM(I18:I19) -> 1
D18: 建设期第1年 | E18: 自动计算 | I18: ='新建及改扩建项目投资概算明细 (光伏)'!F14 -> 0.3 | J18: %
D19: 建设期第2年 | E19: 自动计算 | I19: ='新建及改扩建项目投资概算明细 (光伏)'!G14 -> 0.7 | J19: %
D20: …… | E20: 根据需要（向上取整）配置
C21: 3.3 | D21: 投产起始日期 | E21: 手动输入/下拉菜单选择【日历】 | I21: 7 | J21: 第n年/第n月
D22: 运营期 | E22: 手动输入 | I22: 25 | J22: 年
C23: 3.4 | D23: 试运营期 | E23: 选择时间区间 | J23: 年/月 | K23: 用于最后的累计盈余资金判定
C24: 4 | D24: 项目所在地 | E24: 下拉菜单选择 | K24: 判定是否属于西部地区
D25: 所在省份 | E25: 下拉菜单选择
D26: 所在市、县 | E26: 下拉菜单选择
C27: 5 | D27: 全生命周期小时数 | E27: 手动输入 | I27: 26000 | J27: h
C28: 6 | D28: 基准日累计发电小时数 | E28: 手动输入 | I28: 3500 | J28: h
C29: 7 | D29: 国补最晚截止日 | E29: 自动计算 | I29: =I4+365*20 -> 51221
B30: 生产相关 | C30: 8 | D30: 总装机容量 | E30: 自动计算 | I30: =I31+I32 -> 320 | J30: MW | K30: 1MW=1000kW
C31: 8.1 | D31: 其中：基准日实际装机容量 | E31: 手动输入 | I31: 10 | J31: MW
C32: 8.2 | D32: 新增及改扩建装机容量 | E32: 手动输入 | I32: 310 | J32: MW
C33: 9 | D33: 年利用小时数 | E33: 手动输入 | I33: 1551 | J33: h
C34: 10 | D34: 新建及改扩建项目投产比例
D35: 建设期第1年 | E35: 手动输入 | I35: 0.15 | J35: %
D36: 建设期第2年 | E36: 手动输入 | I36: 0.75 | J36: %
D37: 建设期后 | E37: 手动输入 | I37: 0.1 | J37: %
D38: 全生命周期投产比例
D39: 合作期第1年 | E39: 手动输入 | I39: 0 | J39: %
D40: 合作期第2年 | E40: 手动输入 | I40: =I31/I30 -> 0.03125 | J40: %
D41: 合作期第3年 | E41: 手动输入 | I41: =I40 -> 0.03125 | J41: %
...

Sheet 表1-资金筹措及还本付息表
B2: 新建及改扩建项目资金筹措表
B3: 序号 | C3: 项目 | D3: 合计 | E3: 单位 | F3: 2020年 | G3: 2021年 | H3: 2022年 | I3: 45107 | J3: 45261 | K3: 2024年 | L3: 2025年 | M3: 2026年 | N3: 2027年 | O3: 2028年 | P3: 2029年 | Q3: 2030年 | R3: 2031年 | S3: 2032年 | T3: 2033年 | U3: 2034年 | V3: 2035年 | W3: 2036年 | X3: 2037年 | Y3: 2038年 | Z3: 2039年 | AA3: 2040年 | AB3: 2041年 | AC3: 2042年 | AD3: 2043年 | AE3: 2044年 | AF3: 53051
F4: 1 | G4: 2 | H4: 3 | I4: 4 | J4: 5 | K4: 6 | L4: 7 | M4: 8 | N4: 9 | O4: 10 | P4: 11 | Q4: 12 | R4: 13 | S4: 14 | T4: 15 | U4: 16 | V4: 17 | W4: 18 | X4: 19 | Y4: 20 | Z4: 21 | AA4: 22 | AB4: 23 | AC4: 24 | AD4: 25 | AE4: 26 | AF4: 27
C5: 施工进度安排 | D5: =SUM(F5:AF5) -> 1 | J5: =参数输入表!I18 -> 0.3 | K5: =参数输入表!I19 -> 0.7
C6: 期末投产比例 | J6: =参数输入表!I35 -> 0.15 | K6: =参数输入表!I36+J6 -> 0.9
B7: 1 | C7: 动态总投资（自主投资,含流动资金） | D7: =D8+D9+D10 -> 140377.27 | E7: 万元 | J7: =SUM(J8:J10) -> 41985.124 | K7: =SUM(K8:K10) -> 97592.141 | L7: =SUM(L8:L10) -> 800 | M7: =SUM(M8:M10) -> 0 | N7: =SUM(N8:N10) -> 0 | O7: =SUM(O8:O10) -> 0 | P7: =SUM(P8:P10) -> 0 | Q7: =SUM(Q8:Q10) -> 0 | ... AF7: =SUM(AF8:AF10) -> 0
B8: 1.1 | C8: 静态总投资（自主投资） | D8: =SUM(F8:AF8) -> 139000 | E8: 万元 | J8: =参数输入表!$I$145*J5 -> 41700 | K8: =参数输入表!$I$145*K5 -> 97300 | L8: =IF(L$4-参数输入表!$I$14-参数输入表!$I$7>0,0) -> 0 | M8: =IF(M$4-参数输入表!$I$14-参数输入表!$I$7>0,0) -> 0 | N8: =IF(N$4-参数输入表!$I$14-参数输入表!$I$7>0,0) -> 0 | O8: =IF(O$4-参数输入表!$I$14-参数输入表!$I$7>0,0) -> 0 | P8: =IF(P$4-参数输入表!$I$14-参数输入表!$I$7>0,0) -> 0 | Q8: =IF(Q$4-参数输入表!$I$14-参数输入表!$I$7>0,0) -> 0 | R8: =IF(R$4-参数输入表!$I$14-参数输入表!$I$7>0,0) -> 0 | S8: =IF(S$4-参数输入表!$I$14-参数输入表!$I$7>0,0) -> 0 | ... AF8: =IF(AF$4-参数输入表!$I$14-参数输入表!$I$7>0,0) -> 0
B9: 1.2 | C9: 建设期利息 | D9: =SUM(F9:AF9) -> 577.26523 | E9: 万元 | J9: =J17 -> 285.12398 | K9: =K17 -> 292.14125 | L9: =L17 -> 0 | M9: =M17 -> 0 | N9: =N17 -> 0 | O9: =O17 -> 0 | P9: =P17 -> 0 | Q9: =Q17 -> 0 | ... AF9: =AF17 -> 0
B10: 1.3 | C10: 流动资金 | D10: =SUM(F10:AF10) -> 800 | E10: 万元 | J10: =IF(AND(J4-参数输入表!$I$21=0,参数输入表!$I$149="手动输入"),参数输入表!$I$151,IF(AND(J4-参数输入表!$I$21=0,参数输入表!$I$149="单位千瓦指标计算"),参数输入表!$I$150*参数输入表!$I$32/10,0)) -> 0 | K10: =IF(AND(K4-参数输入表!$I$21=0,参数输入表!$I$149="手动输入"),参数输入表!$I$151,IF(AND(K4-参数输入表!$I$21=0,参数输入表!$I$149="单位千瓦指标计算"),参数输入表!$I$150*参数输入表!$I$32/10,0)) -> 0 | L10: =IF(AND(L4-参数输入表!$I$21=0,参数输入表!$I$149="手动输入"),参数输入表!$I$151,IF(AND(L4-参数输入表!$I$21=0,参数输入表!$I$149="单位千瓦指标计算"),参数输入表!$I$150*参数输入表!$I$32/10,0)) -> 800 | M10: =IF(AND(M4-参数输入表!$I$21=0,参数输入表!$I$149="手动输入"),参数输入表!$I$151,IF(AND(M4-参数输入表!$I$21=0,参数输入表!$I$149="单位千瓦指标计算"),参数输入表!$I$150*参数输入表!$I$32/10,0)) -> 0 | N10: =IF(AND(N4-参数输入表!$I$21=0,参数输入表!$I$149="手动输入"),参数输入表!$I$151,IF(AND(N4-参数输入表!$I$21=0,参数输入表!$I$149="单位千瓦指标计算"),参数输入表!$I$150*参数输入表!$I$32/10,0)) -> 0 | O10: =IF(AND(O4-参数输入表!$I$21=0,参数输入表!$I$149="手动输入"),参数输入表!$I$151,IF(AND(O4-参数输入表!$I$21=0,参数输入表!$I$149="单位千瓦指标计算"),参数输入表!$I$150*参数输入表!$I$32/10,0)) -> 0 | P10: =IF(AND(P4-参数输入表!$I$21=0,参数输入表!$I$149="手动输入"),参数输入表!$I$151,IF(AND(P4-参数输入表!$I$21=0,参数输入表!$I$149="单位千瓦指标计算"),参数输入表!$I$150*参数输入表!$I$32/10,0)) -> 0 | Q10: =IF(AND(Q4-参数输入表!$I$21=0,参数输入表!$I$149="手动输入"),参数输入表!$I$151,IF(AND(Q4-参数输入表!$I$21=0,参数输入表!$I$149="单位千瓦指标计算"),参数输入表!$I$150*参数输入表!$I$32/10,0)) -> 0 | ... AF10: =IF(AND(AF4-参数输入表!$I$21=0,参数输入表!$I$149="手动输入"),参数输入表!$I$151,IF(AND(AF4-参数输入表!$I$21=0,参数输入表!$I$149="单位千瓦指标计算"),参数输入表!$I$150*参数输入表!$I$32/10,0)) -> 0
B11: 2 | C11: 资金来源
B12: 2.1 | C12: 资本金 | D12: =SUM(F12:AF12) -> 35134.316 | E12: 万元 | J12: =SUM(J13:J14) -> 10496.281 | K12: =SUM(K13:K14) -> 24398.035 | L12: =SUM(L13:L14) -> 240 | M12: =SUM(M13:M14) -> 0 | N12: =SUM(N13:N14) -> 0 | O12: =SUM(O13:O14) -> 0 | P12: =SUM(P13:P14) -> 0 | Q12: =SUM(Q13:Q14) -> 0 | ... AF12: =SUM(AF13:AF14) -> 0
B13: 2.1.1 | C13: 用于建设投资 | D13: =SUM(F13:AF13) -> 34894.316 | E13: 万元 | J13: =(J8+J9)*参数输入表!$I$215 -> 10496.281 | K13: =(K8+K9)*参数输入表!$I$215 -> 24398.035 | L13: =(L8+L9)*参数输入表!$I$215 -> 0 | M13: =(M8+M9)*参数输入表!$I$215 -> 0 | N13: =(N8+N9)*参数输入表!$I$215 -> 0 | O13: =(O8+O9)*参数输入表!$I$215 -> 0 | P13: =(P8+P9)*参数输入表!$I$215 -> 0 | Q13: =(Q8+Q9)*参数输入表!$I$215 -> 0 | ... AF13: =(AF8+AF9)*参数输入表!$I$215 -> 0
B14: 2.1.2 | C14: 用于流动资金 | D14: =SUM(F14:AF14) -> 240 | E14: 万元 | J14: =IF(AND(J4-参数输入表!$I$21=0,参数输入表!$I$149="手动输入"),参数输入表!$I$151*参数输入表!$I$223,IF(AND(J4-参数输入表!$I$21=0,参数输入表!$I$149="单位千瓦指标计算"),参数输入表!$I$150*参数输入表!$I$32/10*参数输入表!$I$223,0)) -> 0 | K14: =IF(AND(K4-参数输入表!$I$21=0,参数输入表!$I$149="手动输入"),参数输入表!$I$151*参数输入表!$I$223,IF(AND(K4-参数输入表!$I$21=0,参数输入表!$I$149="单位千瓦指标计算"),参数输入表!$I$150*参数输入表!$I$32/10*参数输入表!$I$223,0)) -> 0 | L14: =IF(AND(L4-参数输入表!$I$21=0,参数输入表!$I$149="手动输入"),参数输入表!$I$151*参数输入表!$I$223,IF(AND(L4-参数输入表!$I$21=0,参数输入表!$I$149="单位千瓦指标计算"),参数输入表!$I$150*参数输入表!$I$32/10*参数输入表!$I$223,0)) -> 240 | M14: =IF(AND(M4-参数输入表!$I$21=0,参数输入表!$I$149="手动输入"),参数输入表!$I$151*参数输入表!$I$223,IF(AND(M4-参数输入表!$I$21=0,参数输入表!$I$149="单位千瓦指标计算"),参数输入表!$I$150*参数输入表!$I$32/10*参数输入表!$I$223,0)) -> 0 | N14: =IF(AND(N4-参数输入表!$I$21=0,参数输入表!$I$149="手动输入"),参数输入表!$I$151*参数输入表!$I$223,IF(AND(N4-参数输入表!$I$21=0,参数输入表!$I$149="单位千瓦指标计算"),参数输入表!$I$150*参数输入表!$I$32/10*参数输入表!$I$223,0)) -> 0 | O14: =IF(AND(O4-参数输入表!$I$21=0,参数输入表!$I$149="手动输入"),参数输入表!$I$151*参数输入表!$I$223,IF(AND(O4-参数输入表!$I$21=0,参数输入表!$I$149="单位千瓦指标计算"),参数输入表!$I$150*参数输入表!$I$32/10*参数输入表!$I$223,0)) -> 0 | P14: =IF(AND(P4-参数输入表!$I$21=0,参数输入表!$I$149="手动输入"),参数输入表!$I$151*参数输入表!$I$223,IF(AND(P4-参数输入表!$I$21=0,参数输入表!$I$149="单位千瓦指标计算"),参数输入表!$I$150*参数输入表!$I$32/10*参数输入表!$I$223,0)) -> 0 | Q14: =IF(AND(Q4-参数输入表!$I$21=0,参数输入表!$I$149="手动输入"),参数输入表!$I$151*参数输入表!$I$223,IF(AND(Q4-参数输入表!$I$21=0,参数输入表!$I$149="单位千瓦指标计算"),参数输入表!$I$150*参数输入表!$I$32/10*参数输入表!$I$223,0)) -> 0 | ... AF14: =IF(AND(AF4-参数输入表!$I$21=0,参数输入表!$I$149="手动输入"),参数输入表!$I$151*参数输入表!$I$223,IF(AND(AF4-参数输入表!$I$21=0,参数输入表!$I$149="单位千瓦指标计算"),参数输入表!$I$150*参数输入表!$I$32/10*参数输入表!$I$223,0)) -> 0
B15: 2.2 | C15: 债务资金 | D15: =SUM(F15:AF15) -> 105242.95 | E15: 万元 | J15: =SUM(J16:J17)+J19 -> 31488.843 | K15: =SUM(K16:K17)+K19 -> 73194.106 | L15: =SUM(L16:L17)+L19 -> 560 | M15: =SUM(M16:M17)+M19 -> 0 | N15: =SUM(N16:N17)+N19 -> 0 | O15: =SUM(O16:O17)+O19 -> 0 | P15: =SUM(P16:P17)+P19 -> 0 | Q15: =SUM(Q16:Q17)+Q19 -> 0 | ... AF15: =SUM(AF16:AF17)+AF19 -> 0
B16: 2.2.1 | C16: 用于建设投资 | D16: =SUM(F16:AF16) -> 104105.68 | E16: 万元 | J16: =J8-J13 -> 31203.719 | K16: =K8-K13 -> 72901.965 | L16: =IF(L$4-参数输入表!$I$14-参数输入表!$I$7>0,0) -> 0 | M16: =IF(M$4-参数输入表!$I$14-参数输入表!$I$7>0,0) -> 0 | N16: =IF(N$4-参数输入表!$I$14-参数输入表!$I$7>0,0) -> 0 | O16: =IF(O$4-参数输入表!$I$14-参数输入表!$I$7>0,0) -> 0 | P16: =IF(P$4-参数输入表!$I$14-参数输入表!$I$7>0,0) -> 0 | Q16: =IF(Q$4-参数输入表!$I$14-参数输入表!$I$7>0,0) -> 0 | R16: =IF(R$4-参数输入表!$I$14-参数输入表!$I$7>0,0) -> 0 | S16: =IF(S$4-参数输入表!$I$14-参数输入表!$I$7>0,0) -> 0 | ... AF16: =IF(AF$4-参数输入表!$I$14-参数输入表!$I$7>0,0) -> 0
B17: 2.2.2 | C17: 用于建设期利息 | D17: =SUM(F17:AF17) -> 577.26523 | E17: 万元 | J17: =J16/2*参数输入表!$I$218*(12-MONTH(参数输入表!I8))/12*(1-J6) -> 285.12398 | K17: =(J16+J17+K16/2)*参数输入表!$I$218*(1-K6) -> 292.14125 | L17: =IF(L$4-参数输入表!$I$14-参数输入表!$I$7>0,0) -> 0 | M17: =IF(M$4-参数输入表!$I$14-参数输入表!$I$7>0,0) -> 0 | N17: =IF(N$4-参数输入表!$I$14-参数输入表!$I$7>0,0) -> 0 | O17: =IF(O$4-参数输入表!$I$14-参数输入表!$I$7>0,0) -> 0 | P17: =IF(P$4-参数输入表!$I$14-参数输入表!$I$7>0,0) -> 0 | Q17: =IF(Q$4-参数输入表!$I$14-参数输入表!$I$7>0,0) -> 0 | R17: =IF(R$4-参数输入表!$I$14-参数输入表!$I$7>0,0) -> 0 | S17: =IF(S$4-参数输入表!$I$14-参数输入表!$I$7>0,0) -> 0 | ... AF17: =IF(AF$4-参数输入表!$I$14-参数输入表!$I$7>0,0) -> 0
C18: 应计利息（隐藏） | D18: =SUM(F18:AF18) -> 3256.8525 | E18: 万元 | J18: =J16/2*参数输入表!$I$218*(12-MONTH(参数输入表!I8))/12 -> 335.43998 | K18: =(J16+J17+K16/2)*参数输入表!$I$218 -> 2921.4125 | L18: =IF(L$4-参数输入表!$I$14-参数输入表!$I$7>0,0) -> 0 | M18: =IF(M$4-参数输入表!$I$14-参数输入表!$I$7>0,0) -> 0 | N18: =IF(N$4-参数输入表!$I$14-参数输入表!$I$7>0,0) -> 0 | O18: =IF(O$4-参数输入表!$I$14-参数输入表!$I$7>0,0) -> 0 | P18: =IF(P$4-参数输入表!$I$14-参数输入表!$I$7>0,0) -> 0 | Q18: =IF(Q$4-参数输入表!$I$14-参数输入表!$I$7>0,0) -> 0 | R18: =IF(R$4-参数输入表!$I$14-参数输入表!$I$7>0,0) -> 0 | S18: =IF(S$4-参数输入表!$I$14-参数输入表!$I$7>0,0) -> 0 | ... AF18: =IF(AF$4-参数输入表!$I$14-参数输入表!$I$7>0,0) -> 0
B19: 2.2.3 | C19: 用于流动资金 | D19: =SUM(F19:AF19) -> 560 | E19: 万元 | J19: =J10-J14 -> 0 | K19: =K10-K14 -> 0 | L19: =L10-L14 -> 560 | M19: =M10-M14 -> 0 | N19: =N10-N14 -> 0 | O19: =O10-O14 -> 0 | P19: =P10-P14 -> 0 | Q19: =Q10-Q14 -> 0 | ... AF19: =AF10-AF14 -> 0
B21: 营运资本变动
B22: 序号 | C22: 项目 | D22: 合计 | E22: 单位 | F22: 建设期 | H22: 运营期
F23: 1 | G23: 2 | H23: 1 | I23: 2 | J23: 3 | K23: 4 | L23: 5 | M23: 6 | N23: 7 | O23: 8 | P23: 9 | Q23: 10 | R23: 11 | S23: 12 | T23: 13 | U23: 14 | V23: 15 | W23: 16 | X23: 17 | Y23: 18 | Z23: 19 | AA23: 20 | AB23: 21 | AC23: 22 | AD23: 23 | AE23: 24 | AF23: 25
B24: 1 | C24: 流动资产 | D24: =SUM(F24:AF24) -> 0 | E24: 万元
C25: 货币资金 | D25: =SUM(F25:AF25) -> 0 | E25: 万元
C26: 应收账款 | D26: =SUM(F26:AF26) -> 0 | E26: 万元
C27: 存货 | D27: =SUM(F27:AF27) -> 0 | E27: 万元
C28: 其他流动资产（留抵税额） | D28: =SUM(F28:AF28) -> 0 | E28: 万元
B29: 2 | C29: 流动负债 | D29: =SUM(F29:AF29) -> 0 | E29: 万元
C30: 短期借款 | D30: =SUM(F30:AF30) -> 0 | E30: 万元
C31: 预收款项 | D31: =SUM(F31:AF31) -> 0 | E31: 万元
C32: 应付职工薪酬 | D32: =SUM(F32:AF32) -> 0 | E32: 万元
C33: 应交税费 | D33: =SUM(F33:AF33) -> 0 | E33: 万元
C34: 应付股利 | D34: =SUM(F34:AF34) -> 0 | E34: 万元
C35: 其他流动负债 | D35: =SUM(F35:AF35) -> 0 | E35: 万元
B37: 借款还本付息表（新增及改扩建项目长期借款）
B38: 序号 | C38: 项目 | D38: 合计 | E38: 单位 | F38: 2020年 | G38: 2021年 | H38: 2022年 | I38: 45107 | J38: 45261 | K38: 2024年 | L38: 2025年 | M38: 2026年 | N38: 2027年 | O38: 2028年 | P38: 2029年 | Q38: 2030年 | R38: 2031年 | S38: 2032年 | T38: 2033年 | U38: 2034年 | V38: 2035年 | W38: 2036年 | X38: 2037年 | Y38: 2038年 | Z38: 2039年 | AA38: 2040年 | AB38: 2041年 | AC38: 2042年 | AD38: 2043年 | AE38: 2044年 | AF38: 53051
F39: 1 | G39: 2 | H39: 3 | I39: 4 | J39: 5 | K39: 6 | L39: 7 | M39: 8 | N39: 9 | O39: 10 | P39: 11 | Q39: 12 | R39: 13 | S39: 14 | T39: 15 | U39: 16 | V39: 17 | W39: 18 | X39: 19 | Y39: 20 | Z39: 21 | AA39: 22 | AB39: 23 | AC39: 24 | AD39: 25 | AE39: 26 | AF39: 27
B40: 1 | C40: 期初借款累计 | E40: 万元 | J40: 0 | K40: =J45 -> 31488.843 | L40: =K45 -> 104682.95 | M40: =L45 -> 99570.445 | N40: =M45 -> 94238.104 | O40: =N45 -> 88676.471 | P40: =O45 -> 82875.689 | Q40: =P45 -> 76825.473 | R40: =Q45 -> 70515.098 | ... AF40: =AE45 -> -1.7961463e-11
B41: 2 | C41: 当期借款 | D41: =SUM(F41:AF41) -> 104682.95 | E41: 万元 | J41: =J16+J17 -> 31488.843 | K41: =K16+K17 -> 73194.106 | L41: =L16+L17 -> 0 | M41: =M16+M17 -> 0 | N41: =N16+N17 -> 0 | O41: =O16+O17 -> 0 | P41: =P16+P17 -> 0 | Q41: =Q16+Q17 -> 0 | ... AF41: =AF16+AF17 -> 0
B42: 3 | C42: 当期还本付息 | D42: =SUM(F42:AF42) -> 146887.65 | E42: 万元 | J42: =IF(J39-参数输入表!$I$217-参数输入表!$I$7<=0,SUM(J43:J44),IF(J39-参数输入表!$I$217-参数输入表!$I$7<=参数输入表!$I$222,-PMT(参数输入表!$I$219,参数输入表!$I$222,'表1-资金筹措及还本付息表'!$D$41),0)) -> 50.315997 | K42: =IF(K39-参数输入表!$I$217-参数输入表!$I$7<=0,SUM(K43:K44),IF(K39-参数输入表!$I$217-参数输入表!$I$7<=参数输入表!$I$222,-PMT(参数输入表!$I$219,参数输入表!$I$222,'表1-资金筹措及还本付息表'!$D$41),0)) -> 2629.2712 | L42: =IF(L39-参数输入表!$I$217-参数输入表!$I$7<=0,SUM(L43:L44),IF(L39-参数输入表!$I$217-参数输入表!$I$7<=参数输入表!$I$222,-PMT(参数输入表!$I$219,参数输入表!$I$222,'表1-资金筹措及还本付息表'!$D$41),0)) -> 9613.8707 | M42: =IF(M39-参数输入表!$I$217-参数输入表!$I$7<=0,SUM(M43:M44),IF(M39-参数输入表!$I$217-参数输入表!$I$7<=参数输入表!$I$222,-PMT(参数输入表!$I$219,参数输入表!$I$222,'表1-资金筹措及还本付息表'!$D$41),0)) -> 9613.8707 | N42: =IF(N39-参数输入表!$I$217-参数输入表!$I$7<=0,SUM(N43:N44),IF(N39-参数输入表!$I$217-参数输入表!$I$7<=参数输入表!$I$222,-PMT(参数输入表!$I$219,参数输入表!$I$222,'表1-资金筹措及还本付息表'!$D$41),0)) -> 9613.8707 | O42: =IF(O39-参数输入表!$I$217-参数输入表!$I$7<=0,SUM(O43:O44),IF(O39-参数输入表!$I$217-参数输入表!$I$7<=参数输入表!$I$222,-PMT(参数输入表!$I$219,参数输入表!$I$222,'表1-资金筹措及还本付息表'!$D$41),0)) -> 9613.8707 | P42: =IF(P39-参数输入表!$I$217-参数输入表!$I$7<=0,SUM(P43:P44),IF(P39-参数输入表!$I$217-参数输入表!$I$7<=参数输入表!$I$222,-PMT(参数输入表!$I$219,参数输入表!$I$222,'表1-资金筹措及还本付息表'!$D$41),0)) -> 9613.8707 | Q42: =IF(Q39-参数输入表!$I$217-参数输入表!$I$7<=0,SUM(Q43:Q44),IF(Q39-参数输入表!$I$217-参数输入表!$I$7<=参数输入表!$I$222,-PMT(参数输入表!$I$219,参数输入表!$I$222,'表1-资金筹措及还本付息表'!$D$41),0)) -> 9613.8707 | ... AF42: =IF(AF39-参数输入表!$I$217-参数输入表!$I$7<=0,SUM(AF43:AF44),IF(AF39-参数输入表!$I$217-参数输入表!$I$7<=参数输入表!$I$222,-PMT(参数输入表!$I$219,参数输入表!$I$222,'表1-资金筹措及还本付息表'!$D$41),0)) -> 0
C43: 其中：还本（等额本息） | D43: =SUM(F43:AF43) -> 104682.95 | E43: 万元 | J43: =IF(J39-参数输入表!$I$217-参数输入表!$I$7<=0,0,J42-J44) -> 0 | K43: =IF(K39-参数输入表!$I$217-参数输入表!$I$7<=0,0,K42-K44) -> 0 | L43: =IF(L39-参数输入表!$I$217-参数输入表!$I$7<=0,0,L42-L44) -> 5112.5039 | M43: =IF(M39-参数输入表!$I$217-参数输入表!$I$7<=0,0,M42-M44) -> 5332.3415 | N43: =IF(N39-参数输入表!$I$217-参数输入表!$I$7<=0,0,N42-N44) -> 5561.6322 | O43: =IF(O39-参数输入表!$I$217-参数输入表!$I$7<=0,0,O42-O44) -> 5800.7824 | P43: =IF(P39-参数输入表!$I$217-参数输入表!$I$7<=0,0,P42-P44) -> 6050.216 | Q43: =IF(Q39-参数输入表!$I$217-参数输入表!$I$7<=0,0,Q42-Q44) -> 6310.3753 | ... AF43: =IF(AF39-参数输入表!$I$217-参数输入表!$I$7<=0,0,AF42-AF44) -> 1.9308572e-13
...

Sheet 表2-折旧摊销表
C1: 中间过程引用（隐藏）
C2: 动态总投资（自主投资_不含流动资金） | D2: =参数输入表!I148 -> 139577.27
C3: 可抵扣进项税 | D3: =参数输入表!I152 -> 14222.844
C4: 固定资产原值 | D4: =D2-D15-D3 -> 123554.42 | F4: 固定资产原值=项目动态总投资（自主投资_不含流动资金）-可抵扣进项税-无形资产原值=项目静态总投资-建设补贴+建设期利息-可抵扣进项税-无形资产原值
C5: 折旧方式 | D5: 直线法/其他 | F5: 无形资产及固定资产均包含在动态总投资中
C6: 折旧年限 | D6: =参数输入表!I438 -> 18
C7: 残值率 | D7: =参数输入表!I439 -> 0
C8: 长期待摊费用（第1年） | D8: =参数输入表!I461/(1+参数输入表!I488) -> 0 | F8: 长期待摊费用=计入长期待摊的成本项/（1+增值税税率）
C9: 长期待摊费用（第6年） | D9: =参数输入表!I466/(1+参数输入表!I488) -> 458.7156
C10: 长期待摊费用（第11年） | D10: =参数输入表!I471/(1+参数输入表!I488) -> 458.7156
C11: 长期待摊费用（第16年） | D11: =参数输入表!I476/(1+参数输入表!I488) -> 458.7156
C12: 长期待摊费用（第21年） | D12: =参数输入表!I481/(1+参数输入表!I488) -> 458.7156
C13: 摊销方式 | D13: 直线法/其他
C14: 摊销年限 | D14: =参数输入表!I487 -> 5
C15: 无形资产原值 | D15: =参数输入表!I441 -> 1800
C16: 摊销方式 | D16: 直线法/其他
C17: 摊销年限 | D17: =参数输入表!I443 -> 18
C18: 残值率 | D18: =参数输入表!I444 -> 0
C19: 大修及更新重置资产原值 | D19: =参数输入表!I507/(1+参数输入表!$I$525) -> 0
C20: 摊销方式 | D20: 直线法/其他
C21: 摊销年限 | D21: =参数输入表!I524 -> 10
B23: 折旧摊销表-资本金（新增部分）
B24: 序号 | C24: 科目 | D24: 合计 | E24: 单位 | F24: 2020年 | G24: 2021年 | H24: 2022年 | I24: 45107 | J24: 45261 | K24: 2024年 | L24: 2025年 | M24: 2026年 | N24: 2027年 | O24: 2028年 | P24: 2029年 | Q24: 2030年 | R24: 2031年 | S24: 2032年 | T24: 2033年 | U24: 2034年 | V24: 2035年 | W24: 2036年 | X24: 2037年 | Y24: 2038年 | Z24: 2039年 | AA24: 2040年 | AB24: 2041年 | AC24: 2042年 | AD24: 2043年 | AE24: 2044年 | AF24: 53051
F25: 1 | G25: 2 | H25: 3 | I25: 4 | J25: 5 | K25: 6 | L25: 7 | M25: 8 | N25: 9 | O25: 10 | P25: 11 | Q25: 12 | R25: 13 | S25: 14 | T25: 15 | U25: 16 | V25: 17 | W25: 18 | X25: 19 | Y25: 20 | Z25: 21 | AA25: 22 | AB25: 23 | AC25: 24 | AD25: 25 | AE25: 26 | AF25: 27
C26: 期末投产比例 | E26: % | J26: =参数输入表!$I$35 -> 0.15 | K26: =参数输入表!$I$36+J26 -> 0.9 | L26: =IF(L25-参数输入表!$I$7-参数输入表!$I$14>0,100%) -> 1 | M26: =IF(M25-参数输入表!$I$7-参数输入表!$I$14>0,100%) -> 1 | N26: =IF(N25-参数输入表!$I$7-参数输入表!$I$14>0,100%) -> 1 | O26: =IF(O25-参数输入表!$I$7-参数输入表!$I$14>0,100%) -> 1 | P26: =IF(P25-参数输入表!$I$7-参数输入表!$I$14>0,100%) -> 1 | Q26: =IF(Q25-参数输入表!$I$7-参数输入表!$I$14>0,100%) -> 1 | R26: =IF(R25-参数输入表!$I$7-参数输入表!$I$14>0,100%) -> 1 | S26: =IF(S25-参数输入表!$I$7-参数输入表!$I$14>0,100%) -> 1 | ... AF26: =IF(AF25-参数输入表!$I$7-参数输入表!$I$14>0,100%) -> 1
B27: 1 | C27: 期末固定资产原值 | E27: 万元 | J27: =IF(J25-参数输入表!$I$14-参数输入表!$I$7<0,(参数输入表!$I$148-参数输入表!$I$152-参数输入表!$I$441+$I$30)*J26,参数输入表!$I$148-参数输入表!$I$152-参数输入表!$I$441+$I$30) -> 18533.163 | K27: =IF(K25-参数输入表!$I$14-参数输入表!$I$7<0,(参数输入表!$I$148-参数输入表!$I$152-参数输入表!$I$441+$I$30)*K26,参数输入表!$I$148-参数输入表!$I$152-参数输入表!$I$441+$I$30) -> 123554.42 | L27: =IF(L25-参数输入表!$I$14-参数输入表!$I$7<0,(参数输入表!$I$148-参数输入表!$I$152-参数输入表!$I$441+$I$30)*L26,参数输入表!$I$148-参数输入表!$I$152-参数输入表!$I$441+$I$30) -> 123554.42 | M27: =IF(M25-参数输入表!$I$14-参数输入表!$I$7<0,(参数输入表!$I$148-参数输入表!$I$152-参数输入表!$I$441+$I$30)*M26,参数输入表!$I$148-参数输入表!$I$152-参数输入表!$I$441+$I$30) -> 123554.42 | N27: =IF(N25-参数输入表!$I$14-参数输入表!$I$7<0,(参数输入表!$I$148-参数输入表!$I$152-参数输入表!$I$441+$I$30)*N26,参数输入表!$I$148-参数输入表!$I$152-参数输入表!$I$441+$I$30) -> 123554.42 | O27: =IF(O25-参数输入表!$I$14-参数输入表!$I$7<0,(参数输入表!$I$148-参数输入表!$I$152-参数输入表!$I$441+$I$30)*O26,参数输入表!$I$148-参数输入表!$I$152-参数输入表!$I$441+$I$30) -> 123554.42 | P27: =IF(P25-参数输入表!$I$14-参数输入表!$I$7<0,(参数输入表!$I$148-参数输入表!$I$152-参数输入表!$I$441+$I$30)*P26,参数输入表!$I$148-参数输入表!$I$152-参数输入表!$I$441+$I$30) -> 123554.42 | Q27: =IF(Q25-参数输入表!$I$14-参数输入表!$I$7<0,(参数输入表!$I$148-参数输入表!$I$152-参数输入表!$I$441+$I$30)*Q26,参数输入表!$I$148-参数输入表!$I$152-参数输入表!$I$441+$I$30) -> 123554.42 | ... AF27: =IF(AF25-参数输入表!$I$14-参数输入表!$I$7<0,(参数输入表!$I$148-参数输入表!$I$152-参数输入表!$I$441+$I$30)*AF26,参数输入表!$I$148-参数输入表!$I$152-参数输入表!$I$441+$I$30) -> 123554.42
C28: 当期新增投资额 | D28: =SUM(F28:AF28) -> 123554.42 | E28: 万元 | J28: ='表1-资金筹措及还本付息表'!J8+'表1-资金筹措及还本付息表'!J9-'新建及改扩建项目投资概算明细 (光伏)'!F26-J69 -> 37178.271 | K28: ='表1-资金筹措及还本付息表'!K8+'表1-资金筹措及还本付息表'!K9-'新建及改扩建项目投资概算明细 (光伏)'!G26-K69 -> 86376.151 | L28: ='表1-资金筹措及还本付息表'!L8+'表1-资金筹措及还本付息表'!L9-'新建及改扩建项目投资概算明细 (光伏)'!H26-L69 -> 0 | M28: ='表1-资金筹措及还本付息表'!M8+'表1-资金筹措及还本付息表'!M9-'新建及改扩建项目投资概算明细 (光伏)'!K26-M69 -> 0 | N28: ='表1-资金筹措及还本付息表'!N8+'表1-资金筹措及还本付息表'!N9-'新建及改扩建项目投资概算明细 (光伏)'!L26-N69 -> 0 | O28: ='表1-资金筹措及还本付息表'!O8+'表1-资金筹措及还本付息表'!O9-'新建及改扩建项目投资概算明细 (光伏)'!M26-O69 -> 0 | P28: ='表1-资金筹措及还本付息表'!P8+'表1-资金筹措及还本付息表'!P9-'新建及改扩建项目投资概算明细 (光伏)'!N26-P69 -> 0 | Q28: ='表1-资金筹措及还本付息表'!Q8+'表1-资金筹措及还本付息表'!Q9-'新建及改扩建项目投资概算明细 (光伏)'!O26-Q69 -> 0 | R28: ='表1-资金筹措及还本付息表'!R8+'表1-资金筹措及还本付息表'!R9-'新建及改扩建项目投资概算明细 (光伏)'!P26-R69 -> 0 | S28: ='表1-资金筹措及还本付息表'!S8+'表1-资金筹措及还本付息表'!S9-'新建及改扩建项目投资概算明细 (光伏)'!Q26-S69 -> 0 | T28: ='表1-资金筹措及还本付息表'!T8+'表1-资金筹措及还本付息表'!T9-'新建及改扩建项目投资概算明细 (光伏)'!R26-T69 -> 0 | ... AF28: ='表1-资金筹措及还本付息表'!AF8+'表1-资金筹措及还本付息表'!AF9-'新建及改扩建项目投资概算明细 (光伏)'!AD26-AF69 -> 0
C29: 新增投资额累计 | E29: 万元 | J29: =I29+J28 -> 37178.271 | K29: =J29+K28 -> 123554.42 | L29: =K29+L28 -> 123554.42 | M29: =L29+M28 -> 123554.42 | N29: =M29+N28 -> 123554.42 | O29: =N29+O28 -> 123554.42 | P29: =O29+P28 -> 123554.42 | Q29: =P29+Q28 -> 123554.42 | ... AF29: =AE29+AF28 -> 123554.42
C30: 期末在建工程 | E30: 万元 | I30: ='表10-资产负债表(标准格式)'!H46 -> 0 | J30: =J29-J27 -> 18645.108 | K30: =K29-K27 -> 0 | L30: =L29-L27 -> 0 | M30: =M29-M27 -> 0 | N30: =N29-N27 -> 0 | O30: =O29-O27 -> 0 | P30: =P29-P27 -> 0 | Q30: =Q29-Q27 -> 0 | ... AF30: =AF29-AF27 -> 0
C31: 当期固定资产折旧 | D31: =SUM(F31:AF31) -> 123554.42 | E31: 万元 | J31: =SUM(J32:J34) -> 1029.6202 | K31: =SUM(K32:K34) -> 6177.7211 | L31: =SUM(L32:L34) -> 6864.1345 | M31: =SUM(M32:M34) -> 6864.1345 | N31: =SUM(N32:N34) -> 6864.1345 | O31: =SUM(O32:O34) -> 6864.1345 | P31: =SUM(P32:P34) -> 6864.1345 | Q31: =SUM(Q32:Q34) -> 6864.1345 | ... AF31: =SUM(AF32:AF34) -> 0
C32: 建设期第1年投产 | D32: =SUM(F32:AF32) -> 18533.163 | E32: 万元 | J32: =(参数输入表!$I$148-参数输入表!$I$152-参数输入表!$I$441+$I$30)*(1-参数输入表!$I$439)*参数输入表!$I$35/参数输入表!$I$438 -> 1029.6202 | K32: =(参数输入表!$I$148-参数输入表!$I$152-参数输入表!$I$441+$I$30)*(1-参数输入表!$I$439)*参数输入表!$I$35/参数输入表!$I$438 -> 1029.6202 | L32: =(参数输入表!$I$148-参数输入表!$I$152-参数输入表!$I$441+$I$30)*(1-参数输入表!$I$439)*参数输入表!$I$35/参数输入表!$I$438 -> 1029.6202 | M32: =(参数输入表!$I$148-参数输入表!$I$152-参数输入表!$I$441+$I$30)*(1-参数输入表!$I$439)*参数输入表!$I$35/参数输入表!$I$438 -> 1029.6202 | N32: =(参数输入表!$I$148-参数输入表!$I$152-参数输入表!$I$441+$I$30)*(1-参数输入表!$I$439)*参数输入表!$I$35/参数输入表!$I$438 -> 1029.6202 | O32: =(参数输入表!$I$148-参数输入表!$I$152-参数输入表!$I$441+$I$30)*(1-参数输入表!$I$439)*参数输入表!$I$35/参数输入表!$I$438 -> 1029.6202 | P32: =(参数输入表!$I$148-参数输入表!$I$152-参数输入表!$I$441+$I$30)*(1-参数输入表!$I$439)*参数输入表!$I$35/参数输入表!$I$438 -> 1029.6202 | Q32: =(参数输入表!$I$148-参数输入表!$I$152-参数输入表!$I$441+$I$30)*(1-参数输入表!$I$439)*参数输入表!$I$35/参数输入表!$I$438 -> 1029.6202 | ... AA32: =(参数输入表!$I$148-参数输入表!$I$152-参数输入表!$I$441+$I$30)*(1-参数输入表!$I$439)*参数输入表!$I$35/参数输入表!$I$438 -> 1029.6202
C33: 建设期第2年投产 | D33: =SUM(F33:AF33) -> 92665.816 | E33: 万元 | K33: =(参数输入表!$I$148-参数输入表!$I$152-参数输入表!$I$441+$I$30)*(1-参数输入表!$I$439)*参数输入表!$I$36/参数输入表!$I$438 -> 5148.1009 | L33: =(参数输入表!$I$148-参数输入表!$I$152-参数输入表!$I$441+$I$30)*(1-参数输入表!$I$439)*参数输入表!$I$36/参数输入表!$I$438 -> 5148.1009 | M33: =(参数输入表!$I$148-参数输入表!$I$152-参数输入表!$I$441+$I$30)*(1-参数输入表!$I$439)*参数输入表!$I$36/参数输入表!$I$438 -> 5148.1009 | N33: =(参数输入表!$I$148-参数输入表!$I$152-参数输入表!$I$441+$I$30)*(1-参数输入表!$I$439)*参数输入表!$I$36/参数输入表!$I$438 -> 5148.1009 | O33: =(参数输入表!$I$148-参数输入表!$I$152-参数输入表!$I$441+$I$30)*(1-参数输入表!$I$439)*参数输入表!$I$36/参数输入表!$I$438 -> 5148.1009 | P33: =(参数输入表!$I$148-参数输入表!$I$152-参数输入表!$I$441+$I$30)*(1-参数输入表!$I$439)*参数输入表!$I$36/参数输入表!$I$438 -> 5148.1009 | Q33: =(参数输入表!$I$148-参数输入表!$I$152-参数输入表!$I$441+$I$30)*(1-参数输入表!$I$439)*参数输入表!$I$36/参数输入表!$I$438 -> 5148.1009 | R33: =(参数输入表!$I$148-参数输入表!$I$152-参数输入表!$I$441+$I$30)*(1-参数输入表!$I$439)*参数输入表!$I$36/参数输入表!$I$438 -> 5148.1009 | ... AB33: =(参数输入表!$I$148-参数输入表!$I$152-参数输入表!$I$441+$I$30)*(1-参数输入表!$I$439)*参数输入表!$I$36/参数输入表!$I$438 -> 5148.1009
C34: 完全投产 | D34: =SUM(F34:AF34) -> 12355.442 | E34: 万元 | L34: =(参数输入表!$I$148-参数输入表!$I$152-参数输入表!$I$441+$I$30)*(1-参数输入表!$I$439)*参数输入表!$I$37/参数输入表!$I$438 -> 686.41345 | M34: =(参数输入表!$I$148-参数输入表!$I$152-参数输入表!$I$441+$I$30)*(1-参数输入表!$I$439)*参数输入表!$I$37/参数输入表!$I$438 -> 686.41345 | N34: =(参数输入表!$I$148-参数输入表!$I$152-参数输入表!$I$441+$I$30)*(1-参数输入表!$I$439)*参数输入表!$I$37/参数输入表!$I$438 -> 686.41345 | O34: =(参数输入表!$I$148-参数输入表!$I$152-参数输入表!$I$441+$I$30)*(1-参数输入表!$I$439)*参数输入表!$I$37/参数输入表!$I$438 -> 686.41345 | P34: =(参数输入表!$I$148-参数输入表!$I$152-参数输入表!$I$441+$I$30)*(1-参数输入表!$I$439)*参数输入表!$I$37/参数输入表!$I$438 -> 686.41345 | Q34: =(参数输入表!$I$148-参数输入表!$I$152-参数输入表!$I$441+$I$30)*(1-参数输入表!$I$439)*参数输入表!$I$37/参数输入表!$I$438 -> 686.41345 | R34: =(参数输入表!$I$148-参数输入表!$I$152-参数输入表!$I$441+$I$30)*(1-参数输入表!$I$439)*参数输入表!$I$37/参数输入表!$I$438 -> 686.41345 | S34: =(参数输入表!$I$148-参数输入表!$I$152-参数输入表!$I$441+$I$30)*(1-参数输入表!$I$439)*参数输入表!$I$37/参数输入表!$I$438 -> 686.41345 | ... AC34: =(参数输入表!$I$148-参数输入表!$I$152-参数输入表!$I$441+$I$30)*(1-参数输入表!$I$439)*参数输入表!$I$37/参数输入表!$I$438 -> 686.41345
C35: 固定资产折旧累计 | E35: 万元 | J35: =I35+J31 -> 1029.6202 | K35: =J35+K31 -> 7207.3413 | L35: =K35+L31 -> 14071.476 | M35: =L35+M31 -> 20935.61 | N35: =M35+N31 -> 27799.745 | O35: =N35+O31 -> 34663.879 | P35: =O35+P31 -> 41528.014 | Q35: =P35+Q31 -> 48392.148 | ... AF35: =AE35+AF31 -> 123554.42
C36: 期末固定资产净值 | E36: 万元 | J36: =J27-J35 -> 17503.543 | K36: =K27-K35 -> 116347.08 | L36: =L27-L35 -> 109482.95 | M36: =M27-M35 -> 102618.81 | N36: =N27-N35 -> 95754.677 | O36: =O27-O35 -> 88890.542 | P36: =P27-P35 -> 82026.408 | Q36: =Q27-Q35 -> 75162.273 | ... AF36: =AF27-AF35 -> 0
B37: 2 | C37: 期初长期待摊费用 | E37: 万元 | F37: 0 | G37: =F67 -> 0 | H37: =G67 -> 0 | I37: =H67 -> 0 | J37: =I67 -> 0 | K37: =J67 -> 0 | L37: =K67 -> 0 | M37: =L67 -> 0 | N37: =M67 -> 366.97248 | ... AF37: =AE67 -> 91.743119
C38: 当期新增长期待摊费用 | D38: =SUM(F38:AF38) -> 1834.8624 | E38: 万元 | F38: =参数输入表!I459/(1+参数输入表!I488) -> 0 | G38: =参数输入表!I460/(1+参数输入表!I488) -> 0 | H38: =参数输入表!I461/(1+参数输入表!I488) -> 0 | I38: =参数输入表!I462/(1+参数输入表!I488) -> 0 | J38: =参数输入表!I463/(1+参数输入表!I488) -> 0 | K38: =参数输入表!I464/(1+参数输入表!I488) -> 0 | L38: =参数输入表!I465/(1+参数输入表!I488) -> 0 | M38: =参数输入表!I466/(1+参数输入表!I488) -> 458.7156 | N38: =参数输入表!I467/(1+参数输入表!I488) -> 0 | O38: =参数输入表!I468/(1+参数输入表!I488) -> 0 | P38: =参数输入表!I469/(1+参数输入表!I488) -> 0 | Q38: =参数输入表!I470/(1+参数输入表!I488) -> 0 | R38: =参数输入表!I471/(1+参数输入表!I488) -> 458.7156 | S38: =参数输入表!I472/(1+参数输入表!I488) -> 0 | T38: =参数输入表!I473/(1+参数输入表!I488) -> 0 | U38: =参数输入表!I474/(1+参数输入表!I488) -> 0 | V38: =参数输入表!I475/(1+参数输入表!I488) -> 0 | W38: =参数输入表!I476/(1+参数输入表!I488) -> 458.7156 | X38: =参数输入表!I477/(1+参数输入表!I488) -> 0 | Y38: =参数输入表!I478/(1+参数输入表!I488) -> 0 | Z38: =参数输入表!I479/(1+参数输入表!I488) -> 0 | AA38: =参数输入表!I480/(1+参数输入表!I488) -> 0 | AB38: =参数输入表!I481/(1+参数输入表!I488) -> 458.7156 | AC38: =参数输入表!I482/(1+参数输入表!I488) -> 0 | AD38: =参数输入表!I483/(1+参数输入表!I488) -> 0 | AE38: =参数输入表!I484/(1+参数输入表!I488) -> 0 | AF38: =参数输入表!I485/(1+参数输入表!I488) -> 0
C39: 当期摊销 | D39: =SUM(F39:AF39) -> 1834.8624 | E39: 万元 | F39: =SUM(F40:F66) -> 0 | G39: =SUM(G40:G66) -> 0 | H39: =SUM(H40:H66) -> 0 | I39: =SUM(I40:I66) -> 0 | J39: =SUM(J40:J66) -> 0 | K39: =SUM(K40:K66) -> 0 | L39: =SUM(L40:L66) -> 0 | M39: =SUM(M40:M66) -> 91.743119 | ... AF39: =SUM(AF40:AF66) -> 91.743119
C40: 合作期第1年 | D40: =SUM(F40:AF40) -> 0 | E40: 万元 | F40: =IF('表2-折旧摊销表'!$AF$25+1-'表2-折旧摊销表'!$F$25>='表2-折旧摊销表'!$D$14,$F$38/$D$14,$F$38/('表2-折旧摊销表'!$AF$25+1-'表2-折旧摊销表'!$F$25)) -> 0 | G40: =IF('表2-折旧摊销表'!$AF$25+1-'表2-折旧摊销表'!$F$25>='表2-折旧摊销表'!$D$14,$F$38/$D$14,$F$38/('表2-折旧摊销表'!$AF$25+1-'表2-折旧摊销表'!$F$25)) -> 0 | H40: =IF('表2-折旧摊销表'!$AF$25+1-'表2-折旧摊销表'!$F$25>='表2-折旧摊销表'!$D$14,$F$38/$D$14,$F$38/('表2-折旧摊销表'!$AF$25+1-'表2-折旧摊销表'!$F$25)) -> 0 | I40: =IF('表2-折旧摊销表'!$AF$25+1-'表2-折旧摊销表'!$F$25>='表2-折旧摊销表'!$D$14,$F$38/$D$14,$F$38/('表2-折旧摊销表'!$AF$25+1-'表2-折旧摊销表'!$F$25)) -> 0 | J40: =IF('表2-折旧摊销表'!$AF$25+1-'表2-折旧摊销表'!$F$25>='表2-折旧摊销表'!$D$14,$F$38/$D$14,$F$38/('表2-折旧摊销表'!$AF$25+1-'表2-折旧摊销表'!$F$25)) -> 0
C41: 合作期第2年 | D41: =SUM(F41:AF41) -> 0 | E41: 万元 | G41: =IF('表2-折旧摊销表'!$AF$25+1-'表2-折旧摊销表'!$G$25>='表2-折旧摊销表'!$D$14,$G$38/$D$14,$G$38/('表2-折旧摊销表'!$AF$25+1-'表2-折旧摊销表'!$G$25)) -> 0 | H41: =IF('表2-折旧摊销表'!$AF$25+1-'表2-折旧摊销表'!$G$25>='表2-折旧摊销表'!$D$14,$G$38/$D$14,$G$38/('表2-折旧摊销表'!$AF$25+1-'表2-折旧摊销表'!$G$25)) -> 0 | I41: =IF('表2-折旧摊销表'!$AF$25+1-'表2-折旧摊销表'!$G$25>='表2-折旧摊销表'!$D$14,$G$38/$D$14,$G$38/('表2-折旧摊销表'!$AF$25+1-'表2-折旧摊销表'!$G$25)) -> 0 | J41: =IF('表2-折旧摊销表'!$AF$25+1-'表2-折旧摊销表'!$G$25>='表2-折旧摊销表'!$D$14,$G$38/$D$14,$G$38/('表2-折旧摊销表'!$AF$25+1-'表2-折旧摊销表'!$G$25)) -> 0 | K41: =IF('表2-折旧摊销表'!$AF$25+1-'表2-折旧摊销表'!$G$25>='表2-折旧摊销表'!$D$14,$G$38/$D$14,$G$38/('表2-折旧摊销表'!$AF$25+1-'表2-折旧摊销表'!$G$25)) -> 0
...

Sheet 表3-成本费用表
B2: 成本费用表-资本金
B3: 序号 | C3: 项目 | D3: 合计 | E3: 单位 | F3: 2020年 | G3: 2021年 | H3: 2022年 | I3: 45107 | J3: 45261 | K3: 2024年 | L3: 2025年 | M3: 2026年 | N3: 2027年 | O3: 2028年 | P3: 2029年 | Q3: 2030年 | R3: 2031年 | S3: 2032年 | T3: 2033年 | U3: 2034年 | V3: 2035年 | W3: 2036年 | X3: 2037年 | Y3: 2038年 | Z3: 2039年 | AA3: 2040年 | AB3: 2041年 | AC3: 2042年 | AD3: 2043年 | AE3: 2044年 | AF3: 53051
F4: 1 | G4: 2 | H4: 3 | I4: 4 | J4: 5 | K4: 6 | L4: 7 | M4: 8 | N4: 9 | O4: 10 | P4: 11 | Q4: 12 | R4: 13 | S4: 14 | T4: 15 | U4: 16 | V4: 17 | W4: 18 | X4: 19 | Y4: 20 | Z4: 21 | AA4: 22 | AB4: 23 | AC4: 24 | AD4: 25 | AE4: 26 | AF4: 27
C5: 投产比例 | F5: =参数输入表!$I$39 -> 0 | G5: =参数输入表!$I$40 -> 0.03125 | H5: =参数输入表!$I$41 -> 0.03125 | I5: =参数输入表!$I$42 -> 0.03125 | J5: =参数输入表!$I$43 -> 0.1765625 | K5: =参数输入表!$I$44 -> 0.7578125 | L5: =参数输入表!$I$45 -> 1 | M5: =参数输入表!$I$46 -> 1 | N5: =参数输入表!$I$47 -> 1 | O5: =参数输入表!$I$48 -> 1 | P5: =参数输入表!$I$49 -> 1 | Q5: =参数输入表!$I$50 -> 1 | R5: =参数输入表!$I$51 -> 1 | S5: =参数输入表!$I$52 -> 1 | T5: =参数输入表!$I$53 -> 1 | U5: =参数输入表!$I$54 -> 1 | V5: =参数输入表!$I$55 -> 1 | W5: =参数输入表!$I$56 -> 1 | X5: =参数输入表!$I$57 -> 1 | Y5: =参数输入表!$I$58 -> 1 | Z5: =参数输入表!$I$59 -> 1 | AA5: =参数输入表!$I$60 -> 1 | AB5: =参数输入表!$I$61 -> 1 | AC5: =参数输入表!$I$62 -> 1 | AD5: =参数输入表!$I$63 -> 1 | AE5: =参数输入表!$I$64 -> 1 | AF5: =参数输入表!$I$65 -> 1
B6: 一 | C6: 生产经营成本 | D6: =SUM(F6:AF6) -> 280573.04 | E6: 万元 | F6: =F7+F16+F17+F20+F21 -> 0 | G6: =G7+G16+G17+G20+G21 -> 0 | H6: =H7+H16+H17+H20+H21 -> 0 | I6: =I7+I16+I17+I20+I21 -> 2000 | J6: =J7+J16+J17+J20+J21 -> 3055.4966 | K6: =K7+K16+K17+K20+K21 -> 13980.681 | L6: =L7+L16+L17+L20+L21 -> 17011.799 | M6: =M7+M16+M17+M20+M21 -> 17068.903 | ... AF6: =AF7+AF16+AF17+AF20+AF21 -> 4244.5263
B7: 1 | C7: 生产成本 | D7: =SUM(F7:AF7) -> 221338.95 | E7: 万元 | F7: ='表5-利润表-资本金(标准格式)'!F11 -> 0 | G7: ='表5-利润表-资本金(标准格式)'!G11 -> 0 | H7: ='表5-利润表-资本金(标准格式)'!H11 -> 0 | I7: ='表5-利润表-资本金(标准格式)'!I11 -> 2000 | J7: =SUM(J8:J15) -> 2381.5855 | K7: =SUM(K8:K15) -> 10114.817 | L7: =SUM(L8:L15) -> 11326.73 | M7: =SUM(M8:M15) -> 11664.87 | N7: =SUM(N8:N15) -> 11693.67 | O7: =SUM(O8:O15) -> 11722.47 | P7: =SUM(P8:P15) -> 11751.27 | Q7: =SUM(Q8:Q15) -> 11780.07 | ... AF7: =SUM(AF8:AF15) -> 993.64165
B8: 1.1 | C8: 材料费 | D8: =SUM(F8:AF8) -> 1206.75 | E8: 万元 | J8: =参数输入表!$I$289*参数输入表!$I$295/(1+参数输入表!$I$318)*J5*(12-MONTH(参数输入表!$I$8))/12 -> 28.25 | K8: =参数输入表!$I$289*参数输入表!$I$296/(1+参数输入表!$I$318)*K5 -> 242.5 | L8: =参数输入表!$I$289*参数输入表!$I$297/(1+参数输入表!$I$318)*L5 -> 320 | M8: =参数输入表!$I$289*参数输入表!$I$298/(1+参数输入表!$I$318)*M5 -> 32 | N8: =参数输入表!$I$289*参数输入表!$I$299/(1+参数输入表!$I$318)*N5 -> 32 | O8: =参数输入表!$I$289*参数输入表!$I$300/(1+参数输入表!$I$318)*O5 -> 32 | P8: =参数输入表!$I$289*参数输入表!$I$301/(1+参数输入表!$I$318)*P5 -> 32 | Q8: =参数输入表!$I$289*参数输入表!$I$302/(1+参数输入表!$I$318)*Q5 -> 32 | R8: =参数输入表!$I$289*参数输入表!$I$303/(1+参数输入表!$I$318)*R5 -> 32 | S8: =参数输入表!$I$289*参数输入表!$I$304/(1+参数输入表!$I$318)*S5 -> 32 | T8: =参数输入表!$I$289*参数输入表!$I$305/(1+参数输入表!$I$318)*T5 -> 32 | U8: =参数输入表!$I$289*参数输入表!$I$306/(1+参数输入表!$I$318)*U5 -> 32 | V8: =参数输入表!$I$289*参数输入表!$I$307/(1+参数输入表!$I$318)*V5 -> 32 | W8: =参数输入表!$I$289*参数输入表!$I$308/(1+参数输入表!$I$318)*W5 -> 32 | X8: =参数输入表!$I$289*参数输入表!$I$309/(1+参数输入表!$I$318)*X5 -> 32 | Y8: =参数输入表!$I$289*参数输入表!$I$310/(1+参数输入表!$I$318)*Y5 -> 32 | Z8: =参数输入表!$I$289*参数输入表!$I$311/(1+参数输入表!$I$318)*Z5 -> 32 | AA8: =参数输入表!$I$289*参数输入表!$I$312/(1+参数输入表!$I$318)*AA5 -> 32 | AB8: =参数输入表!$I$289*参数输入表!$I$313/(1+参数输入表!$I$318)*AB5 -> 32 | AC8: =参数输入表!$I$289*参数输入表!$I$314/(1+参数输入表!$I$318)*AC5 -> 32 | AD8: =参数输入表!$I$289*参数输入表!$I$315/(1+参数输入表!$I$318)*AD5 -> 32 | AE8: =参数输入表!$I$289*参数输入表!$I$316/(1+参数输入表!$I$318)*AE5 -> 32 | AF8: =参数输入表!$I$289*参数输入表!$I$317/(1+参数输入表!$I$318)*AF5*MONTH(参数输入表!I6)/12 -> 8
B9: 1.2 | C9: 维修费 | D9: =SUM(F9:AF9) -> 13768.266 | E9: 万元 | J9: =参数输入表!$I$320*参数输入表!$I$326/(1+参数输入表!$I$349)*J5*(12-MONTH(参数输入表!I8))/12 -> 0 | K9: =参数输入表!$I$320*参数输入表!$I$327/(1+参数输入表!$I$349)*K5 -> 0 | L9: =参数输入表!$I$320*参数输入表!$I$328/(1+参数输入表!$I$349)*L5 -> 0 | M9: =参数输入表!$I$320*参数输入表!$I$329/(1+参数输入表!$I$349)*M5 -> 483.09706 | N9: =参数输入表!$I$320*参数输入表!$I$330/(1+参数输入表!$I$349)*N5 -> 483.09706 | O9: =参数输入表!$I$320*参数输入表!$I$331/(1+参数输入表!$I$349)*O5 -> 483.09706 | P9: =参数输入表!$I$320*参数输入表!$I$332/(1+参数输入表!$I$349)*P5 -> 483.09706 | Q9: =参数输入表!$I$320*参数输入表!$I$333/(1+参数输入表!$I$349)*Q5 -> 483.09706 | R9: =参数输入表!$I$320*参数输入表!$I$334/(1+参数输入表!$I$349)*R5 -> 644.12941 | S9: =参数输入表!$I$320*参数输入表!$I$335/(1+参数输入表!$I$349)*S5 -> 644.12941 | T9: =参数输入表!$I$320*参数输入表!$I$336/(1+参数输入表!$I$349)*T5 -> 644.12941 | U9: =参数输入表!$I$320*参数输入表!$I$337/(1+参数输入表!$I$349)*U5 -> 644.12941 | V9: =参数输入表!$I$320*参数输入表!$I$338/(1+参数输入表!$I$349)*V5 -> 644.12941 | W9: =参数输入表!$I$320*参数输入表!$I$339/(1+参数输入表!$I$349)*W5 -> 805.16176 | X9: =参数输入表!$I$320*参数输入表!$I$340/(1+参数输入表!$I$349)*X5 -> 805.16176 | Y9: =参数输入表!$I$320*参数输入表!$I$341/(1+参数输入表!$I$349)*Y5 -> 805.16176 | Z9: =参数输入表!$I$320*参数输入表!$I$342/(1+参数输入表!$I$349)*Z5 -> 805.16176 | AA9: =参数输入表!$I$320*参数输入表!$I$343/(1+参数输入表!$I$349)*AA5 -> 805.16176 | AB9: =参数输入表!$I$320*参数输入表!$I$344/(1+参数输入表!$I$349)*AB5 -> 966.19411 | AC9: =参数输入表!$I$320*参数输入表!$I$345/(1+参数输入表!$I$349)*AC5 -> 966.19411 | AD9: =参数输入表!$I$320*参数输入表!$I$346/(1+参数输入表!$I$349)*AD5 -> 966.19411 | AE9: =参数输入表!$I$320*参数输入表!$I$347/(1+参数输入表!$I$349)*AE5 -> 966.19411 | AF9: =参数输入表!$I$320*参数输入表!$I$348/(1+参数输入表!$I$349)*AF5*MONTH(参数输入表!I6)/12 -> 241.54853
B10: 1.3 | C10: 生产人员薪酬及福利 | D10: =SUM(F10:AF10) -> 19563.143 | E10: 万元 | J10: =(参数输入表!$I$383*参数输入表!$I$386+参数输入表!$I$384*参数输入表!$I$387)*(1+参数输入表!$I$388)*(1+参数输入表!$I$389*(J4-参数输入表!$I$7))/(1+参数输入表!$I$390)*J5*(12-MONTH(参数输入表!I8))/12 -> 53.3925 | K10: =(参数输入表!$I$383*参数输入表!$I$386+参数输入表!$I$384*参数输入表!$I$387)*(1+参数输入表!$I$388)*(1+参数输入表!$I$389*(K4-参数输入表!$I$7))/(1+参数输入表!$I$390)*K5 -> 480.15 | L10: =(参数输入表!$I$383*参数输入表!$I$386+参数输入表!$I$384*参数输入表!$I$387)*(1+参数输入表!$I$388)*(1+参数输入表!$I$389*(L4-参数输入表!$I$7))/(1+参数输入表!$I$390)*L5 -> 662.4 | M10: =(参数输入表!$I$383*参数输入表!$I$386+参数输入表!$I$384*参数输入表!$I$387)*(1+参数输入表!$I$388)*(1+参数输入表!$I$389*(M4-参数输入表!$I$7))/(1+参数输入表!$I$390)*M5 -> 691.2 | N10: =(参数输入表!$I$383*参数输入表!$I$386+参数输入表!$I$384*参数输入表!$I$387)*(1+参数输入表!$I$388)*(1+参数输入表!$I$389*(N4-参数输入表!$I$7))/(1+参数输入表!$I$390)*N5 -> 720 | O10: =(参数输入表!$I$383*参数输入表!$I$386+参数输入表!$I$384*参数输入表!$I$387)*(1+参数输入表!$I$388)*(1+参数输入表!$I$389*(O4-参数输入表!$I$7))/(1+参数输入表!$I$390)*O5 -> 748.8 | P10: =(参数输入表!$I$383*参数输入表!$I$386+参数输入表!$I$384*参数输入表!$I$387)*(1+参数输入表!$I$388)*(1+参数输入表!$I$389*(P4-参数输入表!$I$7))/(1+参数输入表!$I$390)*P5 -> 777.6 | Q10: =(参数输入表!$I$383*参数输入表!$I$386+参数输入表!$I$384*参数输入表!$I$387)*(1+参数输入表!$I$388)*(1+参数输入表!$I$389*(Q4-参数输入表!$I$7))/(1+参数输入表!$I$390)*Q5 -> 806.4 | R10: =(参数输入表!$I$383*参数输入表!$I$386+参数输入表!$I$384*参数输入表!$I$387)*(1+参数输入表!$I$388)*(1+参数输入表!$I$389*(R4-参数输入表!$I$7))/(1+参数输入表!$I$390)*R5 -> 835.2 | ... AE10: =(参数输入表!$I$383*参数输入表!$I$386+参数输入表!$I$384*参数输入表!$I$387)*(1+参数输入表!$I$388)*(1+参数输入表!$I$389*(AE4-参数输入表!$I$7))/(1+参数输入表!$I$390)*AE5 -> 1209.6 | AF10: =(参数输入表!$I$383*参数输入表!$I$386+参数输入表!$I$384*参数输入表!$I$387)*(1+参数输入表!$I$388)*(1+参数输入表!$I$389*(AF4-参数输入表!$I$7))/(1+参数输入表!$I$390)*AF5*MONTH(参数输入表!I6)/12 -> 309.6
B11: 1.4 | C11: 长期待摊费用当期摊销 | D11: =SUM(F11:AF11) -> 1834.8624 | E11: 万元 | J11: ='表2-折旧摊销表'!J133 -> 0 | K11: ='表2-折旧摊销表'!K133 -> 0 | L11: ='表2-折旧摊销表'!L133 -> 0 | M11: ='表2-折旧摊销表'!M133 -> 91.743119 | N11: ='表2-折旧摊销表'!N133 -> 91.743119 | O11: ='表2-折旧摊销表'!O133 -> 91.743119 | P11: ='表2-折旧摊销表'!P133 -> 91.743119 | Q11: ='表2-折旧摊销表'!Q133 -> 91.743119 | ... AF11: ='表2-折旧摊销表'!AF133 -> 91.743119
B12: 1.5 | C12: 营业相关资产折旧及摊销 | D12: =SUM(F12:AF12) -> 154737.21 | E12: 万元 | J12: ='表2-折旧摊销表'!J132+'表2-折旧摊销表'!J134 -> 2094.218 | K12: ='表2-折旧摊销表'!K132+'表2-折旧摊销表'!K134 -> 8366.9167 | L12: ='表2-折旧摊销表'!L132+'表2-折旧摊销表'!L134 -> 9063.3301 | M12: ='表2-折旧摊销表'!M132+'表2-折旧摊销表'!M134 -> 9063.3301 | N12: ='表2-折旧摊销表'!N132+'表2-折旧摊销表'!N134 -> 9063.3301 | O12: ='表2-折旧摊销表'!O132+'表2-折旧摊销表'!O134 -> 9063.3301 | P12: ='表2-折旧摊销表'!P132+'表2-折旧摊销表'!P134 -> 9063.3301 | Q12: ='表2-折旧摊销表'!Q132+'表2-折旧摊销表'!Q134 -> 9063.3301 | ... AF12: ='表2-折旧摊销表'!AF132+'表2-折旧摊销表'!AF134 -> 0
B13: 1.6 | C13: 其他费用 | D13: =SUM(F13:AF13) -> 6750.75 | E13: 万元 | J13: =参数输入表!$I$392*参数输入表!$I$393/(1+参数输入表!$I$394)*J5*(12-MONTH(参数输入表!I8))/12 -> 28.25 | K13: =参数输入表!$I$392*参数输入表!$I$393/(1+参数输入表!$I$394)*K5 -> 242.5 | L13: =参数输入表!$I$392*参数输入表!$I$393/(1+参数输入表!$I$394)*L5 -> 320 | M13: =参数输入表!$I$392*参数输入表!$I$393/(1+参数输入表!$I$394)*M5 -> 320 | N13: =参数输入表!$I$392*参数输入表!$I$393/(1+参数输入表!$I$394)*N5 -> 320 | O13: =参数输入表!$I$392*参数输入表!$I$393/(1+参数输入表!$I$394)*O5 -> 320 | P13: =参数输入表!$I$392*参数输入表!$I$393/(1+参数输入表!$I$394)*P5 -> 320 | Q13: =参数输入表!$I$392*参数输入表!$I$393/(1+参数输入表!$I$394)*Q5 -> 320 | R13: =参数输入表!$I$392*参数输入表!$I$393/(1+参数输入表!$I$394)*R5 -> 320 | ... AE13: =参数输入表!$I$392*参数输入表!$I$393/(1+参数输入表!$I$394)*AE5 -> 320 | AF13: =参数输入表!$I$392*参数输入表!$I$393/(1+参数输入表!$I$394)*AF5*MONTH(参数输入表!I6)/12 -> 80
B14: 1.7 | C14: 储能费用 | D14: =SUM(F14:AF14) -> 15526.725 | E14: 万元 | J14: =参数输入表!$I$396*参数输入表!$I$397*1000/10000/(1+参数输入表!$I$398)*J5*(12-MONTH(参数输入表!I8))/12 -> 64.975 | K14: =参数输入表!$I$396*参数输入表!$I$397*1000/10000/(1+参数输入表!$I$398)*K5 -> 557.75 | L14: =参数输入表!$I$396*参数输入表!$I$397*1000/10000/(1+参数输入表!$I$398)*L5 -> 736 | M14: =参数输入表!$I$396*参数输入表!$I$397*1000/10000/(1+参数输入表!$I$398)*M5 -> 736 | N14: =参数输入表!$I$396*参数输入表!$I$397*1000/10000/(1+参数输入表!$I$398)*N5 -> 736 | O14: =参数输入表!$I$396*参数输入表!$I$397*1000/10000/(1+参数输入表!$I$398)*O5 -> 736 | P14: =参数输入表!$I$396*参数输入表!$I$397*1000/10000/(1+参数输入表!$I$398)*P5 -> 736 | Q14: =参数输入表!$I$396*参数输入表!$I$397*1000/10000/(1+参数输入表!$I$398)*Q5 -> 736 | R14: =参数输入表!$I$396*参数输入表!$I$397*1000/10000/(1+参数输入表!$I$398)*R5 -> 736 | ... AE14: =参数输入表!$I$396*参数输入表!$I$397*1000/10000/(1+参数输入表!$I$398)*AE5 -> 736 | AF14: =参数输入表!$I$396*参数输入表!$I$397*1000/10000/(1+参数输入表!$I$398)*AF5*MONTH(参数输入表!I6)/12 -> 184
B15: 1.8 | C15: 场地租金费用 | D15: =SUM(F15:AF15) -> 5951.25 | E15: 万元 | J15: =参数输入表!$I$400*参数输入表!$I$406/10000/(1+参数输入表!$I$429)*(12-MONTH(参数输入表!I8))/12 -> 112.5 | K15: =参数输入表!$I$400*参数输入表!$I$407/10000/(1+参数输入表!$I$429) -> 225 | L15: =参数输入表!$I$400*参数输入表!$I$408/10000/(1+参数输入表!$I$429) -> 225 | M15: =参数输入表!$I$400*参数输入表!$I$409/10000/(1+参数输入表!$I$429) -> 247.5 | N15: =参数输入表!$I$400*参数输入表!$I$410/10000/(1+参数输入表!$I$429) -> 247.5 | O15: =参数输入表!$I$400*参数输入表!$I$411/10000/(1+参数输入表!$I$429) -> 247.5 | P15: =参数输入表!$I$400*参数输入表!$I$412/10000/(1+参数输入表!$I$429) -> 247.5 | Q15: =参数输入表!$I$400*参数输入表!$I$413/10000/(1+参数输入表!$I$429) -> 247.5 | R15: =参数输入表!$I$400*参数输入表!$I$414/10000/(1+参数输入表!$I$429) -> 270 | S15: =参数输入表!$I$400*参数输入表!$I$415/10000/(1+参数输入表!$I$429) -> 270 | T15: =参数输入表!$I$400*参数输入表!$I$416/10000/(1+参数输入表!$I$429) -> 270 | U15: =参数输入表!$I$400*参数输入表!$I$417/10000/(1+参数输入表!$I$429) -> 270 | V15: =参数输入表!$I$400*参数输入表!$I$418/10000/(1+参数输入表!$I$429) -> 270 | W15: =参数输入表!$I$400*参数输入表!$I$419/10000/(1+参数输入表!$I$429) -> 292.5 | X15: =参数输入表!$I$400*参数输入表!$I$420/10000/(1+参数输入表!$I$429) -> 292.5 | Y15: =参数输入表!$I$400*参数输入表!$I$421/10000/(1+参数输入表!$I$429) -> 292.5 | Z15: =参数输入表!$I$400*参数输入表!$I$422/10000/(1+参数输入表!$I$429) -> 292.5 | AA15: =参数输入表!$I$400*参数输入表!$I$423/10000/(1+参数输入表!$I$429) -> 292.5 | AB15: =参数输入表!$I$400*参数输入表!$I$424/10000/(1+参数输入表!$I$429) -> 315 | AC15: =参数输入表!$I$400*参数输入表!$I$425/10000/(1+参数输入表!$I$429) -> 315 | AD15: =参数输入表!$I$400*参数输入表!$I$426/10000/(1+参数输入表!$I$429) -> 315 | AE15: =参数输入表!$I$400*参数输入表!$I$427/10000/(1+参数输入表!$I$429) -> 315 | AF15: =参数输入表!$I$400*参数输入表!$I$428/10000/(1+参数输入表!$I$429)*MONTH(参数输入表!I6)/12 -> 78.75
B16: 2 | C16: 销售费用 | D16: =SUM(F16:AF16) -> 0 | E16: 万元 | F16: ='表5-利润表-资本金(标准格式)'!F20 -> 0 | G16: ='表5-利润表-资本金(标准格式)'!G20 -> 0 | H16: ='表5-利润表-资本金(标准格式)'!H20 -> 0 | I16: ='表5-利润表-资本金(标准格式)'!I20 -> 0 | J16: 0 | K16: 0 | L16: 0 | M16: 0 | N16: 0 | O16: 0 | P16: 0 | Q16: 0 | R16: 0 | S16: 0 | T16: 0 | U16: 0 | V16: 0 | W16: 0 | X16: 0 | Y16: 0 | Z16: 0 | AA16: 0 | AB16: 0 | AC16: 0 | AD16: 0 | AE16: 0 | AF16: 0
B17: 3 | C17: 管理费用 | D17: =SUM(F17:AF17) -> 4313.6169 | E17: 万元 | F17: ='表5-利润表-资本金(标准格式)'!F21 -> 0 | G17: ='表5-利润表-资本金(标准格式)'!G21 -> 0 | H17: ='表5-利润表-资本金(标准格式)'!H21 -> 0 | I17: ='表5-利润表-资本金(标准格式)'!I21 -> 0 | J17: =SUM(J18:J19) -> 1.7018923 | K17: =SUM(K18:K19) -> 14.609164 | L17: =SUM(L18:L19) -> 19.278072 | M17: =SUM(M18:M19) -> 54.329111 | N17: =SUM(N18:N19) -> 54.329111 | O17: =SUM(O18:O19) -> 54.329111 | P17: =SUM(P18:P19) -> 54.329111 | Q17: =SUM(Q18:Q19) -> 54.329111 | ... AF17: =SUM(AF18:AF19) -> 3245.7746
B18: 3.1 | C18: 保险费 | D18: =SUM(F18:AF18) -> 1081.4245 | E18: 万元 | J18: =参数输入表!$I$351*参数输入表!$I$357/(1+参数输入表!$I$380)*J5*(12-MONTH(参数输入表!I8))/12 -> 1.7018923 | K18: =参数输入表!$I$351*参数输入表!$I$358/(1+参数输入表!$I$380)*K5 -> 14.609164 | L18: =参数输入表!$I$351*参数输入表!$I$359/(1+参数输入表!$I$380)*L5 -> 19.278072 | M18: =参数输入表!$I$351*参数输入表!$I$360/(1+参数输入表!$I$380)*M5 -> 54.329111 | N18: =参数输入表!$I$351*参数输入表!$I$361/(1+参数输入表!$I$380)*N5 -> 54.329111 | O18: =参数输入表!$I$351*参数输入表!$I$362/(1+参数输入表!$I$380)*O5 -> 54.329111 | P18: =参数输入表!$I$351*参数输入表!$I$363/(1+参数输入表!$I$380)*P5 -> 54.329111 | Q18: =参数输入表!$I$351*参数输入表!$I$364/(1+参数输入表!$I$380)*Q5 -> 54.329111 | R18: =参数输入表!$I$351*参数输入表!$I$365/(1+参数输入表!$I$380)*R5 -> 54.329111 | S18: =参数输入表!$I$351*参数输入表!$I$366/(1+参数输入表!$I$380)*S5 -> 54.329111 | T18: =参数输入表!$I$351*参数输入表!$I$367/(1+参数输入表!$I$380)*T5 -> 54.329111 | U18: =参数输入表!$I$351*参数输入表!$I$368/(1+参数输入表!$I$380)*U5 -> 54.329111 | V18: =参数输入表!$I$351*参数输入表!$I$369/(1+参数输入表!$I$380)*V5 -> 54.329111 | W18: =参数输入表!$I$351*参数输入表!$I$370/(1+参数输入表!$I$380)*W5 -> 54.329111 | X18: =参数输入表!$I$351*参数输入表!$I$371/(1+参数输入表!$I$380)*X5 -> 54.329111 | Y18: =参数输入表!$I$351*参数输入表!$I$372/(1+参数输入表!$I$380)*Y5 -> 54.329111 | Z18: =参数输入表!$I$351*参数输入表!$I$373/(1+参数输入表!$I$380)*Z5 -> 54.329111 | AA18: =参数输入表!$I$351*参数输入表!$I$374/(1+参数输入表!$I$380)*AA5 -> 54.329111 | AB18: =参数输入表!$I$351*参数输入表!$I$375/(1+参数输入表!$I$380)*AB5 -> 54.329111 | AC18: =参数输入表!$I$351*参数输入表!$I$376/(1+参数输入表!$I$380)*AC5 -> 54.329111 | AD18: =参数输入表!$I$351*参数输入表!$I$377/(1+参数输入表!$I$380)*AD5 -> 54.329111 | AE18: =参数输入表!$I$351*参数输入表!$I$378/(1+参数输入表!$I$380)*AE5 -> 54.329111 | AF18: =参数输入表!$I$351*参数输入表!$I$379/(1+参数输入表!$I$380)*AF5*MONTH(参数输入表!I6)/12 -> 13.582278
B19: 3.2 | C19: 期末拆除费用 | D19: =SUM(F19:AF19) -> 3232.1923 | E19: 万元 | AF19: =参数输入表!$I$431*参数输入表!$I$432/(1+参数输入表!$I$433) -> 3232.1923
B20: 4 | C20: 研发费用 | D20: =SUM(F20:AF20) -> 0 | E20: 万元 | F20: ='表5-利润表-资本金(标准格式)'!F22 -> 0 | G20: ='表5-利润表-资本金(标准格式)'!G22 -> 0 | H20: ='表5-利润表-资本金(标准格式)'!H22 -> 0 | I20: ='表5-利润表-资本金(标准格式)'!I22 -> 0 | J20: 0 | K20: 0 | L20: 0 | M20: 0 | N20: 0 | O20: 0 | P20: 0 | Q20: 0 | R20: 0 | S20: 0 | T20: 0 | U20: 0 | V20: 0 | W20: 0 | X20: 0 | Y20: 0 | Z20: 0 | AA20: 0 | AB20: 0 | AC20: 0 | AD20: 0 | AE20: 0 | AF20: 0
B21: 5 | C21: 财务费用 | D21: =SUM(F21:AF21) -> 54920.468 | E21: 万元 | F21: ='表5-利润表-资本金(标准格式)'!F23 -> 0 | G21: ='表5-利润表-资本金(标准格式)'!G23 -> 0 | H21: ='表5-利润表-资本金(标准格式)'!H23 -> 0 | I21: ='表5-利润表-资本金(标准格式)'!I23 -> 0 | J21: =SUM(J22:J24) -> 672.2092 | K21: =SUM(K22:K24) -> 3851.2555 | L21: =SUM(L22:L24) -> 5665.7911 | M21: =SUM(M22:M24) -> 5349.7034 | N21: =SUM(N22:N24) -> 5024.1627 | O21: =SUM(O22:O24) -> 4707.0125 | P21: =SUM(P22:P24) -> 4379.5789 | Q21: =SUM(Q22:Q24) -> 4041.4196 | ... AF21: =SUM(AF22:AF24) -> 5.11
B22: 5.1 | C22: 长期借款利息 | D22: =SUM(F22:AF22) -> 46904.724 | E22: 万元 | J22: ='表1-资金筹措及还本付息表'!J44+'表1-资金筹措及还本付息表'!J74 -> 460.34207 | K22: ='表1-资金筹措及还本付息表'!K44+'表1-资金筹措及还本付息表'!K74 -> 3409.2712 | L22: ='表1-资金筹措及还本付息表'!L44+'表1-资金筹措及还本付息表'!L74 -> 5203.3668 | M22: ='表1-资金筹措及还本付息表'!M44+'表1-资金筹措及还本付息表'!M74 -> 4905.5291 | N22: ='表1-资金筹措及还本付息表'!N44+'表1-资金筹措及还本付息表'!N74 -> 4598.2385 | O22: ='表1-资金筹措及还本付息表'!O44+'表1-资金筹措及还本付息表'!O74 -> 4281.0883 | P22: ='表1-资金筹措及还本付息表'!P44+'表1-资金筹措及还本付息表'!P74 -> 3953.6546 | Q22: ='表1-资金筹措及还本付息表'!Q44+'表1-资金筹措及还本付息表'!Q74 -> 3615.4953 | ... AF22: ='表1-资金筹措及还本付息表'!AF44+'表1-资金筹措及还本付息表'!AF74 -> -1.9308572e-13
B23: 5.2 | C23: 短期借款利息 | D23: =SUM(F23:AF23) -> 7601.8339 | E23: 万元 | J23: ='表1-资金筹措及还本付息表'!J84 -> 211.86713 | K23: ='表1-资金筹措及还本付息表'!K84 -> 441.98426 | L23: ='表1-资金筹措及还本付息表'!L84 -> 441.98426 | M23: ='表1-资金筹措及还本付息表'!M84 -> 423.73426 | N23: ='表1-资金筹措及还本付息表'!N84 -> 405.48426 | O23: ='表1-资金筹措及还本付息表'!O84 -> 405.48426 | P23: ='表1-资金筹措及还本付息表'!P84 -> 405.48426 | Q23: ='表1-资金筹措及还本付息表'!Q84 -> 405.48426 | ... AF23: ='表1-资金筹措及还本付息表'!AF84 -> 0
B24: 5.3 | C24: 流动资金借款利息 | D24: =SUM(F24:AF24) -> 413.91 | E24: 万元 | J24: ='表1-资金筹措及还本付息表'!J64 -> 0 | K24: ='表1-资金筹措及还本付息表'!K64 -> 0 | L24: ='表1-资金筹措及还本付息表'!L64 -> 20.44 | M24: ='表1-资金筹措及还本付息表'!M64 -> 20.44 | N24: ='表1-资金筹措及还本付息表'!N64 -> 20.44 | O24: ='表1-资金筹措及还本付息表'!O64 -> 20.44 | P24: ='表1-资金筹措及还本付息表'!P64 -> 20.44 | Q24: ='表1-资金筹措及还本付息表'!Q64 -> 20.44 | ... AF24: ='表1-资金筹措及还本付息表'!AF64 -> 5.11
B25: 二 | C25: 营业外支出 | D25: =SUM(F25:AF25) -> 0 | E25: 万元 | F25: ='表5-利润表-资本金(标准格式)'!F41 -> 0 | G25: ='表5-利润表-资本金(标准格式)'!G41 -> 0 | H25: ='表5-利润表-资本金(标准格式)'!H41 -> 0 | I25: ='表5-利润表-资本金(标准格式)'!I41 -> 0 | J25: =参数输入表!$I$533/(1+参数输入表!$I$556) -> 0 | K25: =参数输入表!$I$534/(1+参数输入表!$I$556) -> 0 | L25: =参数输入表!$I$535/(1+参数输入表!$I$556) -> 0 | M25: =参数输入表!$I$536/(1+参数输入表!$I$556) -> 0 | N25: =参数输入表!$I$537/(1+参数输入表!$I$556) -> 0 | O25: =参数输入表!$I$538/(1+参数输入表!$I$556) -> 0 | P25: =参数输入表!$I$539/(1+参数输入表!$I$556) -> 0 | Q25: =参数输入表!$I$540/(1+参数输入表!$I$556) -> 0 | R25: =参数输入表!$I$541/(1+参数输入表!$I$556) -> 0 | S25: =参数输入表!$I$542/(1+参数输入表!$I$556) -> 0 | T25: =参数输入表!$I$543/(1+参数输入表!$I$556) -> 0 | U25: =参数输入表!$I$544/(1+参数输入表!$I$556) -> 0 | V25: =参数输入表!$I$545/(1+参数输入表!$I$556) -> 0 | W25: =参数输入表!$I$546/(1+参数输入表!$I$556) -> 0 | X25: =参数输入表!$I$547/(1+参数输入表!$I$556) -> 0 | Y25: =参数输入表!$I$548/(1+参数输入表!$I$556) -> 0 | Z25: =参数输入表!$I$549/(1+参数输入表!$I$556) -> 0 | AA25: =参数输入表!$I$550/(1+参数输入表!$I$556) -> 0 | AB25: =参数输入表!$I$551/(1+参数输入表!$I$556) -> 0 | AC25: =参数输入表!$I$552/(1+参数输入表!$I$556) -> 0 | AD25: =参数输入表!$I$553/(1+参数输入表!$I$556) -> 0 | AE25: =参数输入表!$I$554/(1+参数输入表!$I$556) -> 0 | AF25: =参数输入表!$I$555/(1+参数输入表!$I$556) -> 0
B27: 成本费用表-全投资
B28: 序号 | C28: 项目 | D28: 合计 | E28: 单位 | F28: 2020年 | G28: 2021年 | H28: 2022年 | I28: 45107 | J28: 45261 | K28: 2024年 | L28: 2025年 | M28: 2026年 | N28: 2027年 | O28: 2028年 | P28: 2029年 | Q28: 2030年 | R28: 2031年 | S28: 2032年 | T28: 2033年 | U28: 2034年 | V28: 2035年 | W28: 2036年 | X28: 2037年 | Y28: 2038年 | Z28: 2039年 | AA28: 2040年 | AB28: 2041年 | AC28: 2042年 | AD28: 2043年 | AE28: 2044年 | AF28: 53051
F29: 1 | G29: 2 | H29: 3 | I29: 4 | J29: 5 | K29: 6 | L29: 7 | M29: 8 | N29: 9 | O29: 10 | P29: 11 | Q29: 12 | R29: 13 | S29: 14 | T29: 15 | U29: 16 | V29: 17 | W29: 18 | X29: 19 | Y29: 20 | Z29: 21 | AA29: 22 | AB29: 23 | AC29: 24 | AD29: 25 | AE29: 26 | AF29: 27
C30: 投产比例 | F30: =参数输入表!$I$39 -> 0 | G30: =参数输入表!$I$40 -> 0.03125 | H30: =参数输入表!$I$41 -> 0.03125 | I30: =参数输入表!$I$42 -> 0.03125 | J30: =参数输入表!$I$43 -> 0.1765625 | K30: =参数输入表!$I$44 -> 0.7578125 | L30: =参数输入表!$I$45 -> 1 | M30: =参数输入表!$I$46 -> 1 | N30: =参数输入表!$I$47 -> 1 | O30: =参数输入表!$I$48 -> 1 | P30: =参数输入表!$I$49 -> 1 | Q30: =参数输入表!$I$50 -> 1 | R30: =参数输入表!$I$51 -> 1 | S30: =参数输入表!$I$52 -> 1 | T30: =参数输入表!$I$53 -> 1 | U30: =参数输入表!$I$54 -> 1 | V30: =参数输入表!$I$55 -> 1 | W30: =参数输入表!$I$56 -> 1 | X30: =参数输入表!$I$57 -> 1 | Y30: =参数输入表!$I$58 -> 1 | Z30: =参数输入表!$I$59 -> 1 | AA30: =参数输入表!$I$60 -> 1 | AB30: =参数输入表!$I$61 -> 1 | AC30: =参数输入表!$I$62 -> 1 | AD30: =参数输入表!$I$63 -> 1 | AE30: =参数输入表!$I$64 -> 1 | AF30: =参数输入表!$I$65 -> 1
B31: 一 | C31: 生产经营成本（全投资） | D31: =SUM(F31:AF31) -> 225075.3 | E31: 万元 | F31: =F32+F41+F42+F45 -> 0 | G31: =G32+G41+G42+G45 -> 0 | H31: =H32+H41+H42+H45 -> 0 | I31: =I32+I41+I42+I45 -> 2000 | J31: =J32+J41+J42+J45 -> 2378.4768 | K31: =K32+K41+K42+K45 -> 10100.563 | L31: =L32+L41+L42+L45 -> 11313.938 | M31: =M32+M41+M42+M45 -> 11687.129 | ... AF31: =AF32+AF41+AF42+AF45 -> 4239.4163
B32: 1 | C32: 生产成本 | D32: =SUM(F32:AF32) -> 220761.69 | E32: 万元 | F32: =F7 -> 0 | G32: =G7 -> 0 | H32: =H7 -> 0 | I32: =I7 -> 2000 | J32: =SUM(J33:J40) -> 2376.7749 | K32: =SUM(K33:K40) -> 10085.953 | L32: =SUM(L33:L40) -> 11294.66 | M32: =SUM(M33:M40) -> 11632.8 | N32: =SUM(N33:N40) -> 11661.6 | O32: =SUM(O33:O40) -> 11690.4 | P32: =SUM(P33:P40) -> 11719.2 | Q32: =SUM(Q33:Q40) -> 11748 | ... AF32: =SUM(AF33:AF40) -> 993.64165
B33: 1.1 | C33: 材料费 | D33: =SUM(F33:AF33) -> 1206.75 | E33: 万元 | J33: =J8 -> 28.25 | K33: =K8 -> 242.5 | L33: =L8 -> 320 | M33: =M8 -> 32 | N33: =N8 -> 32 | O33: =O8 -> 32 | P33: =P8 -> 32 | Q33: =Q8 -> 32 | ... AF33: =AF8 -> 8
B34: 1.2 | C34: 维修费 | D34: =SUM(F34:AF34) -> 13768.266 | E34: 万元 | J34: =J9 -> 0 | K34: =K9 -> 0 | L34: =L9 -> 0 | M34: =M9 -> 483.09706 | N34: =N9 -> 483.09706 | O34: =O9 -> 483.09706 | P34: =P9 -> 483.09706 | Q34: =Q9 -> 483.09706 | ... AF34: =AF9 -> 241.54853
B35: 1.3 | C35: 生产人员薪酬及福利 | D35: =SUM(F35:AF35) -> 19563.143 | E35: 万元 | J35: =J10 -> 53.3925 | K35: =K10 -> 480.15 | L35: =L10 -> 662.4 | M35: =M10 -> 691.2 | N35: =N10 -> 720 | O35: =O10 -> 748.8 | P35: =P10 -> 777.6 | Q35: =Q10 -> 806.4 | ... AF35: =AF10 -> 309.6
B36: 1.4 | C36: 长期待摊费用当期摊销 | D36: =SUM(F36:AF36) -> 1834.8624 | E36: 万元 | J36: =J11 -> 0 | K36: =K11 -> 0 | L36: =L11 -> 0 | M36: =M11 -> 91.743119 | N36: =N11 -> 91.743119 | O36: =O11 -> 91.743119 | P36: =P11 -> 91.743119 | Q36: =Q11 -> 91.743119 | ... AF36: =AF11 -> 91.743119
B37: 1.5 | C37: 营业相关资产折旧及摊销（全投资） | D37: =SUM(F37:AF37) -> 154159.94 | E37: 万元 | J37: ='表2-折旧摊销表'!J201+'表2-折旧摊销表'!J203 -> 2089.4074 | K37: ='表2-折旧摊销表'!K201+'表2-折旧摊销表'!K203 -> 8338.0534 | L37: ='表2-折旧摊销表'!L201+'表2-折旧摊销表'!L203 -> 9031.2598 | M37: ='表2-折旧摊销表'!M201+'表2-折旧摊销表'!M203 -> 9031.2598 | N37: ='表2-折旧摊销表'!N201+'表2-折旧摊销表'!N203 -> 9031.2598 | O37: ='表2-折旧摊销表'!O201+'表2-折旧摊销表'!O203 -> 9031.2598 | P37: ='表2-折旧摊销表'!P201+'表2-折旧摊销表'!P203 -> 9031.2598 | Q37: ='表2-折旧摊销表'!Q201+'表2-折旧摊销表'!Q203 -> 9031.2598 | ... AF37: ='表2-折旧摊销表'!AF201+'表2-折旧摊销表'!AF203 -> 0
B38: 1.6 | C38: 其他费用 | D38: =SUM(F38:AF38) -> 6750.75 | E38: 万元 | J38: =J13 -> 28.25 | K38: =K13 -> 242.5 | L38: =L13 -> 320 | M38: =M13 -> 320 | N38: =N13 -> 320 | O38: =O13 -> 320 | P38: =P13 -> 320 | Q38: =Q13 -> 320 | ... AF38: =AF13 -> 80
B39: 1.7 | C39: 储能费用 | D39: =SUM(F39:AF39) -> 15526.725 | E39: 万元 | J39: =J14 -> 64.975 | K39: =K14 -> 557.75 | L39: =L14 -> 736 | M39: =M14 -> 736 | N39: =N14 -> 736 | O39: =O14 -> 736 | P39: =P14 -> 736 | Q39: =Q14 -> 736 | ... AF39: =AF14 -> 184
B40: 1.8 | C40: 场地租金费用 | D40: =SUM(F40:AF40) -> 5951.25 | E40: 万元 | J40: =J15 -> 112.5 | K40: =K15 -> 225 | L40: =L15 -> 225 | M40: =M15 -> 247.5 | N40: =N15 -> 247.5 | O40: =O15 -> 247.5 | P40: =P15 -> 247.5 | Q40: =Q15 -> 247.5 | ... AF40: =AF15 -> 78.75
B41: 2 | C41: 销售费用 | D41: =SUM(F41:AF41) -> 0 | E41: 万元 | F41: =F16 -> 0 | G41: =G16 -> 0 | H41: =H16 -> 0 | I41: =I16 -> 0 | J41: 0 | K41: 0 | L41: 0 | M41: 0 | N41: 0 | O41: 0 | P41: 0 | Q41: 0 | R41: 0 | S41: 0 | T41: 0 | U41: 0 | V41: 0 | W41: 0 | X41: 0 | Y41: 0 | Z41: 0 | AA41: 0 | AB41: 0 | AC41: 0 | AD41: 0 | AE41: 0 | AF41: 0
B42: 3 | C42: 管理费用 | D42: =SUM(F42:AF42) -> 4313.6169 | E42: 万元 | F42: =F17 -> 0 | G42: =G17 -> 0 | H42: =H17 -> 0 | I42: =I17 -> 0 | J42: =SUM(J43:J44) -> 1.7018923 | K42: =SUM(K43:K44) -> 14.609164 | L42: =SUM(L43:L44) -> 19.278072 | M42: =SUM(M43:M44) -> 54.329111 | N42: =SUM(N43:N44) -> 54.329111 | O42: =SUM(O43:O44) -> 54.329111 | P42: =SUM(P43:P44) -> 54.329111 | Q42: =SUM(Q43:Q44) -> 54.329111 | ... AF42: =SUM(AF43:AF44) -> 3245.7746
...

Sheet 表4-收入税金表
B2: 收入表
B3: 序号 | C3: 项目 | D3: 合计 | E3: 单位 | F3: 2020年 | G3: 2021年 | H3: 2022年 | I3: 45107 | J3: 2023年12月 | K3: 2024年 | L3: 2025年 | M3: 2026年 | N3: 2027年 | O3: 2028年 | P3: 2029年 | Q3: 2030年 | R3: 2031年 | S3: 2032年 | T3: 2033年 | U3: 2034年 | V3: 2035年 | W3: 2036年 | X3: 2037年 | Y3: 2038年 | Z3: 2039年 | AA3: 2040年 | AB3: 2041年 | AC3: 2042年 | AD3: 2043年 | AE3: 2044年 | AF3: 53051
F4: 1 | G4: 2 | H4: 3 | I4: 4 | J4: 5 | K4: 6 | L4: 7 | M4: 8 | N4: 9 | O4: 10 | P4: 11 | Q4: 12 | R4: 13 | S4: 14 | T4: 15 | U4: 16 | V4: 17 | W4: 18 | X4: 19 | Y4: 20 | Z4: 21 | AA4: 22 | AB4: 23 | AC4: 24 | AD4: 25 | AE4: 26 | AF4: 27
C5: 投产比例 | F5: =参数输入表!$I$39 -> 0 | G5: =参数输入表!$I$40 -> 0.03125 | H5: =参数输入表!$I$41 -> 0.03125 | I5: =参数输入表!$I$42 -> 0.03125 | J5: =参数输入表!$I$43 -> 0.1765625 | K5: =参数输入表!$I$44 -> 0.7578125 | L5: =参数输入表!$I$45 -> 1 | M5: =参数输入表!$I$46 -> 1 | N5: =参数输入表!$I$47 -> 1 | O5: =参数输入表!$I$48 -> 1 | P5: =参数输入表!$I$49 -> 1 | Q5: =参数输入表!$I$50 -> 1 | R5: =参数输入表!$I$51 -> 1 | S5: =参数输入表!$I$52 -> 1 | T5: =参数输入表!$I$53 -> 1 | U5: =参数输入表!$I$54 -> 1 | V5: =参数输入表!$I$55 -> 1 | W5: =参数输入表!$I$56 -> 1 | X5: =参数输入表!$I$57 -> 1 | Y5: =参数输入表!$I$58 -> 1 | Z5: =参数输入表!$I$59 -> 1 | AA5: =参数输入表!$I$60 -> 1 | AB5: =参数输入表!$I$61 -> 1 | AC5: =参数输入表!$I$62 -> 1 | AD5: =参数输入表!$I$63 -> 1 | AE5: =参数输入表!$I$64 -> 1 | AF5: =参数输入表!$I$65 -> 1
B6: 1 | C6: 营业收入 | D6: =SUM(F6:AF6) -> 354199.74 | E6: 万元 | F6: ='表5-利润表-资本金(标准格式)'!F6 -> 0 | G6: ='表5-利润表-资本金(标准格式)'!G6 -> 0 | H6: ='表5-利润表-资本金(标准格式)'!H6 -> 0 | I6: ='表5-利润表-资本金(标准格式)'!I6 -> 2000 | J6: =J7+J19+J15 -> 1656.1591 | K6: =K7+K19+K15 -> 14152.051 | L6: =L7+L19+L15 -> 18589.687 | M6: =M7+M19+M15 -> 18504.498 | N6: =N7+N19+N15 -> 18419.312 | O6: =O7+O19+O15 -> 18334.126 | P6: =P7+P19+P15 -> 18248.938 | Q6: =Q7+Q19+Q15 -> 18163.752 | ... AF6: =AF7+AF19+AF15 -> 3242.0223
B7: 1.1 | C7: 发电销售收入 | D7: =SUM(F7:AF7) -> 270180.41 | E7: 万元 | J7: =J8*(J12-J13-J14)/(1+参数输入表!$I$563) -> 1191.2068 | K7: =K8*(K12-K13-K14)/(1+参数输入表!$I$563) -> 10178.971 | L7: =L8*(L12-L13-L14)/(1+参数输入表!$I$563) -> 13370.773 | M7: =M8*(M12-M13-M14)/(1+参数输入表!$I$563) -> 13309.502 | N7: =N8*(N12-N13-N14)/(1+参数输入表!$I$563) -> 13248.23 | O7: =O8*(O12-O13-O14)/(1+参数输入表!$I$563) -> 13186.959 | P7: =P8*(P12-P13-P14)/(1+参数输入表!$I$563) -> 13125.688 | Q7: =Q8*(Q12-Q13-Q14)/(1+参数输入表!$I$563) -> 13064.416 | ... AF7: =AF8*(AF12-AF13-AF14)/(1+参数输入表!$I$563) -> 3036.3364
C8: 上网电量 | D8: =SUM(F8:AF8) -> 984851.19 | E8: 万度 | J8: =参数输入表!$I$67*参数输入表!$I$68*(1-参数输入表!$I$74)*(1-参数输入表!$I$102)/10*J5*(12-MONTH(参数输入表!I8))/12 -> 4342.1408 | K8: =参数输入表!$I$67*参数输入表!$I$68*(1-参数输入表!$I$75)*(1-参数输入表!$I$103)/10*K5 -> 37103.991 | L8: =参数输入表!$I$67*参数输入表!$I$68*(1-参数输入表!$I$76)*(1-参数输入表!$I$104)/10*L5 -> 48738.624 | M8: =参数输入表!$I$67*参数输入表!$I$68*(1-参数输入表!$I$77)*(1-参数输入表!$I$105)/10*M5 -> 48515.28 | N8: =参数输入表!$I$67*参数输入表!$I$68*(1-参数输入表!$I$78)*(1-参数输入表!$I$106)/10*N5 -> 48291.936 | O8: =参数输入表!$I$67*参数输入表!$I$68*(1-参数输入表!$I$79)*(1-参数输入表!$I$107)/10*O5 -> 48068.592 | P8: =参数输入表!$I$67*参数输入表!$I$68*(1-参数输入表!$I$80)*(1-参数输入表!$I$108)/10*P5 -> 47845.248 | Q8: =参数输入表!$I$67*参数输入表!$I$68*(1-参数输入表!$I$81)*(1-参数输入表!$I$109)/10*Q5 -> 47621.904 | R8: =参数输入表!$I$67*参数输入表!$I$68*(1-参数输入表!$I$82)*(1-参数输入表!$I$110)/10*R5 -> 47398.56 | S8: =参数输入表!$I$67*参数输入表!$I$68*(1-参数输入表!$I$83)*(1-参数输入表!$I$111)/10*S5 -> 47175.216 | T8: =参数输入表!$I$67*参数输入表!$I$68*(1-参数输入表!$I$84)*(1-参数输入表!$I$112)/10*T5 -> 46951.872 | U8: =参数输入表!$I$67*参数输入表!$I$68*(1-参数输入表!$I$85)*(1-参数输入表!$I$113)/10*U5 -> 46728.528 | V8: =参数输入表!$I$67*参数输入表!$I$68*(1-参数输入表!$I$86)*(1-参数输入表!$I$114)/10*V5 -> 46505.184 | W8: =参数输入表!$I$67*参数输入表!$I$68*(1-参数输入表!$I$87)*(1-参数输入表!$I$115)/10*W5 -> 46281.84 | X8: =参数输入表!$I$67*参数输入表!$I$68*(1-参数输入表!$I$88)*(1-参数输入表!$I$116)/10*X5 -> 46058.496 | Y8: =参数输入表!$I$67*参数输入表!$I$68*(1-参数输入表!$I$89)*(1-参数输入表!$I$117)/10*Y5 -> 45835.152 | Z8: =参数输入表!$I$67*参数输入表!$I$68*(1-参数输入表!$I$90)*(1-参数输入表!$I$118)/10*Z5 -> 45611.808 | AA8: =参数输入表!$I$67*参数输入表!$I$68*(1-参数输入表!$I$91)*(1-参数输入表!$I$119)/10*AA5 -> 45388.464 | AB8: =参数输入表!$I$67*参数输入表!$I$68*(1-参数输入表!$I$92)*(1-参数输入表!$I$120)/10*AB5 -> 45165.12 | AC8: =参数输入表!$I$67*参数输入表!$I$68*(1-参数输入表!$I$93)*(1-参数输入表!$I$121)/10*AC5 -> 44941.776 | AD8: =参数输入表!$I$67*参数输入表!$I$68*(1-参数输入表!$I$94)*(1-参数输入表!$I$122)/10*AD5 -> 44718.432 | AE8: =参数输入表!$I$67*参数输入表!$I$68*(1-参数输入表!$I$95)*(1-参数输入表!$I$123)/10*AE5 -> 44495.088 | AF8: =参数输入表!$I$67*参数输入表!$I$68*(1-参数输入表!$I$96)*(1-参数输入表!$I$124)/10*AF5*MONTH(参数输入表!I6)/12 -> 11067.936
C9: 保障内交易电量 | D9: =SUM(F9:AF9) -> 689395.83 | E9: 万度 | J9: =J8*参数输入表!$I$125 -> 3039.4986 | K9: =K8*参数输入表!$I$125 -> 25972.794 | L9: =L8*参数输入表!$I$125 -> 34117.037 | M9: =M8*参数输入表!$I$125 -> 33960.696 | N9: =N8*参数输入表!$I$125 -> 33804.355 | O9: =O8*参数输入表!$I$125 -> 33648.014 | P9: =P8*参数输入表!$I$125 -> 33491.674 | Q9: =Q8*参数输入表!$I$125 -> 33335.333 | ... AF9: =AF8*参数输入表!$I$125 -> 7747.5552
C10: 市场化交易电量 | D10: =SUM(F10:AF10) -> 196970.24 | E10: 万度 | J10: =J8*参数输入表!$I$126 -> 868.42817 | K10: =K8*参数输入表!$I$126 -> 7420.7983 | L10: =L8*参数输入表!$I$126 -> 9747.7248 | M10: =M8*参数输入表!$I$126 -> 9703.056 | N10: =N8*参数输入表!$I$126 -> 9658.3872 | O10: =O8*参数输入表!$I$126 -> 9613.7184 | P10: =P8*参数输入表!$I$126 -> 9569.0496 | Q10: =Q8*参数输入表!$I$126 -> 9524.3808 | ... AF10: =AF8*参数输入表!$I$126 -> 2213.5872
